
# Created by Ruins mod version 17.1 Ingame Parser
# authoring Player: austinsupercar

weight=20
embed_into_distance=1
acceptable_target_blocks=
unacceptable_target_blocks=flowing_water,water,flowing_lava,lava
dimensions=7,6,14
allowable_overhang=0
max_leveling=2
leveling_buffer=0
preserve_water=0
preserve_lava=0
preventRotation=1

rule1=0,100,minecraft:log2-1
rule2=0,100,minecraft:wool-8
rule3=0,100,minecraft:wool-14
rule4=0,100,minecraft:wool-15
rule5=0,100,minecraft:dirt-0
rule6=0,100,minecraft:grass-0
rule7=0,100,minecraft:wool-12
rule8=0,100,minecraft:wool-0
rule9=0,100,minecraft:wool-6
rule10=0,100,minecraft:wooden_door-0
rule11=0,100,minecraft:oak_stairs-1
rule12=0,100,minecraft:oak_stairs-3
rule13=0,100,minecraft:hay_block-0
rule14=0,100,minecraft:oak_stairs-0
rule15=0,100,minecraft:bed-3
rule16=0,100,ChestGenHook:chests/simple_dungeon:5-4
rule17=0,100,minecraft:bed-11
rule18=0,100,minecraft:furnace-4
rule19=0,100,minecraft:stained_glass-11
rule20=0,100,minecraft:wooden_door-8
rule21=0,100,minecraft:wooden_door-9
rule22=0,100,minecraft:oak_stairs-5
rule23=0,100,minecraft:oak_stairs-7
rule24=0,100,minecraft:oak_stairs-4
rule25=0,100,minecraft:oak_stairs-2
rule26=0,100,minecraft:cobblestone-0
rule27=0,100,minecraft:wooden_slab-0

layer
2,2,3,4,4,3,2,2,1,1,1,1,1,1
7,2,2,2,2,2,2,5,5,5,6,6,5,1
7,8,8,8,8,8,8,7,6,6,6,6,5,1
7,9,9,9,9,9,9,7,6,6,6,6,5,1
7,3,3,3,3,3,3,7,6,6,1,1,1,1
2,2,2,2,2,2,2,2,6,6,6,6,6,6
endlayer

layer
2,2,3,10,10,3,2,2,1,1,1,1,1,1
7,0,0,0,0,0,0,7,1,13,0,12,11,1
7,0,0,0,0,0,0,0,0,0,0,12,12,1
7,15,0,15,0,0,0,0,0,0,0,12,14,1
7,17,18,17,0,16,16,7,0,0,1,1,1,1
2,2,2,2,2,2,2,2,0,0,0,0,0,0
endlayer

layer
2,2,3,21,20,3,2,2,1,19,19,1,1,1
7,0,0,0,0,0,0,7,1,0,0,0,22,1
7,0,0,0,0,0,0,0,0,0,0,0,23,1
7,0,0,0,0,0,0,0,0,0,0,0,24,1
7,0,0,0,0,16,16,7,0,0,1,1,1,1
2,2,2,2,2,2,2,2,0,0,0,0,0,0
endlayer

layer
2,2,3,3,3,3,2,2,1,1,1,1,1,1
7,0,0,0,0,0,0,7,1,0,0,0,0,1
7,0,0,0,0,0,0,0,0,0,0,0,0,1
7,0,0,0,0,0,0,0,0,0,0,0,0,1
7,0,0,0,0,0,0,7,0,0,1,1,1,1
2,2,2,2,2,2,2,2,0,0,0,0,0,0
endlayer

layer
4,4,4,4,4,4,4,4,14,14,14,14,14,25
7,3,3,3,3,3,3,7,26,26,23,23,23,25
7,0,0,0,0,0,0,7,26,26,26,26,26,25
7,0,0,0,0,0,0,7,7,26,26,26,26,25
7,3,3,3,3,3,3,7,7,7,7,11,11,11
4,4,4,4,4,4,4,4,0,0,0,0,0,0
endlayer

layer
0,0,0,0,0,0,0,0,0,0,0,0,0,0
4,4,4,4,4,4,4,4,14,14,14,14,14,0
7,3,3,3,3,3,3,7,26,26,26,26,25,0
7,3,3,3,3,3,3,7,11,11,11,11,25,0
4,4,4,4,4,4,4,4,0,0,0,0,0,0
0,0,0,0,0,0,0,0,0,0,0,0,0,0
endlayer

layer
0,0,0,0,0,0,0,0,0,0,0,0,0,0
0,0,0,0,0,0,0,0,0,0,0,0,0,0
4,4,4,4,4,4,4,4,27,27,27,27,0,0
4,4,4,4,4,4,4,4,0,0,0,0,0,0
0,0,0,0,0,0,0,0,0,0,0,0,0,0
0,0,0,0,0,0,0,0,0,0,0,0,0,0
endlayer

