{
    "registryname": "stomach",
    "localizedname": "Advanced Grinder",
	"color": "edabe5",
    "parts": [
        {
            "x": -1,
            "y": 0,
            "z": 0,
            "elements": [
                "contenttweaker:outer_stomach_wall@0"
            ]
        },
        {
            "x": 1,
            "y": 0,
            "z": 0,
            "elements": [
                "contenttweaker:outer_stomach_wall@0"
            ]
        },
        {
            "x": -7,
            "y": 10,
            "z": 21,
            "elements": [
                "contenttweaker:outer_stomach_wall@0"
            ]
        },
        {
            "x": -6,
            "y": 10,
            "z": 21,
            "elements": [
                "contenttweaker:inner_stomach_wall@0"
            ]
        },
        {
            "x": -8,
            "y": 2,
            "z": 17,
            "elements": [
                "contenttweaker:outer_stomach_wall@0"
            ]
        },
        {
            "x": -7,
            "y": 2,
            "z": 17,
            "elements": [
                "contenttweaker:inner_stomach_wall@0"
            ]
        },
        {
            "x": -3,
            "y": -6,
            "z": 13,
            "elements": [
                "contenttweaker:outer_stomach_wall@0"
            ]
        },
        {
            "x": 6,
            "y": 10,
            "z": 21,
            "elements": [
                "contenttweaker:inner_stomach_wall@0"
            ]
        },
        {
            "x": -2,
            "y": -6,
            "z": 13,
            "elements": [
                "contenttweaker:outer_stomach_wall@0"
            ]
        },
        {
            "x": -1,
            "y": -6,
            "z": 13,
            "elements": [
                "contenttweaker:outer_stomach_wall@0"
            ]
        },
        {
            "x": 7,
            "y": 10,
            "z": 21,
            "elements": [
                "contenttweaker:outer_stomach_wall@0"
            ]
        },
        {
            "x": 1,
            "y": -6,
            "z": 13,
            "elements": [
                "contenttweaker:outer_stomach_wall@0"
            ]
        },
        {
            "x": 2,
            "y": -6,
            "z": 13,
            "elements": [
                "contenttweaker:outer_stomach_wall@0"
            ]
        },
        {
            "x": 7,
            "y": 2,
            "z": 17,
            "elements": [
                "contenttweaker:inner_stomach_wall@0"
            ]
        },
        {
            "x": 8,
            "y": 2,
            "z": 17,
            "elements": [
                "contenttweaker:outer_stomach_wall@0"
            ]
        },
        {
            "x": 1,
            "y": -1,
            "z": 0,
            "elements": [
                "contenttweaker:outer_stomach_wall@0"
            ]
        },
        {
            "x": 0,
            "y": -1,
            "z": 0,
            "elements": [
                "modularmachinery:blockfluidoutputhatch@2"
            ]
        },
        {
            "x": 0,
            "y": 1,
            "z": 0,
            "elements": [
                "contenttweaker:outer_stomach_wall@0"
            ]
        },
        {
            "x": -1,
            "y": -1,
            "z": 0,
            "elements": [
                "contenttweaker:outer_stomach_wall@0"
            ]
        },
        {
            "x": -7,
            "y": 11,
            "z": 21,
            "elements": [
                "contenttweaker:outer_stomach_wall@0"
            ]
        },
        {
            "x": -6,
            "y": 11,
            "z": 21,
            "elements": [
                "contenttweaker:inner_stomach_wall@0"
            ]
        },
        {
            "x": -8,
            "y": 3,
            "z": 17,
            "elements": [
                "contenttweaker:outer_stomach_wall@0"
            ]
        },
        {
            "x": -7,
            "y": 3,
            "z": 17,
            "elements": [
                "contenttweaker:inner_stomach_wall@0"
            ]
        },
        {
            "x": -4,
            "y": -5,
            "z": 13,
            "elements": [
                "contenttweaker:outer_stomach_wall@0"
            ]
        },
        {
            "x": -3,
            "y": -5,
            "z": 13,
            "elements": [
                "contenttweaker:inner_stomach_wall@0"
            ]
        },
        {
            "x": 6,
            "y": 11,
            "z": 21,
            "elements": [
                "contenttweaker:inner_stomach_wall@0"
            ]
        },
        {
            "x": -2,
            "y": -5,
            "z": 13,
            "elements": [
                "contenttweaker:inner_stomach_wall@0"
            ]
        },
        {
            "x": -1,
            "y": -5,
            "z": 13,
            "elements": [
                "contenttweaker:inner_stomach_wall@0"
            ]
        },
        {
            "x": 7,
            "y": 11,
            "z": 21,
            "elements": [
                "contenttweaker:outer_stomach_wall@0"
            ]
        },
        {
            "x": 0,
            "y": -5,
            "z": 13,
            "elements": [
                "contenttweaker:inner_stomach_wall@0"
            ]
        },
        {
            "x": 1,
            "y": -5,
            "z": 13,
            "elements": [
                "contenttweaker:inner_stomach_wall@0"
            ]
        },
        {
            "x": 2,
            "y": -5,
            "z": 13,
            "elements": [
                "contenttweaker:inner_stomach_wall@0"
            ]
        },
        {
            "x": 7,
            "y": 3,
            "z": 17,
            "elements": [
                "contenttweaker:inner_stomach_wall@0"
            ]
        },
        {
            "x": 3,
            "y": -5,
            "z": 13,
            "elements": [
                "contenttweaker:outer_stomach_wall@0"
            ]
        },
        {
            "x": 8,
            "y": 3,
            "z": 17,
            "elements": [
                "contenttweaker:outer_stomach_wall@0"
            ]
        },
        {
            "x": 4,
            "y": -5,
            "z": 13,
            "elements": [
                "contenttweaker:outer_stomach_wall@0"
            ]
        },
        {
            "x": 1,
            "y": -2,
            "z": 0,
            "elements": [
                "contenttweaker:outer_stomach_wall@0"
            ]
        },
        {
            "x": 0,
            "y": -2,
            "z": 0,
            "elements": [
                "modularmachinery:blockoutputbus@2"
            ]
        },
        {
            "x": -1,
            "y": -2,
            "z": 0,
            "elements": [
                "contenttweaker:outer_stomach_wall@0"
            ]
        },
        {
            "x": -7,
            "y": 12,
            "z": 21,
            "elements": [
                "contenttweaker:outer_stomach_wall@0"
            ]
        },
        {
            "x": -6,
            "y": 12,
            "z": 21,
            "elements": [
                "contenttweaker:inner_stomach_wall@0"
            ]
        },
        {
            "x": -8,
            "y": 4,
            "z": 17,
            "elements": [
                "contenttweaker:outer_stomach_wall@0"
            ]
        },
        {
            "x": -7,
            "y": 4,
            "z": 17,
            "elements": [
                "contenttweaker:inner_stomach_wall@0"
            ]
        },
        {
            "x": -5,
            "y": -4,
            "z": 13,
            "elements": [
                "contenttweaker:outer_stomach_wall@0"
            ]
        },
        {
            "x": -4,
            "y": -4,
            "z": 13,
            "elements": [
                "contenttweaker:inner_stomach_wall@0"
            ]
        },
        {
            "x": -3,
            "y": -4,
            "z": 13,
            "elements": [
                "contenttweaker:inner_stomach_wall@0"
            ]
        },
        {
            "x": 6,
            "y": 12,
            "z": 21,
            "elements": [
                "contenttweaker:inner_stomach_wall@0"
            ]
        },
        {
            "x": -2,
            "y": -4,
            "z": 13,
            "elements": [
                "tconstruct:slime_channel@0"
            ]
        },
        {
            "x": -1,
            "y": -4,
            "z": 13,
            "elements": [
                "tconstruct:slime_channel@0"
            ]
        },
        {
            "x": 7,
            "y": 12,
            "z": 21,
            "elements": [
                "contenttweaker:outer_stomach_wall@0"
            ]
        },
        {
            "x": 0,
            "y": -4,
            "z": 13,
            "elements": [
                "tconstruct:slime_channel@0"
            ]
        },
        {
            "x": 1,
            "y": -4,
            "z": 13,
            "elements": [
                "tconstruct:slime_channel@0"
            ]
        },
        {
            "x": 2,
            "y": -4,
            "z": 13,
            "elements": [
                "tconstruct:slime_channel@0"
            ]
        },
        {
            "x": 7,
            "y": 4,
            "z": 17,
            "elements": [
                "contenttweaker:inner_stomach_wall@0"
            ]
        },
        {
            "x": 3,
            "y": -4,
            "z": 13,
            "elements": [
                "contenttweaker:inner_stomach_wall@0"
            ]
        },
        {
            "x": 8,
            "y": 4,
            "z": 17,
            "elements": [
                "contenttweaker:outer_stomach_wall@0"
            ]
        },
        {
            "x": 4,
            "y": -4,
            "z": 13,
            "elements": [
                "contenttweaker:inner_stomach_wall@0"
            ]
        },
        {
            "x": 5,
            "y": -4,
            "z": 13,
            "elements": [
                "contenttweaker:outer_stomach_wall@0"
            ]
        },
        {
            "x": 0,
            "y": -3,
            "z": 0,
            "elements": [
                "contenttweaker:outer_stomach_wall@0"
            ]
        },
        {
            "x": -6,
            "y": 13,
            "z": 21,
            "elements": [
                "contenttweaker:outer_stomach_wall@0"
            ]
        },
        {
            "x": -5,
            "y": 13,
            "z": 21,
            "elements": [
                "contenttweaker:inner_stomach_wall@0"
            ]
        },
        {
            "x": -8,
            "y": 5,
            "z": 17,
            "elements": [
                "contenttweaker:outer_stomach_wall@0"
            ]
        },
        {
            "x": -7,
            "y": 5,
            "z": 17,
            "elements": [
                "contenttweaker:inner_stomach_wall@0"
            ]
        },
        {
            "x": -6,
            "y": -3,
            "z": 13,
            "elements": [
                "contenttweaker:outer_stomach_wall@0"
            ]
        },
        {
            "x": -5,
            "y": -3,
            "z": 13,
            "elements": [
                "contenttweaker:inner_stomach_wall@0"
            ]
        },
        {
            "x": -4,
            "y": -3,
            "z": 13,
            "elements": [
                "contenttweaker:inner_stomach_wall@0"
            ]
        },
        {
            "x": 5,
            "y": 13,
            "z": 21,
            "elements": [
                "contenttweaker:inner_stomach_wall@0"
            ]
        },
        {
            "x": -3,
            "y": -3,
            "z": 13,
            "elements": [
                "tconstruct:slime_channel@0"
            ]
        },
        {
            "x": 6,
            "y": 13,
            "z": 21,
            "elements": [
                "contenttweaker:outer_stomach_wall@0"
            ]
        },
        {
            "x": 7,
            "y": 5,
            "z": 17,
            "elements": [
                "contenttweaker:inner_stomach_wall@0"
            ]
        },
        {
            "x": 3,
            "y": -3,
            "z": 13,
            "elements": [
                "tconstruct:slime_channel@0"
            ]
        },
        {
            "x": 8,
            "y": 5,
            "z": 17,
            "elements": [
                "contenttweaker:outer_stomach_wall@0"
            ]
        },
        {
            "x": 4,
            "y": -3,
            "z": 13,
            "elements": [
                "contenttweaker:inner_stomach_wall@0"
            ]
        },
        {
            "x": 5,
            "y": -3,
            "z": 13,
            "elements": [
                "contenttweaker:inner_stomach_wall@0"
            ]
        },
        {
            "x": 6,
            "y": -3,
            "z": 13,
            "elements": [
                "contenttweaker:outer_stomach_wall@0"
            ]
        },
        {
            "x": -5,
            "y": 14,
            "z": 21,
            "elements": [
                "contenttweaker:outer_stomach_wall@0"
            ]
        },
        {
            "x": -8,
            "y": 6,
            "z": 17,
            "elements": [
                "contenttweaker:outer_stomach_wall@0"
            ]
        },
        {
            "x": -4,
            "y": 14,
            "z": 21,
            "elements": [
                "contenttweaker:inner_stomach_wall@0"
            ]
        },
        {
            "x": -7,
            "y": 6,
            "z": 17,
            "elements": [
                "contenttweaker:inner_stomach_wall@0"
            ]
        },
        {
            "x": -6,
            "y": -2,
            "z": 13,
            "elements": [
                "contenttweaker:outer_stomach_wall@0"
            ]
        },
        {
            "x": -5,
            "y": -2,
            "z": 13,
            "elements": [
                "contenttweaker:inner_stomach_wall@0"
            ]
        },
        {
            "x": 4,
            "y": 14,
            "z": 21,
            "elements": [
                "contenttweaker:inner_stomach_wall@0"
            ]
        },
        {
            "x": -4,
            "y": -2,
            "z": 13,
            "elements": [
                "tconstruct:slime_channel@0"
            ]
        },
        {
            "x": 5,
            "y": 14,
            "z": 21,
            "elements": [
                "contenttweaker:outer_stomach_wall@0"
            ]
        },
        {
            "x": 7,
            "y": 6,
            "z": 17,
            "elements": [
                "contenttweaker:inner_stomach_wall@0"
            ]
        },
        {
            "x": 8,
            "y": 6,
            "z": 17,
            "elements": [
                "contenttweaker:outer_stomach_wall@0"
            ]
        },
        {
            "x": 4,
            "y": -2,
            "z": 13,
            "elements": [
                "tconstruct:slime_channel@0"
            ]
        },
        {
            "x": 5,
            "y": -2,
            "z": 13,
            "elements": [
                "contenttweaker:inner_stomach_wall@0"
            ]
        },
        {
            "x": 6,
            "y": -2,
            "z": 13,
            "elements": [
                "contenttweaker:inner_stomach_wall@0"
            ]
        },
        {
            "x": 7,
            "y": -2,
            "z": 13,
            "elements": [
                "contenttweaker:outer_stomach_wall@0"
            ]
        },
        {
            "x": -8,
            "y": 7,
            "z": 17,
            "elements": [
                "contenttweaker:outer_stomach_wall@0"
            ]
        },
        {
            "x": -4,
            "y": 15,
            "z": 21,
            "elements": [
                "contenttweaker:outer_stomach_wall@0"
            ]
        },
        {
            "x": -7,
            "y": 7,
            "z": 17,
            "elements": [
                "contenttweaker:inner_stomach_wall@0"
            ]
        },
        {
            "x": -3,
            "y": 15,
            "z": 21,
            "elements": [
                "contenttweaker:inner_stomach_wall@0"
            ]
        },
        {
            "x": -2,
            "y": 15,
            "z": 21,
            "elements": [
                "contenttweaker:inner_stomach_wall@0"
            ]
        },
        {
            "x": -1,
            "y": 15,
            "z": 21,
            "elements": [
                "contenttweaker:inner_stomach_wall@0"
            ]
        },
        {
            "x": 0,
            "y": 15,
            "z": 21,
            "elements": [
                "contenttweaker:inner_stomach_wall@0"
            ]
        },
        {
            "x": 1,
            "y": 15,
            "z": 21,
            "elements": [
                "contenttweaker:inner_stomach_wall@0"
            ]
        },
        {
            "x": -7,
            "y": -1,
            "z": 13,
            "elements": [
                "contenttweaker:outer_stomach_wall@0"
            ]
        },
        {
            "x": -6,
            "y": -1,
            "z": 13,
            "elements": [
                "contenttweaker:inner_stomach_wall@0"
            ]
        },
        {
            "x": 2,
            "y": 15,
            "z": 21,
            "elements": [
                "contenttweaker:inner_stomach_wall@0"
            ]
        },
        {
            "x": -5,
            "y": -1,
            "z": 13,
            "elements": [
                "tconstruct:slime_channel@0"
            ]
        },
        {
            "x": 3,
            "y": 15,
            "z": 21,
            "elements": [
                "contenttweaker:inner_stomach_wall@0"
            ]
        },
        {
            "x": 4,
            "y": 15,
            "z": 21,
            "elements": [
                "contenttweaker:outer_stomach_wall@0"
            ]
        },
        {
            "x": 7,
            "y": 7,
            "z": 17,
            "elements": [
                "contenttweaker:inner_stomach_wall@0"
            ]
        },
        {
            "x": 8,
            "y": 7,
            "z": 17,
            "elements": [
                "contenttweaker:outer_stomach_wall@0"
            ]
        },
        {
            "x": 5,
            "y": -1,
            "z": 13,
            "elements": [
                "tconstruct:slime_channel@0"
            ]
        },
        {
            "x": 6,
            "y": -1,
            "z": 13,
            "elements": [
                "contenttweaker:inner_stomach_wall@0"
            ]
        },
        {
            "x": 7,
            "y": -1,
            "z": 13,
            "elements": [
                "contenttweaker:outer_stomach_wall@0"
            ]
        },
        {
            "x": -8,
            "y": 8,
            "z": 17,
            "elements": [
                "contenttweaker:outer_stomach_wall@0"
            ]
        },
        {
            "x": -7,
            "y": 8,
            "z": 17,
            "elements": [
                "contenttweaker:inner_stomach_wall@0"
            ]
        },
        {
            "x": -3,
            "y": 16,
            "z": 21,
            "elements": [
                "contenttweaker:outer_stomach_wall@0"
            ]
        },
        {
            "x": -2,
            "y": 16,
            "z": 21,
            "elements": [
                "contenttweaker:outer_stomach_wall@0"
            ]
        },
        {
            "x": -1,
            "y": 16,
            "z": 21,
            "elements": [
                "contenttweaker:outer_stomach_wall@0"
            ]
        },
        {
            "x": 0,
            "y": 16,
            "z": 21,
            "elements": [
                "contenttweaker:outer_stomach_wall@0"
            ]
        },
        {
            "x": 1,
            "y": 16,
            "z": 21,
            "elements": [
                "contenttweaker:outer_stomach_wall@0"
            ]
        },
        {
            "x": -7,
            "y": 0,
            "z": 13,
            "elements": [
                "contenttweaker:outer_stomach_wall@0"
            ]
        },
        {
            "x": -6,
            "y": 0,
            "z": 13,
            "elements": [
                "contenttweaker:inner_stomach_wall@0"
            ]
        },
        {
            "x": 2,
            "y": 16,
            "z": 21,
            "elements": [
                "contenttweaker:outer_stomach_wall@0"
            ]
        },
        {
            "x": 3,
            "y": 16,
            "z": 21,
            "elements": [
                "contenttweaker:outer_stomach_wall@0"
            ]
        },
        {
            "x": 7,
            "y": 8,
            "z": 17,
            "elements": [
                "contenttweaker:inner_stomach_wall@0"
            ]
        },
        {
            "x": 8,
            "y": 8,
            "z": 17,
            "elements": [
                "contenttweaker:outer_stomach_wall@0"
            ]
        },
        {
            "x": 6,
            "y": 0,
            "z": 13,
            "elements": [
                "contenttweaker:inner_stomach_wall@0"
            ]
        },
        {
            "x": 7,
            "y": 0,
            "z": 13,
            "elements": [
                "contenttweaker:outer_stomach_wall@0"
            ]
        },
        {
            "x": -8,
            "y": 9,
            "z": 17,
            "elements": [
                "contenttweaker:outer_stomach_wall@0"
            ]
        },
        {
            "x": -7,
            "y": 9,
            "z": 17,
            "elements": [
                "contenttweaker:inner_stomach_wall@0"
            ]
        },
        {
            "x": -7,
            "y": 1,
            "z": 13,
            "elements": [
                "contenttweaker:outer_stomach_wall@0"
            ]
        },
        {
            "x": -6,
            "y": 1,
            "z": 13,
            "elements": [
                "contenttweaker:inner_stomach_wall@0"
            ]
        },
        {
            "x": 7,
            "y": 9,
            "z": 17,
            "elements": [
                "contenttweaker:inner_stomach_wall@0"
            ]
        },
        {
            "x": 0,
            "y": -7,
            "z": 9,
            "elements": [
                "contenttweaker:outer_stomach_wall@0"
            ]
        },
        {
            "x": 8,
            "y": 9,
            "z": 17,
            "elements": [
                "contenttweaker:outer_stomach_wall@0"
            ]
        },
        {
            "x": 6,
            "y": 1,
            "z": 13,
            "elements": [
                "contenttweaker:inner_stomach_wall@0"
            ]
        },
        {
            "x": 7,
            "y": 1,
            "z": 13,
            "elements": [
                "contenttweaker:outer_stomach_wall@0"
            ]
        },
        {
            "x": -8,
            "y": 10,
            "z": 17,
            "elements": [
                "contenttweaker:outer_stomach_wall@0"
            ]
        },
        {
            "x": -7,
            "y": 10,
            "z": 17,
            "elements": [
                "contenttweaker:inner_stomach_wall@0"
            ]
        },
        {
            "x": -7,
            "y": 2,
            "z": 13,
            "elements": [
                "contenttweaker:outer_stomach_wall@0"
            ]
        },
        {
            "x": -6,
            "y": 2,
            "z": 13,
            "elements": [
                "contenttweaker:inner_stomach_wall@0"
            ]
        },
        {
            "x": -3,
            "y": -6,
            "z": 9,
            "elements": [
                "contenttweaker:outer_stomach_wall@0"
            ]
        },
        {
            "x": -2,
            "y": -6,
            "z": 9,
            "elements": [
                "contenttweaker:outer_stomach_wall@0"
            ]
        },
        {
            "x": -1,
            "y": -6,
            "z": 9,
            "elements": [
                "contenttweaker:outer_stomach_wall@0"
            ]
        },
        {
            "x": 7,
            "y": 10,
            "z": 17,
            "elements": [
                "contenttweaker:inner_stomach_wall@0"
            ]
        },
        {
            "x": 8,
            "y": 10,
            "z": 17,
            "elements": [
                "contenttweaker:outer_stomach_wall@0"
            ]
        },
        {
            "x": 1,
            "y": -6,
            "z": 9,
            "elements": [
                "contenttweaker:outer_stomach_wall@0"
            ]
        },
        {
            "x": 6,
            "y": 2,
            "z": 13,
            "elements": [
                "contenttweaker:inner_stomach_wall@0"
            ]
        },
        {
            "x": 2,
            "y": -6,
            "z": 9,
            "elements": [
                "contenttweaker:outer_stomach_wall@0"
            ]
        },
        {
            "x": 7,
            "y": 2,
            "z": 13,
            "elements": [
                "contenttweaker:outer_stomach_wall@0"
            ]
        },
        {
            "x": 3,
            "y": -6,
            "z": 9,
            "elements": [
                "contenttweaker:outer_stomach_wall@0"
            ]
        },
        {
            "x": 4,
            "y": -6,
            "z": 9,
            "elements": [
                "contenttweaker:outer_stomach_wall@0"
            ]
        },
        {
            "x": -8,
            "y": 11,
            "z": 17,
            "elements": [
                "contenttweaker:outer_stomach_wall@0"
            ]
        },
        {
            "x": -7,
            "y": 11,
            "z": 17,
            "elements": [
                "contenttweaker:inner_stomach_wall@0"
            ]
        },
        {
            "x": -7,
            "y": 3,
            "z": 13,
            "elements": [
                "contenttweaker:outer_stomach_wall@0"
            ]
        },
        {
            "x": -6,
            "y": 3,
            "z": 13,
            "elements": [
                "contenttweaker:inner_stomach_wall@0"
            ]
        },
        {
            "x": -5,
            "y": -5,
            "z": 9,
            "elements": [
                "contenttweaker:outer_stomach_wall@0"
            ]
        },
        {
            "x": -4,
            "y": -5,
            "z": 9,
            "elements": [
                "contenttweaker:outer_stomach_wall@0"
            ]
        },
        {
            "x": -3,
            "y": -5,
            "z": 9,
            "elements": [
                "contenttweaker:inner_stomach_wall@0"
            ]
        },
        {
            "x": -2,
            "y": -5,
            "z": 9,
            "elements": [
                "contenttweaker:inner_stomach_wall@0"
            ]
        },
        {
            "x": -1,
            "y": -5,
            "z": 9,
            "elements": [
                "contenttweaker:inner_stomach_wall@0"
            ]
        },
        {
            "x": 7,
            "y": 11,
            "z": 17,
            "elements": [
                "contenttweaker:inner_stomach_wall@0"
            ]
        },
        {
            "x": 0,
            "y": -5,
            "z": 9,
            "elements": [
                "contenttweaker:inner_stomach_wall@0"
            ]
        },
        {
            "x": 8,
            "y": 11,
            "z": 17,
            "elements": [
                "contenttweaker:outer_stomach_wall@0"
            ]
        },
        {
            "x": 1,
            "y": -5,
            "z": 9,
            "elements": [
                "contenttweaker:inner_stomach_wall@0"
            ]
        },
        {
            "x": 6,
            "y": 3,
            "z": 13,
            "elements": [
                "contenttweaker:inner_stomach_wall@0"
            ]
        },
        {
            "x": 2,
            "y": -5,
            "z": 9,
            "elements": [
                "contenttweaker:inner_stomach_wall@0"
            ]
        },
        {
            "x": 7,
            "y": 3,
            "z": 13,
            "elements": [
                "contenttweaker:outer_stomach_wall@0"
            ]
        },
        {
            "x": 5,
            "y": -5,
            "z": 9,
            "elements": [
                "contenttweaker:outer_stomach_wall@0"
            ]
        },
        {
            "x": -7,
            "y": 12,
            "z": 17,
            "elements": [
                "contenttweaker:outer_stomach_wall@0"
            ]
        },
        {
            "x": -6,
            "y": 12,
            "z": 17,
            "elements": [
                "contenttweaker:inner_stomach_wall@0"
            ]
        },
        {
            "x": -7,
            "y": 4,
            "z": 13,
            "elements": [
                "contenttweaker:outer_stomach_wall@0"
            ]
        },
        {
            "x": -6,
            "y": 4,
            "z": 13,
            "elements": [
                "contenttweaker:inner_stomach_wall@0"
            ]
        },
        {
            "x": -6,
            "y": -4,
            "z": 9,
            "elements": [
                "contenttweaker:outer_stomach_wall@0"
            ]
        },
        {
            "x": -5,
            "y": -4,
            "z": 9,
            "elements": [
                "contenttweaker:inner_stomach_wall@0"
            ]
        },
        {
            "x": -4,
            "y": -4,
            "z": 9,
            "elements": [
                "contenttweaker:inner_stomach_wall@0"
            ]
        },
        {
            "x": 6,
            "y": 12,
            "z": 17,
            "elements": [
                "contenttweaker:inner_stomach_wall@0"
            ]
        },
        {
            "x": 7,
            "y": 12,
            "z": 17,
            "elements": [
                "contenttweaker:outer_stomach_wall@0"
            ]
        },
        {
            "x": 6,
            "y": 4,
            "z": 13,
            "elements": [
                "contenttweaker:inner_stomach_wall@0"
            ]
        },
        {
            "x": 7,
            "y": 4,
            "z": 13,
            "elements": [
                "contenttweaker:outer_stomach_wall@0"
            ]
        },
        {
            "x": 3,
            "y": -4,
            "z": 9,
            "elements": [
                "contenttweaker:inner_stomach_wall@0"
            ]
        },
        {
            "x": 4,
            "y": -4,
            "z": 9,
            "elements": [
                "contenttweaker:inner_stomach_wall@0"
            ]
        },
        {
            "x": 5,
            "y": -4,
            "z": 9,
            "elements": [
                "contenttweaker:inner_stomach_wall@0"
            ]
        },
        {
            "x": 6,
            "y": -4,
            "z": 9,
            "elements": [
                "contenttweaker:outer_stomach_wall@0"
            ]
        },
        {
            "x": -7,
            "y": 13,
            "z": 17,
            "elements": [
                "contenttweaker:outer_stomach_wall@0"
            ]
        },
        {
            "x": -6,
            "y": 13,
            "z": 17,
            "elements": [
                "contenttweaker:inner_stomach_wall@0"
            ]
        },
        {
            "x": -7,
            "y": 5,
            "z": 13,
            "elements": [
                "contenttweaker:outer_stomach_wall@0"
            ]
        },
        {
            "x": -6,
            "y": 5,
            "z": 13,
            "elements": [
                "contenttweaker:inner_stomach_wall@0"
            ]
        },
        {
            "x": -7,
            "y": -3,
            "z": 9,
            "elements": [
                "contenttweaker:outer_stomach_wall@0"
            ]
        },
        {
            "x": -6,
            "y": -3,
            "z": 9,
            "elements": [
                "contenttweaker:inner_stomach_wall@0"
            ]
        },
        {
            "x": 6,
            "y": 13,
            "z": 17,
            "elements": [
                "contenttweaker:inner_stomach_wall@0"
            ]
        },
        {
            "x": 7,
            "y": 13,
            "z": 17,
            "elements": [
                "contenttweaker:outer_stomach_wall@0"
            ]
        },
        {
            "x": 6,
            "y": 5,
            "z": 13,
            "elements": [
                "contenttweaker:inner_stomach_wall@0"
            ]
        },
        {
            "x": 7,
            "y": 5,
            "z": 13,
            "elements": [
                "contenttweaker:outer_stomach_wall@0"
            ]
        },
        {
            "x": 6,
            "y": -3,
            "z": 9,
            "elements": [
                "contenttweaker:inner_stomach_wall@0"
            ]
        },
        {
            "x": 7,
            "y": -3,
            "z": 9,
            "elements": [
                "contenttweaker:outer_stomach_wall@0"
            ]
        },
        {
            "x": -6,
            "y": 14,
            "z": 17,
            "elements": [
                "contenttweaker:outer_stomach_wall@0"
            ]
        },
        {
            "x": -5,
            "y": 14,
            "z": 17,
            "elements": [
                "contenttweaker:inner_stomach_wall@0"
            ]
        },
        {
            "x": -7,
            "y": 6,
            "z": 13,
            "elements": [
                "contenttweaker:outer_stomach_wall@0"
            ]
        },
        {
            "x": -6,
            "y": 6,
            "z": 13,
            "elements": [
                "contenttweaker:inner_stomach_wall@0"
            ]
        },
        {
            "x": -7,
            "y": -2,
            "z": 9,
            "elements": [
                "contenttweaker:outer_stomach_wall@0"
            ]
        },
        {
            "x": -6,
            "y": -2,
            "z": 9,
            "elements": [
                "contenttweaker:inner_stomach_wall@0"
            ]
        },
        {
            "x": 5,
            "y": 14,
            "z": 17,
            "elements": [
                "contenttweaker:inner_stomach_wall@0"
            ]
        },
        {
            "x": 6,
            "y": 14,
            "z": 17,
            "elements": [
                "contenttweaker:outer_stomach_wall@0"
            ]
        },
        {
            "x": 6,
            "y": 6,
            "z": 13,
            "elements": [
                "contenttweaker:inner_stomach_wall@0"
            ]
        },
        {
            "x": 7,
            "y": 6,
            "z": 13,
            "elements": [
                "contenttweaker:outer_stomach_wall@0"
            ]
        },
        {
            "x": 6,
            "y": -2,
            "z": 9,
            "elements": [
                "contenttweaker:inner_stomach_wall@0"
            ]
        },
        {
            "x": 7,
            "y": -2,
            "z": 9,
            "elements": [
                "contenttweaker:outer_stomach_wall@0"
            ]
        },
        {
            "x": -5,
            "y": 15,
            "z": 17,
            "elements": [
                "contenttweaker:outer_stomach_wall@0"
            ]
        },
        {
            "x": -4,
            "y": 15,
            "z": 17,
            "elements": [
                "contenttweaker:inner_stomach_wall@0"
            ]
        },
        {
            "x": -3,
            "y": 15,
            "z": 17,
            "elements": [
                "contenttweaker:inner_stomach_wall@0"
            ]
        },
        {
            "x": -6,
            "y": 7,
            "z": 13,
            "elements": [
                "contenttweaker:outer_stomach_wall@0"
            ]
        },
        {
            "x": -5,
            "y": 7,
            "z": 13,
            "elements": [
                "contenttweaker:inner_stomach_wall@0"
            ]
        },
        {
            "x": 0,
            "y": 15,
            "z": 17,
            "elements": [
                "adchimneys:nether_wart_block@1"
            ]
        },
        {
            "x": 1,
            "y": 15,
            "z": 17,
            "elements": [
                "adchimneys:nether_wart_block@1"
            ]
        },
        {
            "x": -7,
            "y": -1,
            "z": 9,
            "elements": [
                "contenttweaker:outer_stomach_wall@0"
            ]
        },
        {
            "x": -6,
            "y": -1,
            "z": 9,
            "elements": [
                "contenttweaker:inner_stomach_wall@0"
            ]
        },
        {
            "x": 3,
            "y": 15,
            "z": 17,
            "elements": [
                "contenttweaker:inner_stomach_wall@0"
            ]
        },
        {
            "x": 4,
            "y": 15,
            "z": 17,
            "elements": [
                "contenttweaker:inner_stomach_wall@0"
            ]
        },
        {
            "x": 5,
            "y": 15,
            "z": 17,
            "elements": [
                "contenttweaker:outer_stomach_wall@0"
            ]
        },
        {
            "x": 6,
            "y": 7,
            "z": 13,
            "elements": [
                "contenttweaker:inner_stomach_wall@0"
            ]
        },
        {
            "x": 7,
            "y": 7,
            "z": 13,
            "elements": [
                "contenttweaker:outer_stomach_wall@0"
            ]
        },
        {
            "x": 6,
            "y": -1,
            "z": 9,
            "elements": [
                "contenttweaker:inner_stomach_wall@0"
            ]
        },
        {
            "x": 7,
            "y": -1,
            "z": 9,
            "elements": [
                "contenttweaker:outer_stomach_wall@0"
            ]
        },
        {
            "x": -4,
            "y": 16,
            "z": 17,
            "elements": [
                "contenttweaker:outer_stomach_wall@0"
            ]
        },
        {
            "x": -3,
            "y": 16,
            "z": 17,
            "elements": [
                "contenttweaker:outer_stomach_wall@0"
            ]
        },
        {
            "x": -6,
            "y": 8,
            "z": 13,
            "elements": [
                "contenttweaker:outer_stomach_wall@0"
            ]
        },
        {
            "x": -2,
            "y": 16,
            "z": 17,
            "elements": [
                "contenttweaker:inner_stomach_wall@0"
            ]
        },
        {
            "x": -5,
            "y": 8,
            "z": 13,
            "elements": [
                "contenttweaker:inner_stomach_wall@0"
            ]
        },
        {
            "x": -1,
            "y": 16,
            "z": 17,
            "elements": [
                "contenttweaker:inner_stomach_wall@0"
            ]
        },
        {
            "x": 0,
            "y": 16,
            "z": 17,
            "elements": [
                "contenttweaker:inner_stomach_wall@0"
            ]
        },
        {
            "x": 1,
            "y": 16,
            "z": 17,
            "elements": [
                "contenttweaker:inner_stomach_wall@0"
            ]
        },
        {
            "x": -7,
            "y": 0,
            "z": 9,
            "elements": [
                "contenttweaker:outer_stomach_wall@0"
            ]
        },
        {
            "x": -6,
            "y": 0,
            "z": 9,
            "elements": [
                "contenttweaker:inner_stomach_wall@0"
            ]
        },
        {
            "x": 2,
            "y": 16,
            "z": 17,
            "elements": [
                "contenttweaker:inner_stomach_wall@0"
            ]
        },
        {
            "x": 3,
            "y": 16,
            "z": 17,
            "elements": [
                "contenttweaker:inner_stomach_wall@0"
            ]
        },
        {
            "x": 4,
            "y": 16,
            "z": 17,
            "elements": [
                "contenttweaker:inner_stomach_wall@0"
            ]
        },
        {
            "x": 5,
            "y": 16,
            "z": 17,
            "elements": [
                "contenttweaker:outer_stomach_wall@0"
            ]
        },
        {
            "x": 6,
            "y": 8,
            "z": 13,
            "elements": [
                "contenttweaker:inner_stomach_wall@0"
            ]
        },
        {
            "x": 7,
            "y": 8,
            "z": 13,
            "elements": [
                "contenttweaker:outer_stomach_wall@0"
            ]
        },
        {
            "x": 6,
            "y": 0,
            "z": 9,
            "elements": [
                "contenttweaker:inner_stomach_wall@0"
            ]
        },
        {
            "x": 7,
            "y": 0,
            "z": 9,
            "elements": [
                "contenttweaker:outer_stomach_wall@0"
            ]
        },
        {
            "x": -6,
            "y": 9,
            "z": 13,
            "elements": [
                "contenttweaker:outer_stomach_wall@0"
            ]
        },
        {
            "x": -2,
            "y": 17,
            "z": 17,
            "elements": [
                "contenttweaker:outer_stomach_wall@0"
            ]
        },
        {
            "x": -5,
            "y": 9,
            "z": 13,
            "elements": [
                "contenttweaker:inner_stomach_wall@0"
            ]
        },
        {
            "x": -1,
            "y": 17,
            "z": 17,
            "elements": [
                "contenttweaker:outer_stomach_wall@0"
            ]
        },
        {
            "x": 0,
            "y": 17,
            "z": 17,
            "elements": [
                "contenttweaker:outer_stomach_wall@0"
            ]
        },
        {
            "x": 1,
            "y": 17,
            "z": 17,
            "elements": [
                "contenttweaker:outer_stomach_wall@0"
            ]
        },
        {
            "x": -6,
            "y": 1,
            "z": 9,
            "elements": [
                "contenttweaker:outer_stomach_wall@0"
            ]
        },
        {
            "x": 2,
            "y": 17,
            "z": 17,
            "elements": [
                "contenttweaker:outer_stomach_wall@0"
            ]
        },
        {
            "x": -5,
            "y": 1,
            "z": 9,
            "elements": [
                "contenttweaker:inner_stomach_wall@0"
            ]
        },
        {
            "x": 3,
            "y": 17,
            "z": 17,
            "elements": [
                "contenttweaker:outer_stomach_wall@0"
            ]
        },
        {
            "x": 4,
            "y": 17,
            "z": 17,
            "elements": [
                "contenttweaker:outer_stomach_wall@0"
            ]
        },
        {
            "x": 5,
            "y": 17,
            "z": 17,
            "elements": [
                "contenttweaker:outer_stomach_wall@0"
            ]
        },
        {
            "x": 6,
            "y": 9,
            "z": 13,
            "elements": [
                "contenttweaker:inner_stomach_wall@0"
            ]
        },
        {
            "x": 7,
            "y": 9,
            "z": 13,
            "elements": [
                "contenttweaker:outer_stomach_wall@0"
            ]
        },
        {
            "x": 5,
            "y": 1,
            "z": 9,
            "elements": [
                "contenttweaker:inner_stomach_wall@0"
            ]
        },
        {
            "x": 6,
            "y": 1,
            "z": 9,
            "elements": [
                "contenttweaker:outer_stomach_wall@0"
            ]
        },
        {
            "x": -6,
            "y": 10,
            "z": 13,
            "elements": [
                "contenttweaker:outer_stomach_wall@0"
            ]
        },
        {
            "x": -5,
            "y": 10,
            "z": 13,
            "elements": [
                "contenttweaker:inner_stomach_wall@0"
            ]
        },
        {
            "x": -6,
            "y": 2,
            "z": 9,
            "elements": [
                "contenttweaker:outer_stomach_wall@0"
            ]
        },
        {
            "x": -5,
            "y": 2,
            "z": 9,
            "elements": [
                "contenttweaker:inner_stomach_wall@0"
            ]
        },
        {
            "x": 3,
            "y": 18,
            "z": 17,
            "elements": [
                "contenttweaker:outer_stomach_wall@0"
            ]
        },
        {
            "x": 4,
            "y": 18,
            "z": 17,
            "elements": [
                "contenttweaker:outer_stomach_wall@0"
            ]
        },
        {
            "x": 5,
            "y": 18,
            "z": 17,
            "elements": [
                "contenttweaker:outer_stomach_wall@0"
            ]
        },
        {
            "x": 6,
            "y": 10,
            "z": 13,
            "elements": [
                "contenttweaker:inner_stomach_wall@0"
            ]
        },
        {
            "x": 7,
            "y": 10,
            "z": 13,
            "elements": [
                "contenttweaker:outer_stomach_wall@0"
            ]
        },
        {
            "x": 5,
            "y": 2,
            "z": 9,
            "elements": [
                "contenttweaker:inner_stomach_wall@0"
            ]
        },
        {
            "x": 6,
            "y": 2,
            "z": 9,
            "elements": [
                "contenttweaker:outer_stomach_wall@0"
            ]
        },
        {
            "x": -6,
            "y": 11,
            "z": 13,
            "elements": [
                "contenttweaker:outer_stomach_wall@0"
            ]
        },
        {
            "x": -5,
            "y": 11,
            "z": 13,
            "elements": [
                "contenttweaker:inner_stomach_wall@0"
            ]
        },
        {
            "x": -5,
            "y": 3,
            "z": 9,
            "elements": [
                "contenttweaker:outer_stomach_wall@0"
            ]
        },
        {
            "x": 3,
            "y": 19,
            "z": 17,
            "elements": [
                "contenttweaker:outer_stomach_wall@0"
            ]
        },
        {
            "x": 4,
            "y": 19,
            "z": 17,
            "elements": [
                "contenttweaker:outer_stomach_wall@0"
            ]
        },
        {
            "x": -4,
            "y": 3,
            "z": 9,
            "elements": [
                "contenttweaker:inner_stomach_wall@0"
            ]
        },
        {
            "x": 5,
            "y": 19,
            "z": 17,
            "elements": [
                "contenttweaker:outer_stomach_wall@0"
            ]
        },
        {
            "x": -3,
            "y": 3,
            "z": 9,
            "elements": [
                "contenttweaker:inner_stomach_wall@0"
            ]
        },
        {
            "x": 6,
            "y": 11,
            "z": 13,
            "elements": [
                "contenttweaker:inner_stomach_wall@0"
            ]
        },
        {
            "x": -1,
            "y": -5,
            "z": 5,
            "elements": [
                "contenttweaker:outer_stomach_wall@0"
            ]
        },
        {
            "x": 7,
            "y": 11,
            "z": 13,
            "elements": [
                "contenttweaker:outer_stomach_wall@0"
            ]
        },
        {
            "x": 3,
            "y": 3,
            "z": 9,
            "elements": [
                "contenttweaker:inner_stomach_wall@0"
            ]
        },
        {
            "x": 0,
            "y": -5,
            "z": 5,
            "elements": [
                "contenttweaker:outer_stomach_wall@0"
            ]
        },
        {
            "x": 4,
            "y": 3,
            "z": 9,
            "elements": [
                "contenttweaker:inner_stomach_wall@0"
            ]
        },
        {
            "x": 5,
            "y": 3,
            "z": 9,
            "elements": [
                "contenttweaker:outer_stomach_wall@0"
            ]
        },
        {
            "x": 1,
            "y": -5,
            "z": 5,
            "elements": [
                "contenttweaker:outer_stomach_wall@0"
            ]
        },
        {
            "x": -1,
            "y": 5,
            "z": 26,
            "elements": [
                "contenttweaker:outer_stomach_wall@0"
            ]
        },
        {
            "x": 0,
            "y": 5,
            "z": 26,
            "elements": [
                "contenttweaker:outer_stomach_wall@0"
            ]
        },
        {
            "x": 1,
            "y": 5,
            "z": 26,
            "elements": [
                "contenttweaker:outer_stomach_wall@0"
            ]
        },
        {
            "x": 2,
            "y": 5,
            "z": 26,
            "elements": [
                "contenttweaker:outer_stomach_wall@0"
            ]
        },
        {
            "x": -5,
            "y": 12,
            "z": 13,
            "elements": [
                "contenttweaker:outer_stomach_wall@0"
            ]
        },
        {
            "x": -4,
            "y": 12,
            "z": 13,
            "elements": [
                "contenttweaker:inner_stomach_wall@0"
            ]
        },
        {
            "x": -4,
            "y": 4,
            "z": 9,
            "elements": [
                "contenttweaker:outer_stomach_wall@0"
            ]
        },
        {
            "x": -2,
            "y": 4,
            "z": 9,
            "elements": [
                "contenttweaker:inner_stomach_wall@0"
            ]
        },
        {
            "x": 6,
            "y": 12,
            "z": 13,
            "elements": [
                "contenttweaker:inner_stomach_wall@0"
            ]
        },
        {
            "x": 2,
            "y": 4,
            "z": 9,
            "elements": [
                "contenttweaker:inner_stomach_wall@0"
            ]
        },
        {
            "x": -2,
            "y": -4,
            "z": 5,
            "elements": [
                "contenttweaker:outer_stomach_wall@0"
            ]
        },
        {
            "x": -1,
            "y": -4,
            "z": 5,
            "elements": [
                "contenttweaker:inner_stomach_wall@0"
            ]
        },
        {
            "x": 7,
            "y": 12,
            "z": 13,
            "elements": [
                "contenttweaker:outer_stomach_wall@0"
            ]
        },
        {
            "x": 0,
            "y": -4,
            "z": 5,
            "elements": [
                "contenttweaker:inner_stomach_wall@0"
            ]
        },
        {
            "x": 4,
            "y": 4,
            "z": 9,
            "elements": [
                "contenttweaker:outer_stomach_wall@0"
            ]
        },
        {
            "x": 1,
            "y": -4,
            "z": 5,
            "elements": [
                "contenttweaker:inner_stomach_wall@0"
            ]
        },
        {
            "x": 2,
            "y": -4,
            "z": 5,
            "elements": [
                "contenttweaker:outer_stomach_wall@0"
            ]
        },
        {
            "x": 3,
            "y": -4,
            "z": 5,
            "elements": [
                "contenttweaker:outer_stomach_wall@0"
            ]
        },
        {
            "x": -2,
            "y": 6,
            "z": 26,
            "elements": [
                "contenttweaker:outer_stomach_wall@0"
            ]
        },
        {
            "x": -1,
            "y": 6,
            "z": 26,
            "elements": [
                "contenttweaker:outer_stomach_wall@0"
            ]
        },
        {
            "x": 0,
            "y": 6,
            "z": 26,
            "elements": [
                "contenttweaker:outer_stomach_wall@0"
            ]
        },
        {
            "x": 1,
            "y": 6,
            "z": 26,
            "elements": [
                "contenttweaker:outer_stomach_wall@0"
            ]
        },
        {
            "x": -2,
            "y": -2,
            "z": 22,
            "elements": [
                "contenttweaker:outer_stomach_wall@0"
            ]
        },
        {
            "x": 2,
            "y": 6,
            "z": 26,
            "elements": [
                "contenttweaker:outer_stomach_wall@0"
            ]
        },
        {
            "x": -1,
            "y": -2,
            "z": 22,
            "elements": [
                "contenttweaker:outer_stomach_wall@0"
            ]
        },
        {
            "x": 0,
            "y": -2,
            "z": 22,
            "elements": [
                "contenttweaker:outer_stomach_wall@0"
            ]
        },
        {
            "x": 1,
            "y": -2,
            "z": 22,
            "elements": [
                "contenttweaker:outer_stomach_wall@0"
            ]
        },
        {
            "x": 2,
            "y": -2,
            "z": 22,
            "elements": [
                "contenttweaker:outer_stomach_wall@0"
            ]
        },
        {
            "x": -4,
            "y": 13,
            "z": 13,
            "elements": [
                "contenttweaker:outer_stomach_wall@0"
            ]
        },
        {
            "x": -3,
            "y": 13,
            "z": 13,
            "elements": [
                "contenttweaker:inner_stomach_wall@0"
            ]
        },
        {
            "x": -4,
            "y": 5,
            "z": 9,
            "elements": [
                "contenttweaker:outer_stomach_wall@0"
            ]
        },
        {
            "x": -3,
            "y": 5,
            "z": 9,
            "elements": [
                "contenttweaker:outer_stomach_wall@0"
            ]
        },
        {
            "x": -2,
            "y": 5,
            "z": 9,
            "elements": [
                "contenttweaker:outer_stomach_wall@0"
            ]
        },
        {
            "x": -1,
            "y": 5,
            "z": 9,
            "elements": [
                "contenttweaker:inner_stomach_wall@0"
            ]
        },
        {
            "x": 4,
            "y": 13,
            "z": 13,
            "elements": [
                "contenttweaker:sinking_stomach_wall@0"
            ]
        },
        {
            "x": 0,
            "y": 5,
            "z": 9,
            "elements": [
                "contenttweaker:inner_stomach_wall@0"
            ]
        },
        {
            "x": 5,
            "y": 13,
            "z": 13,
            "elements": [
                "contenttweaker:sinking_stomach_wall@0"
            ]
        },
        {
            "x": 1,
            "y": 5,
            "z": 9,
            "elements": [
                "contenttweaker:inner_stomach_wall@0"
            ]
        },
        {
            "x": -3,
            "y": -3,
            "z": 5,
            "elements": [
                "contenttweaker:outer_stomach_wall@0"
            ]
        },
        {
            "x": -2,
            "y": -3,
            "z": 5,
            "elements": [
                "contenttweaker:inner_stomach_wall@0"
            ]
        },
        {
            "x": 2,
            "y": 5,
            "z": 9,
            "elements": [
                "contenttweaker:outer_stomach_wall@0"
            ]
        },
        {
            "x": 7,
            "y": 13,
            "z": 13,
            "elements": [
                "contenttweaker:outer_stomach_wall@0"
            ]
        },
        {
            "x": 3,
            "y": 5,
            "z": 9,
            "elements": [
                "contenttweaker:outer_stomach_wall@0"
            ]
        },
        {
            "x": 4,
            "y": 5,
            "z": 9,
            "elements": [
                "contenttweaker:outer_stomach_wall@0"
            ]
        },
        {
            "x": 2,
            "y": -3,
            "z": 5,
            "elements": [
                "contenttweaker:inner_stomach_wall@0"
            ]
        },
        {
            "x": 3,
            "y": -3,
            "z": 5,
            "elements": [
                "contenttweaker:inner_stomach_wall@0"
            ]
        },
        {
            "x": 4,
            "y": -3,
            "z": 5,
            "elements": [
                "contenttweaker:outer_stomach_wall@0"
            ]
        },
        {
            "x": -2,
            "y": 7,
            "z": 26,
            "elements": [
                "contenttweaker:outer_stomach_wall@0"
            ]
        },
        {
            "x": -1,
            "y": 7,
            "z": 26,
            "elements": [
                "contenttweaker:outer_stomach_wall@0"
            ]
        },
        {
            "x": 0,
            "y": 7,
            "z": 26,
            "elements": [
                "contenttweaker:outer_stomach_wall@0"
            ]
        },
        {
            "x": 1,
            "y": 7,
            "z": 26,
            "elements": [
                "contenttweaker:outer_stomach_wall@0"
            ]
        },
        {
            "x": -3,
            "y": -1,
            "z": 22,
            "elements": [
                "contenttweaker:outer_stomach_wall@0"
            ]
        },
        {
            "x": -2,
            "y": -1,
            "z": 22,
            "elements": [
                "contenttweaker:inner_stomach_wall@0"
            ]
        },
        {
            "x": 2,
            "y": 7,
            "z": 26,
            "elements": [
                "contenttweaker:outer_stomach_wall@0"
            ]
        },
        {
            "x": -1,
            "y": -1,
            "z": 22,
            "elements": [
                "contenttweaker:inner_stomach_wall@0"
            ]
        },
        {
            "x": 0,
            "y": -1,
            "z": 22,
            "elements": [
                "contenttweaker:inner_stomach_wall@0"
            ]
        },
        {
            "x": 1,
            "y": -1,
            "z": 22,
            "elements": [
                "contenttweaker:inner_stomach_wall@0"
            ]
        },
        {
            "x": 2,
            "y": -1,
            "z": 22,
            "elements": [
                "contenttweaker:inner_stomach_wall@0"
            ]
        },
        {
            "x": 3,
            "y": -1,
            "z": 22,
            "elements": [
                "contenttweaker:outer_stomach_wall@0"
            ]
        },
        {
            "x": -3,
            "y": 14,
            "z": 13,
            "elements": [
                "contenttweaker:outer_stomach_wall@0"
            ]
        },
        {
            "x": -2,
            "y": 14,
            "z": 13,
            "elements": [
                "contenttweaker:inner_stomach_wall@0"
            ]
        },
        {
            "x": -1,
            "y": 14,
            "z": 13,
            "elements": [
                "contenttweaker:inner_stomach_wall@0"
            ]
        },
        {
            "x": 0,
            "y": 14,
            "z": 13,
            "elements": [
                "contenttweaker:inner_stomach_wall@0"
            ]
        },
        {
            "x": 1,
            "y": 14,
            "z": 13,
            "elements": [
                "contenttweaker:inner_stomach_wall@0"
            ]
        },
        {
            "x": -3,
            "y": 6,
            "z": 9,
            "elements": [
                "contenttweaker:outer_stomach_wall@0"
            ]
        },
        {
            "x": -2,
            "y": 6,
            "z": 9,
            "elements": [
                "contenttweaker:outer_stomach_wall@0"
            ]
        },
        {
            "x": 2,
            "y": 14,
            "z": 13,
            "elements": [
                "contenttweaker:inner_stomach_wall@0"
            ]
        },
        {
            "x": -1,
            "y": 6,
            "z": 9,
            "elements": [
                "contenttweaker:outer_stomach_wall@0"
            ]
        },
        {
            "x": 3,
            "y": 14,
            "z": 13,
            "elements": [
                "contenttweaker:sinking_stomach_wall@0"
            ]
        },
        {
            "x": 4,
            "y": 14,
            "z": 13,
            "elements": [
                "contenttweaker:sinking_stomach_wall@0"
            ]
        },
        {
            "x": 0,
            "y": 6,
            "z": 9,
            "elements": [
                "contenttweaker:outer_stomach_wall@0"
            ]
        },
        {
            "x": -4,
            "y": -2,
            "z": 5,
            "elements": [
                "contenttweaker:outer_stomach_wall@0"
            ]
        },
        {
            "x": 5,
            "y": 14,
            "z": 13,
            "elements": [
                "contenttweaker:sinking_stomach_wall@0"
            ]
        },
        {
            "x": 1,
            "y": 6,
            "z": 9,
            "elements": [
                "contenttweaker:outer_stomach_wall@0"
            ]
        },
        {
            "x": -3,
            "y": -2,
            "z": 5,
            "elements": [
                "contenttweaker:inner_stomach_wall@0"
            ]
        },
        {
            "x": 6,
            "y": 14,
            "z": 13,
            "elements": [
                "contenttweaker:inner_stomach_wall@0"
            ]
        },
        {
            "x": 2,
            "y": 6,
            "z": 9,
            "elements": [
                "contenttweaker:outer_stomach_wall@0"
            ]
        },
        {
            "x": 7,
            "y": 14,
            "z": 13,
            "elements": [
                "contenttweaker:outer_stomach_wall@0"
            ]
        },
        {
            "x": 3,
            "y": 6,
            "z": 9,
            "elements": [
                "contenttweaker:outer_stomach_wall@0"
            ]
        },
        {
            "x": 3,
            "y": -2,
            "z": 5,
            "elements": [
                "contenttweaker:inner_stomach_wall@0"
            ]
        },
        {
            "x": 4,
            "y": -2,
            "z": 5,
            "elements": [
                "contenttweaker:inner_stomach_wall@0"
            ]
        },
        {
            "x": 5,
            "y": -2,
            "z": 5,
            "elements": [
                "contenttweaker:outer_stomach_wall@0"
            ]
        },
        {
            "x": -2,
            "y": 8,
            "z": 26,
            "elements": [
                "contenttweaker:outer_stomach_wall@0"
            ]
        },
        {
            "x": -1,
            "y": 8,
            "z": 26,
            "elements": [
                "contenttweaker:outer_stomach_wall@0"
            ]
        },
        {
            "x": 0,
            "y": 8,
            "z": 26,
            "elements": [
                "contenttweaker:outer_stomach_wall@0"
            ]
        },
        {
            "x": -4,
            "y": 0,
            "z": 22,
            "elements": [
                "contenttweaker:outer_stomach_wall@0"
            ]
        },
        {
            "x": 1,
            "y": 8,
            "z": 26,
            "elements": [
                "contenttweaker:outer_stomach_wall@0"
            ]
        },
        {
            "x": -3,
            "y": 0,
            "z": 22,
            "elements": [
                "contenttweaker:inner_stomach_wall@0"
            ]
        },
        {
            "x": -2,
            "y": 0,
            "z": 22,
            "elements": [
                "contenttweaker:inner_stomach_wall@0"
            ]
        },
        {
            "x": 2,
            "y": 8,
            "z": 26,
            "elements": [
                "contenttweaker:outer_stomach_wall@0"
            ]
        },
        {
            "x": -1,
            "y": 0,
            "z": 22,
            "elements": [
                "contenttweaker:inner_stomach_wall@0"
            ]
        },
        {
            "x": 0,
            "y": 0,
            "z": 22,
            "elements": [
                "contenttweaker:inner_stomach_wall@0"
            ]
        },
        {
            "x": 1,
            "y": 0,
            "z": 22,
            "elements": [
                "contenttweaker:inner_stomach_wall@0"
            ]
        },
        {
            "x": 2,
            "y": 0,
            "z": 22,
            "elements": [
                "contenttweaker:inner_stomach_wall@0"
            ]
        },
        {
            "x": 3,
            "y": 0,
            "z": 22,
            "elements": [
                "contenttweaker:inner_stomach_wall@0"
            ]
        },
        {
            "x": 4,
            "y": 0,
            "z": 22,
            "elements": [
                "contenttweaker:outer_stomach_wall@0"
            ]
        },
        {
            "x": -2,
            "y": 15,
            "z": 13,
            "elements": [
                "contenttweaker:outer_stomach_wall@0"
            ]
        },
        {
            "x": -1,
            "y": 15,
            "z": 13,
            "elements": [
                "contenttweaker:outer_stomach_wall@0"
            ]
        },
        {
            "x": 0,
            "y": 15,
            "z": 13,
            "elements": [
                "contenttweaker:outer_stomach_wall@0"
            ]
        },
        {
            "x": 1,
            "y": 15,
            "z": 13,
            "elements": [
                "contenttweaker:outer_stomach_wall@0"
            ]
        },
        {
            "x": -2,
            "y": 7,
            "z": 9,
            "elements": [
                "contenttweaker:outer_stomach_wall@0"
            ]
        },
        {
            "x": 2,
            "y": 15,
            "z": 13,
            "elements": [
                "contenttweaker:inner_stomach_wall@0"
            ]
        },
        {
            "x": -1,
            "y": 7,
            "z": 9,
            "elements": [
                "contenttweaker:outer_stomach_wall@0"
            ]
        },
        {
            "x": 3,
            "y": 15,
            "z": 13,
            "elements": [
                "contenttweaker:sinking_stomach_wall@0"
            ]
        },
        {
            "x": 4,
            "y": 15,
            "z": 13,
            "elements": [
                "contenttweaker:sinking_stomach_wall@0"
            ]
        },
        {
            "x": 0,
            "y": 7,
            "z": 9,
            "elements": [
                "contenttweaker:outer_stomach_wall@0"
            ]
        },
        {
            "x": -4,
            "y": -1,
            "z": 5,
            "elements": [
                "contenttweaker:outer_stomach_wall@0"
            ]
        },
        {
            "x": 5,
            "y": 15,
            "z": 13,
            "elements": [
                "contenttweaker:sinking_stomach_wall@0"
            ]
        },
        {
            "x": 1,
            "y": 7,
            "z": 9,
            "elements": [
                "contenttweaker:outer_stomach_wall@0"
            ]
        },
        {
            "x": -3,
            "y": -1,
            "z": 5,
            "elements": [
                "contenttweaker:inner_stomach_wall@0"
            ]
        },
        {
            "x": 6,
            "y": 15,
            "z": 13,
            "elements": [
                "contenttweaker:inner_stomach_wall@0"
            ]
        },
        {
            "x": 2,
            "y": 7,
            "z": 9,
            "elements": [
                "contenttweaker:outer_stomach_wall@0"
            ]
        },
        {
            "x": 7,
            "y": 15,
            "z": 13,
            "elements": [
                "contenttweaker:outer_stomach_wall@0"
            ]
        },
        {
            "x": 3,
            "y": -1,
            "z": 5,
            "elements": [
                "contenttweaker:inner_stomach_wall@0"
            ]
        },
        {
            "x": 4,
            "y": -1,
            "z": 5,
            "elements": [
                "contenttweaker:inner_stomach_wall@0"
            ]
        },
        {
            "x": 5,
            "y": -1,
            "z": 5,
            "elements": [
                "contenttweaker:outer_stomach_wall@0"
            ]
        },
        {
            "x": -2,
            "y": 9,
            "z": 26,
            "elements": [
                "contenttweaker:outer_stomach_wall@0"
            ]
        },
        {
            "x": -5,
            "y": 1,
            "z": 22,
            "elements": [
                "contenttweaker:outer_stomach_wall@0"
            ]
        },
        {
            "x": -1,
            "y": 9,
            "z": 26,
            "elements": [
                "contenttweaker:outer_stomach_wall@0"
            ]
        },
        {
            "x": 0,
            "y": 9,
            "z": 26,
            "elements": [
                "contenttweaker:outer_stomach_wall@0"
            ]
        },
        {
            "x": -4,
            "y": 1,
            "z": 22,
            "elements": [
                "contenttweaker:inner_stomach_wall@0"
            ]
        },
        {
            "x": 1,
            "y": 9,
            "z": 26,
            "elements": [
                "contenttweaker:outer_stomach_wall@0"
            ]
        },
        {
            "x": -3,
            "y": 1,
            "z": 22,
            "elements": [
                "contenttweaker:inner_stomach_wall@0"
            ]
        },
        {
            "x": -2,
            "y": 1,
            "z": 22,
            "elements": [
                "tconstruct:slime_channel@0"
            ]
        },
        {
            "x": 2,
            "y": 9,
            "z": 26,
            "elements": [
                "contenttweaker:outer_stomach_wall@0"
            ]
        },
        {
            "x": -1,
            "y": 1,
            "z": 22,
            "elements": [
                "tconstruct:slime_channel@0"
            ]
        },
        {
            "x": 0,
            "y": 1,
            "z": 22,
            "elements": [
                "tconstruct:slime_channel@0"
            ]
        },
        {
            "x": 1,
            "y": 1,
            "z": 22,
            "elements": [
                "tconstruct:slime_channel@0"
            ]
        },
        {
            "x": 2,
            "y": 1,
            "z": 22,
            "elements": [
                "tconstruct:slime_channel@0"
            ]
        },
        {
            "x": 3,
            "y": 1,
            "z": 22,
            "elements": [
                "contenttweaker:inner_stomach_wall@0"
            ]
        },
        {
            "x": 4,
            "y": 1,
            "z": 22,
            "elements": [
                "contenttweaker:inner_stomach_wall@0"
            ]
        },
        {
            "x": 5,
            "y": 1,
            "z": 22,
            "elements": [
                "contenttweaker:outer_stomach_wall@0"
            ]
        },
        {
            "x": 1,
            "y": 16,
            "z": 13,
            "elements": [
                "contenttweaker:outer_stomach_wall@0"
            ]
        },
        {
            "x": 2,
            "y": 16,
            "z": 13,
            "elements": [
                "contenttweaker:inner_stomach_wall@0"
            ]
        },
        {
            "x": 3,
            "y": 16,
            "z": 13,
            "elements": [
                "contenttweaker:sinking_stomach_wall@0"
            ]
        },
        {
            "x": 4,
            "y": 16,
            "z": 13,
            "elements": [
                "contenttweaker:sinking_stomach_wall@0"
            ]
        },
        {
            "x": -4,
            "y": 0,
            "z": 5,
            "elements": [
                "contenttweaker:outer_stomach_wall@0"
            ]
        },
        {
            "x": 5,
            "y": 16,
            "z": 13,
            "elements": [
                "contenttweaker:sinking_stomach_wall@0"
            ]
        },
        {
            "x": -3,
            "y": 0,
            "z": 5,
            "elements": [
                "contenttweaker:inner_stomach_wall@0"
            ]
        },
        {
            "x": 6,
            "y": 16,
            "z": 13,
            "elements": [
                "contenttweaker:inner_stomach_wall@0"
            ]
        },
        {
            "x": 7,
            "y": 16,
            "z": 13,
            "elements": [
                "contenttweaker:outer_stomach_wall@0"
            ]
        },
        {
            "x": 3,
            "y": 0,
            "z": 5,
            "elements": [
                "contenttweaker:inner_stomach_wall@0"
            ]
        },
        {
            "x": 4,
            "y": 0,
            "z": 5,
            "elements": [
                "contenttweaker:outer_stomach_wall@0"
            ]
        },
        {
            "x": -2,
            "y": 10,
            "z": 26,
            "elements": [
                "contenttweaker:outer_stomach_wall@0"
            ]
        },
        {
            "x": -5,
            "y": 2,
            "z": 22,
            "elements": [
                "contenttweaker:outer_stomach_wall@0"
            ]
        },
        {
            "x": -1,
            "y": 10,
            "z": 26,
            "elements": [
                "contenttweaker:outer_stomach_wall@0"
            ]
        },
        {
            "x": 0,
            "y": 10,
            "z": 26,
            "elements": [
                "contenttweaker:outer_stomach_wall@0"
            ]
        },
        {
            "x": -4,
            "y": 2,
            "z": 22,
            "elements": [
                "contenttweaker:inner_stomach_wall@0"
            ]
        },
        {
            "x": 1,
            "y": 10,
            "z": 26,
            "elements": [
                "contenttweaker:outer_stomach_wall@0"
            ]
        },
        {
            "x": -3,
            "y": 2,
            "z": 22,
            "elements": [
                "contenttweaker:inner_stomach_wall@0"
            ]
        },
        {
            "x": 2,
            "y": 10,
            "z": 26,
            "elements": [
                "contenttweaker:outer_stomach_wall@0"
            ]
        },
        {
            "x": 3,
            "y": 2,
            "z": 22,
            "elements": [
                "contenttweaker:inner_stomach_wall@0"
            ]
        },
        {
            "x": 4,
            "y": 2,
            "z": 22,
            "elements": [
                "contenttweaker:inner_stomach_wall@0"
            ]
        },
        {
            "x": 5,
            "y": 2,
            "z": 22,
            "elements": [
                "contenttweaker:outer_stomach_wall@0"
            ]
        },
        {
            "x": 1,
            "y": 17,
            "z": 13,
            "elements": [
                "contenttweaker:outer_stomach_wall@0"
            ]
        },
        {
            "x": 2,
            "y": 17,
            "z": 13,
            "elements": [
                "contenttweaker:inner_stomach_wall@0"
            ]
        },
        {
            "x": 3,
            "y": 17,
            "z": 13,
            "elements": [
                "contenttweaker:sinking_stomach_wall@0"
            ]
        },
        {
            "x": 4,
            "y": 17,
            "z": 13,
            "elements": [
                "contenttweaker:sinking_stomach_wall@0"
            ]
        },
        {
            "x": 5,
            "y": 17,
            "z": 13,
            "elements": [
                "contenttweaker:sinking_stomach_wall@0"
            ]
        },
        {
            "x": -3,
            "y": 1,
            "z": 5,
            "elements": [
                "contenttweaker:outer_stomach_wall@0"
            ]
        },
        {
            "x": -2,
            "y": 1,
            "z": 5,
            "elements": [
                "contenttweaker:inner_stomach_wall@0"
            ]
        },
        {
            "x": 6,
            "y": 17,
            "z": 13,
            "elements": [
                "contenttweaker:inner_stomach_wall@0"
            ]
        },
        {
            "x": 7,
            "y": 17,
            "z": 13,
            "elements": [
                "contenttweaker:outer_stomach_wall@0"
            ]
        },
        {
            "x": 2,
            "y": 1,
            "z": 5,
            "elements": [
                "contenttweaker:inner_stomach_wall@0"
            ]
        },
        {
            "x": 3,
            "y": 1,
            "z": 5,
            "elements": [
                "contenttweaker:outer_stomach_wall@0"
            ]
        },
        {
            "x": -5,
            "y": 3,
            "z": 22,
            "elements": [
                "contenttweaker:outer_stomach_wall@0"
            ]
        },
        {
            "x": -1,
            "y": 11,
            "z": 26,
            "elements": [
                "contenttweaker:outer_stomach_wall@0"
            ]
        },
        {
            "x": 0,
            "y": 11,
            "z": 26,
            "elements": [
                "contenttweaker:outer_stomach_wall@0"
            ]
        },
        {
            "x": -4,
            "y": 3,
            "z": 22,
            "elements": [
                "contenttweaker:inner_stomach_wall@0"
            ]
        },
        {
            "x": 1,
            "y": 11,
            "z": 26,
            "elements": [
                "contenttweaker:outer_stomach_wall@0"
            ]
        },
        {
            "x": -3,
            "y": 3,
            "z": 22,
            "elements": [
                "contenttweaker:inner_stomach_wall@0"
            ]
        },
        {
            "x": -1,
            "y": -5,
            "z": 18,
            "elements": [
                "contenttweaker:outer_stomach_wall@0"
            ]
        },
        {
            "x": 3,
            "y": 3,
            "z": 22,
            "elements": [
                "contenttweaker:inner_stomach_wall@0"
            ]
        },
        {
            "x": 0,
            "y": -5,
            "z": 18,
            "elements": [
                "contenttweaker:outer_stomach_wall@0"
            ]
        },
        {
            "x": 4,
            "y": 3,
            "z": 22,
            "elements": [
                "contenttweaker:inner_stomach_wall@0"
            ]
        },
        {
            "x": 5,
            "y": 3,
            "z": 22,
            "elements": [
                "contenttweaker:outer_stomach_wall@0"
            ]
        },
        {
            "x": 1,
            "y": -5,
            "z": 18,
            "elements": [
                "contenttweaker:outer_stomach_wall@0"
            ]
        },
        {
            "x": 1,
            "y": 18,
            "z": 13,
            "elements": [
                "contenttweaker:outer_stomach_wall@0"
            ]
        },
        {
            "x": 2,
            "y": 18,
            "z": 13,
            "elements": [
                "contenttweaker:inner_stomach_wall@0"
            ]
        },
        {
            "x": 3,
            "y": 18,
            "z": 13,
            "elements": [
                "contenttweaker:sinking_stomach_wall@0"
            ]
        },
        {
            "x": 4,
            "y": 18,
            "z": 13,
            "elements": [
                "contenttweaker:sinking_stomach_wall@0"
            ]
        },
        {
            "x": 5,
            "y": 18,
            "z": 13,
            "elements": [
                "contenttweaker:sinking_stomach_wall@0"
            ]
        },
        {
            "x": -2,
            "y": 2,
            "z": 5,
            "elements": [
                "contenttweaker:outer_stomach_wall@0"
            ]
        },
        {
            "x": 6,
            "y": 18,
            "z": 13,
            "elements": [
                "contenttweaker:inner_stomach_wall@0"
            ]
        },
        {
            "x": -1,
            "y": 2,
            "z": 5,
            "elements": [
                "contenttweaker:inner_stomach_wall@0"
            ]
        },
        {
            "x": 7,
            "y": 18,
            "z": 13,
            "elements": [
                "contenttweaker:outer_stomach_wall@0"
            ]
        },
        {
            "x": 0,
            "y": 2,
            "z": 5,
            "elements": [
                "contenttweaker:inner_stomach_wall@0"
            ]
        },
        {
            "x": 1,
            "y": 2,
            "z": 5,
            "elements": [
                "contenttweaker:inner_stomach_wall@0"
            ]
        },
        {
            "x": 2,
            "y": 2,
            "z": 5,
            "elements": [
                "contenttweaker:outer_stomach_wall@0"
            ]
        },
        {
            "x": -5,
            "y": 4,
            "z": 22,
            "elements": [
                "contenttweaker:outer_stomach_wall@0"
            ]
        },
        {
            "x": -4,
            "y": 4,
            "z": 22,
            "elements": [
                "contenttweaker:inner_stomach_wall@0"
            ]
        },
        {
            "x": -3,
            "y": 4,
            "z": 22,
            "elements": [
                "contenttweaker:inner_stomach_wall@0"
            ]
        },
        {
            "x": -4,
            "y": -4,
            "z": 18,
            "elements": [
                "contenttweaker:outer_stomach_wall@0"
            ]
        },
        {
            "x": -3,
            "y": -4,
            "z": 18,
            "elements": [
                "contenttweaker:outer_stomach_wall@0"
            ]
        },
        {
            "x": -2,
            "y": -4,
            "z": 18,
            "elements": [
                "contenttweaker:outer_stomach_wall@0"
            ]
        },
        {
            "x": -1,
            "y": -4,
            "z": 18,
            "elements": [
                "contenttweaker:inner_stomach_wall@0"
            ]
        },
        {
            "x": 3,
            "y": 4,
            "z": 22,
            "elements": [
                "tconstruct:slime_channel@0"
            ]
        },
        {
            "x": 0,
            "y": -4,
            "z": 18,
            "elements": [
                "contenttweaker:inner_stomach_wall@0"
            ]
        },
        {
            "x": 4,
            "y": 4,
            "z": 22,
            "elements": [
                "tconstruct:slime_channel@0"
            ]
        },
        {
            "x": 5,
            "y": 4,
            "z": 22,
            "elements": [
                "contenttweaker:inner_stomach_wall@0"
            ]
        },
        {
            "x": 1,
            "y": -4,
            "z": 18,
            "elements": [
                "contenttweaker:inner_stomach_wall@0"
            ]
        },
        {
            "x": 6,
            "y": 4,
            "z": 22,
            "elements": [
                "contenttweaker:outer_stomach_wall@0"
            ]
        },
        {
            "x": 2,
            "y": -4,
            "z": 18,
            "elements": [
                "contenttweaker:outer_stomach_wall@0"
            ]
        },
        {
            "x": 3,
            "y": -4,
            "z": 18,
            "elements": [
                "contenttweaker:outer_stomach_wall@0"
            ]
        },
        {
            "x": 4,
            "y": -4,
            "z": 18,
            "elements": [
                "contenttweaker:outer_stomach_wall@0"
            ]
        },
        {
            "x": 1,
            "y": 19,
            "z": 13,
            "elements": [
                "contenttweaker:outer_stomach_wall@0"
            ]
        },
        {
            "x": 2,
            "y": 19,
            "z": 13,
            "elements": [
                "contenttweaker:inner_stomach_wall@0"
            ]
        },
        {
            "x": 3,
            "y": 19,
            "z": 13,
            "elements": [
                "contenttweaker:sinking_stomach_wall@0"
            ]
        },
        {
            "x": 4,
            "y": 19,
            "z": 13,
            "elements": [
                "contenttweaker:sinking_stomach_wall@0"
            ]
        },
        {
            "x": 5,
            "y": 19,
            "z": 13,
            "elements": [
                "contenttweaker:sinking_stomach_wall@0"
            ]
        },
        {
            "x": 6,
            "y": 19,
            "z": 13,
            "elements": [
                "contenttweaker:inner_stomach_wall@0"
            ]
        },
        {
            "x": -1,
            "y": 3,
            "z": 5,
            "elements": [
                "contenttweaker:outer_stomach_wall@0"
            ]
        },
        {
            "x": 7,
            "y": 19,
            "z": 13,
            "elements": [
                "contenttweaker:outer_stomach_wall@0"
            ]
        },
        {
            "x": 1,
            "y": 3,
            "z": 5,
            "elements": [
                "contenttweaker:outer_stomach_wall@0"
            ]
        },
        {
            "x": -6,
            "y": 5,
            "z": 22,
            "elements": [
                "contenttweaker:outer_stomach_wall@0"
            ]
        },
        {
            "x": -5,
            "y": 5,
            "z": 22,
            "elements": [
                "contenttweaker:inner_stomach_wall@0"
            ]
        },
        {
            "x": -4,
            "y": 5,
            "z": 22,
            "elements": [
                "tconstruct:slime_channel@0"
            ]
        },
        {
            "x": -3,
            "y": 5,
            "z": 22,
            "elements": [
                "tconstruct:slime_channel@0"
            ]
        },
        {
            "x": -5,
            "y": -3,
            "z": 18,
            "elements": [
                "contenttweaker:outer_stomach_wall@0"
            ]
        },
        {
            "x": -4,
            "y": -3,
            "z": 18,
            "elements": [
                "contenttweaker:inner_stomach_wall@0"
            ]
        },
        {
            "x": -3,
            "y": -3,
            "z": 18,
            "elements": [
                "contenttweaker:inner_stomach_wall@0"
            ]
        },
        {
            "x": -2,
            "y": -3,
            "z": 18,
            "elements": [
                "contenttweaker:inner_stomach_wall@0"
            ]
        },
        {
            "x": -1,
            "y": -3,
            "z": 18,
            "elements": [
                "tconstruct:slime_channel@0"
            ]
        },
        {
            "x": 0,
            "y": -3,
            "z": 18,
            "elements": [
                "tconstruct:slime_channel@0"
            ]
        },
        {
            "x": 5,
            "y": 5,
            "z": 22,
            "elements": [
                "tconstruct:slime_channel@0"
            ]
        },
        {
            "x": 1,
            "y": -3,
            "z": 18,
            "elements": [
                "tconstruct:slime_channel@0"
            ]
        },
        {
            "x": 6,
            "y": 5,
            "z": 22,
            "elements": [
                "contenttweaker:inner_stomach_wall@0"
            ]
        },
        {
            "x": 2,
            "y": -3,
            "z": 18,
            "elements": [
                "contenttweaker:inner_stomach_wall@0"
            ]
        },
        {
            "x": 7,
            "y": 5,
            "z": 22,
            "elements": [
                "contenttweaker:outer_stomach_wall@0"
            ]
        },
        {
            "x": 3,
            "y": -3,
            "z": 18,
            "elements": [
                "contenttweaker:inner_stomach_wall@0"
            ]
        },
        {
            "x": 4,
            "y": -3,
            "z": 18,
            "elements": [
                "contenttweaker:inner_stomach_wall@0"
            ]
        },
        {
            "x": 5,
            "y": -3,
            "z": 18,
            "elements": [
                "contenttweaker:outer_stomach_wall@0"
            ]
        },
        {
            "x": 0,
            "y": 4,
            "z": 5,
            "elements": [
                "contenttweaker:outer_stomach_wall@0"
            ]
        },
        {
            "x": 0,
            "y": -4,
            "z": 1,
            "elements": [
                "contenttweaker:outer_stomach_wall@0"
            ]
        },
        {
            "x": -7,
            "y": 6,
            "z": 22,
            "elements": [
                "contenttweaker:outer_stomach_wall@0"
            ]
        },
        {
            "x": -6,
            "y": 6,
            "z": 22,
            "elements": [
                "contenttweaker:inner_stomach_wall@0"
            ]
        },
        {
            "x": -5,
            "y": 6,
            "z": 22,
            "elements": [
                "tconstruct:slime_channel@0"
            ]
        },
        {
            "x": -6,
            "y": -2,
            "z": 18,
            "elements": [
                "contenttweaker:outer_stomach_wall@0"
            ]
        },
        {
            "x": -5,
            "y": -2,
            "z": 18,
            "elements": [
                "contenttweaker:inner_stomach_wall@0"
            ]
        },
        {
            "x": -4,
            "y": -2,
            "z": 18,
            "elements": [
                "tconstruct:slime_channel@0"
            ]
        },
        {
            "x": -3,
            "y": -2,
            "z": 18,
            "elements": [
                "tconstruct:slime_channel@0"
            ]
        },
        {
            "x": -2,
            "y": -2,
            "z": 18,
            "elements": [
                "tconstruct:slime_channel@0"
            ]
        },
        {
            "x": 6,
            "y": 6,
            "z": 22,
            "elements": [
                "contenttweaker:inner_stomach_wall@0"
            ]
        },
        {
            "x": 2,
            "y": -2,
            "z": 18,
            "elements": [
                "tconstruct:slime_channel@0"
            ]
        },
        {
            "x": 7,
            "y": 6,
            "z": 22,
            "elements": [
                "contenttweaker:outer_stomach_wall@0"
            ]
        },
        {
            "x": 3,
            "y": -2,
            "z": 18,
            "elements": [
                "tconstruct:slime_channel@0"
            ]
        },
        {
            "x": 4,
            "y": -2,
            "z": 18,
            "elements": [
                "tconstruct:slime_channel@0"
            ]
        },
        {
            "x": 5,
            "y": -2,
            "z": 18,
            "elements": [
                "contenttweaker:inner_stomach_wall@0"
            ]
        },
        {
            "x": 6,
            "y": -2,
            "z": 18,
            "elements": [
                "contenttweaker:outer_stomach_wall@0"
            ]
        },
        {
            "x": -1,
            "y": -3,
            "z": 1,
            "elements": [
                "contenttweaker:outer_stomach_wall@0"
            ]
        },
        {
            "x": 1,
            "y": -3,
            "z": 1,
            "elements": [
                "contenttweaker:outer_stomach_wall@0"
            ]
        },
        {
            "x": -7,
            "y": 7,
            "z": 22,
            "elements": [
                "contenttweaker:outer_stomach_wall@0"
            ]
        },
        {
            "x": -6,
            "y": 7,
            "z": 22,
            "elements": [
                "contenttweaker:inner_stomach_wall@0"
            ]
        },
        {
            "x": -7,
            "y": -1,
            "z": 18,
            "elements": [
                "contenttweaker:outer_stomach_wall@0"
            ]
        },
        {
            "x": -6,
            "y": -1,
            "z": 18,
            "elements": [
                "contenttweaker:inner_stomach_wall@0"
            ]
        },
        {
            "x": -5,
            "y": -1,
            "z": 18,
            "elements": [
                "tconstruct:slime_channel@0"
            ]
        },
        {
            "x": 6,
            "y": 7,
            "z": 22,
            "elements": [
                "contenttweaker:inner_stomach_wall@0"
            ]
        },
        {
            "x": 7,
            "y": 7,
            "z": 22,
            "elements": [
                "contenttweaker:outer_stomach_wall@0"
            ]
        },
        {
            "x": 5,
            "y": -1,
            "z": 18,
            "elements": [
                "tconstruct:slime_channel@0"
            ]
        },
        {
            "x": 6,
            "y": -1,
            "z": 18,
            "elements": [
                "contenttweaker:inner_stomach_wall@0"
            ]
        },
        {
            "x": 7,
            "y": -1,
            "z": 18,
            "elements": [
                "contenttweaker:outer_stomach_wall@0"
            ]
        },
        {
            "x": -2,
            "y": -2,
            "z": 1,
            "elements": [
                "contenttweaker:outer_stomach_wall@0"
            ]
        },
        {
            "x": -1,
            "y": -2,
            "z": 1,
            "elements": [
                "contenttweaker:inner_stomach_wall@0"
            ]
        },
        {
            "x": 2,
            "y": -2,
            "z": 1,
            "elements": [
                "contenttweaker:outer_stomach_wall@0"
            ]
        },
        {
            "x": -7,
            "y": 8,
            "z": 22,
            "elements": [
                "contenttweaker:outer_stomach_wall@0"
            ]
        },
        {
            "x": -6,
            "y": 8,
            "z": 22,
            "elements": [
                "contenttweaker:inner_stomach_wall@0"
            ]
        },
        {
            "x": -7,
            "y": 0,
            "z": 18,
            "elements": [
                "contenttweaker:outer_stomach_wall@0"
            ]
        },
        {
            "x": -6,
            "y": 0,
            "z": 18,
            "elements": [
                "contenttweaker:inner_stomach_wall@0"
            ]
        },
        {
            "x": 6,
            "y": 8,
            "z": 22,
            "elements": [
                "contenttweaker:inner_stomach_wall@0"
            ]
        },
        {
            "x": 7,
            "y": 8,
            "z": 22,
            "elements": [
                "contenttweaker:outer_stomach_wall@0"
            ]
        },
        {
            "x": 6,
            "y": 0,
            "z": 18,
            "elements": [
                "contenttweaker:inner_stomach_wall@0"
            ]
        },
        {
            "x": 7,
            "y": 0,
            "z": 18,
            "elements": [
                "contenttweaker:outer_stomach_wall@0"
            ]
        },
        {
            "x": -2,
            "y": -1,
            "z": 1,
            "elements": [
                "contenttweaker:outer_stomach_wall@0"
            ]
        },
        {
            "x": -1,
            "y": -1,
            "z": 1,
            "elements": [
                "contenttweaker:inner_stomach_wall@0"
            ]
        },
        {
            "x": 0,
            "y": -1,
            "z": 1,
            "elements": [
                "contenttweaker:inner_stomach_wall@0"
            ]
        },
        {
            "x": 2,
            "y": -1,
            "z": 1,
            "elements": [
                "contenttweaker:outer_stomach_wall@0"
            ]
        },
        {
            "x": -7,
            "y": 9,
            "z": 22,
            "elements": [
                "contenttweaker:outer_stomach_wall@0"
            ]
        },
        {
            "x": -6,
            "y": 9,
            "z": 22,
            "elements": [
                "contenttweaker:inner_stomach_wall@0"
            ]
        },
        {
            "x": -7,
            "y": 1,
            "z": 18,
            "elements": [
                "contenttweaker:outer_stomach_wall@0"
            ]
        },
        {
            "x": -6,
            "y": 1,
            "z": 18,
            "elements": [
                "contenttweaker:inner_stomach_wall@0"
            ]
        },
        {
            "x": 6,
            "y": 9,
            "z": 22,
            "elements": [
                "contenttweaker:inner_stomach_wall@0"
            ]
        },
        {
            "x": 7,
            "y": 9,
            "z": 22,
            "elements": [
                "contenttweaker:outer_stomach_wall@0"
            ]
        },
        {
            "x": 6,
            "y": 1,
            "z": 18,
            "elements": [
                "contenttweaker:inner_stomach_wall@0"
            ]
        },
        {
            "x": 7,
            "y": 1,
            "z": 18,
            "elements": [
                "contenttweaker:outer_stomach_wall@0"
            ]
        },
        {
            "x": -2,
            "y": 0,
            "z": 1,
            "elements": [
                "contenttweaker:outer_stomach_wall@0"
            ]
        },
        {
            "x": 2,
            "y": 0,
            "z": 1,
            "elements": [
