
# Created by Ruins mod version 17.2 Ingame Parser
# authoring Player: austinsupercar

# TEMPLATE PARAMETER SETTINGS:
#
# criterion expression specifying mod ids required to load template
# may include plus (AND), minus (AND NOT), comma (OR), and parentheses
# all required mods listed must be present; no prohibited mods can be
requiredMods=
#
# likelihood this template will be chosen relative to all others
# e.g., a weight=6 template is chosen 3X as often as one with weight=2
weight=1
#
# list of dimensions in which this template may spawn, even if generic
# one or more dimension names, separated by commas (blank = all)
dimensionsToSpawnIn=
#
# list of other biomes in which this template may spawn
# biome corresponding to directory is always assumed, listed or not
# generic templates should leave this list empty
biomesToSpawnIn=
#
# criterion expression specifying types of biome where template spawns
# this is in addition to those explicitly listed as biomesToSpawnIn
# generic templates should leave this list empty
biomeTypesToSpawnIn=
#
# list of biomes in which this template may not spawn
# takes precedence over biomeTypesToSpawnIn, but NOT biomesToSpawnIn
# should be empty if biomeTypesToSpawnIn is empty
biomesToNotSpawnIn=
#
# depth template is pushed down into the surface when built
# offset is min/max range of random additional bury depth
embed_into_distance=0
random_height_offset=0,0
#
# whitelist/blacklist of block types on which template may be built
# specify one, not both; leave the other empty (both empty = allow all)
acceptable_target_blocks=
unacceptable_target_blocks=flowing_water,water,flowing_lava,lava
#
# size of template (#layers, #rows per layer, #blocks per row)
dimensions=108,44,54
#
# max number of missing blocks allowed in surface beneath template
allowable_overhang=0
#
# depth/height limit affected by terrain leveling
# also maximum bumpiness tolerated in surface beneath template
max_leveling=2
#
# padding applied to all sides of template horizontal footprint
# expands area affected by terrain leveling (-1 = no leveling)
leveling_buffer=0
#
# do not rotate template randomly when built (1 = no rotation)
preventRotation=0
#
# treat water/lava blocks as air and protect them from rule0 (1 = yes)
preserve_water=0
preserve_lava=0
#
# minimum distance this template must have from instances of itself
uniqueMinDistance=0
#
# min/max distances this template can be from world spawn (0 = no limit)
# only applies to overworld--i.e., dimension 0
spawnMinDistance=0
spawnMaxDistance=0
#
# other template built nearby whenever this one is
# syntax: <name>;<relativeX>;<maxYdifference>;<relativeZ>[;<chance>]
# may be used more than once to specify multiple neighbors
adjoining_template=

rule1=0,100,railcraft:reinforced_concrete-7
rule2=0,100,railcraft:reinforced_concrete-3
rule3=0,100,minecraft:prismarine-1
rule4=0,100,minecraft:bedrock-0
rule5=0,100,contenttweaker:sinking_stomach_wall_h-0
rule6=0,100,chisel:netherrack-8
rule7=0,100,contenttweaker:inner_stomach_wall_h-0
rule8=0,100,contenttweaker:outer_stomach_wall_h-0
rule9=0,100,chisel:netherrack-9
rule10=0,100,railcraft:reinforced_concrete-14
rule11=0,100,chisel:netherrack-10
rule12=0,100,tconstruct:slime_congealed-0
rule13=0,100,thermalfoundation:rockwool-15
rule14=0,100,minecraft:wool-0
rule15=0,100,minecraft:stained_hardened_clay-0
rule16=0,100,railcraft:reinforced_concrete-15
rule17=0,100,chisel:andesite1-5
rule18=0,100,mekanism:slickplasticblock-15
rule19=0,100,contenttweaker:inner_stomach_wall-0
rule20=0,100,minecraft:planks-0
rule21=0,100,foundry:liquidglasswhite-1
rule22=0,100,railcraft:reinforced_concrete-0
rule23=0,100,minecraft:stained_glass-0
rule24=0,100,railcraft:reinforced_concrete-2
rule25=0,100,railcraft:reinforced_concrete-11
rule26=0,100,foundry:liquidglasswhite-0

layer
0,0,0,0,0,0,0,0,0,0,0,0,0,0,0,0,0,0,0,1,1,1,1,1,1,1,1,2,2,2,2,2,2,2,2,2,2,2,2,2,2,2,2,1,1,1,1,1,0,0,0,0,0,0
0,0,0,0,0,0,0,0,0,0,0,0,0,0,0,0,0,0,0,1,1,1,1,1,1,1,1,2,2,2,2,2,2,2,2,2,2,2,2,2,2,2,2,1,1,1,1,1,0,0,0,0,0,0
0,0,3,0,0,0,0,0,0,0,0,0,0,0,0,0,0,0,0,1,1,1,1,1,1,1,1,2,2,2,2,2,2,2,2,2,2,2,2,2,2,2,2,1,1,1,1,1,0,0,0,0,0,0
0,0,3,3,3,3,3,3,3,3,3,3,3,3,3,3,3,3,3,1,1,1,1,1,1,1,1,2,2,2,2,2,2,2,2,2,2,2,2,2,2,2,2,1,1,1,1,1,0,0,0,0,0,0
0,0,0,0,0,0,0,0,0,0,0,0,0,0,0,0,0,0,0,1,1,1,1,1,1,1,1,4,4,4,4,4,4,4,4,4,4,4,4,4,4,4,4,1,1,1,1,1,0,0,0,0,0,0
0,0,0,0,0,0,0,0,0,0,0,0,0,0,0,0,0,0,0,1,1,1,1,1,1,1,1,4,4,4,4,4,4,4,4,4,4,4,4,4,4,4,4,1,1,1,1,1,0,0,0,0,0,0
0,0,0,0,0,0,0,0,0,0,0,0,0,0,0,0,0,0,0,1,1,1,1,1,1,1,1,4,4,4,4,4,4,4,4,4,4,4,4,4,4,4,4,1,1,1,1,1,0,0,0,0,0,0
0,0,0,0,0,0,0,0,0,0,0,0,0,0,0,0,0,0,0,1,1,1,1,1,1,1,1,4,4,4,4,4,4,4,4,4,4,4,4,4,4,4,4,1,1,1,1,1,0,0,0,0,0,0
0,0,0,0,0,0,0,0,0,0,0,0,0,0,0,0,0,0,0,1,1,1,1,1,1,1,1,4,4,4,4,4,4,4,4,4,4,4,4,4,4,4,4,1,1,1,1,1,0,0,0,0,0,0
0,0,0,0,0,0,0,0,0,0,0,0,0,0,0,0,0,0,0,1,1,1,1,1,1,1,1,4,4,4,4,4,4,4,4,4,4,4,4,4,4,4,4,1,1,1,1,1,0,0,0,0,0,0
0,0,0,0,0,0,0,0,0,0,0,0,0,0,0,0,0,0,0,1,1,1,1,1,1,1,1,4,4,4,4,4,4,4,4,4,4,4,4,4,4,4,4,1,1,1,1,1,0,0,0,0,0,0
0,0,0,0,0,0,0,0,0,0,0,0,0,0,0,0,0,0,0,1,1,1,1,1,1,1,1,4,4,4,4,4,4,4,4,4,4,4,4,4,4,4,4,1,1,1,1,1,0,0,0,0,0,0
0,0,0,0,0,0,0,0,0,0,0,0,0,0,0,2,2,2,2,4,4,4,4,4,4,4,4,4,4,4,4,4,4,4,4,4,4,4,4,4,4,4,4,1,1,1,1,1,0,0,0,0,0,0
0,0,0,0,0,0,0,0,0,0,0,0,0,0,0,2,2,2,2,4,4,4,4,4,4,4,4,4,4,4,4,4,4,4,4,4,4,4,4,4,4,4,4,1,1,1,1,1,0,0,0,0,0,0
0,0,0,0,0,0,0,0,0,0,0,0,0,0,0,2,2,2,2,4,4,4,4,4,4,4,4,4,4,4,4,4,4,4,4,4,4,4,4,4,4,4,4,1,1,1,1,1,0,0,0,0,0,0
0,0,0,0,0,0,0,0,0,0,0,0,0,0,0,2,2,2,2,4,4,4,4,4,4,4,4,4,4,4,4,4,4,4,4,4,4,4,4,4,4,4,4,1,1,1,1,1,0,0,0,0,0,0
0,0,0,0,0,0,0,0,0,0,0,0,0,0,0,2,2,2,2,4,4,4,4,4,4,4,4,4,4,4,4,4,4,4,4,4,4,4,4,4,4,4,4,1,1,1,1,1,0,0,0,0,0,0
0,0,0,0,0,0,0,0,0,0,0,0,0,0,0,2,2,2,2,4,4,4,4,4,4,4,4,4,4,4,4,4,4,4,4,4,4,4,4,4,4,4,4,1,1,1,1,1,0,0,0,0,0,0
0,0,0,0,0,0,0,0,0,0,0,0,0,0,0,2,2,2,2,4,4,4,4,4,4,4,4,4,4,4,4,4,4,4,4,4,4,4,4,4,4,4,4,1,1,1,1,1,0,0,0,0,0,0
0,0,0,0,0,0,0,0,0,0,0,0,0,0,0,2,2,2,2,4,4,4,4,4,4,4,4,4,4,4,4,4,4,4,4,4,4,4,4,4,4,4,4,1,1,1,1,1,0,0,0,0,0,0
0,0,0,0,0,0,0,0,0,0,0,0,0,0,0,2,2,2,2,4,4,4,4,4,4,4,4,4,4,4,4,4,4,4,4,4,4,4,4,4,4,4,4,5,5,5,1,1,0,0,0,0,0,0
0,0,0,0,0,0,0,0,0,0,0,0,0,0,0,2,2,2,2,4,4,4,4,4,4,4,4,4,4,4,4,4,4,4,4,4,4,4,4,4,4,4,4,5,5,5,1,1,0,0,0,0,0,0
0,0,0,0,0,0,0,0,0,0,0,0,0,0,0,2,2,2,2,4,4,4,4,4,4,4,4,4,4,4,4,4,4,4,4,4,4,4,4,4,4,4,4,5,5,5,1,1,0,0,0,0,0,0
0,0,0,0,0,0,0,0,0,0,0,0,0,0,0,2,2,2,2,4,4,4,4,4,4,4,4,4,4,4,4,4,4,4,4,4,4,4,4,4,4,4,4,5,5,5,1,1,0,0,0,0,0,0
0,0,0,0,0,0,0,0,0,0,0,0,0,0,0,2,2,2,2,4,4,4,4,4,4,4,4,4,4,4,4,4,4,4,4,4,4,4,4,4,4,4,4,1,1,1,1,1,0,0,0,0,0,0
0,0,0,0,0,0,0,0,0,0,0,0,0,0,0,2,2,2,2,4,4,4,4,4,4,4,4,4,4,4,4,4,4,4,4,4,4,4,4,4,4,4,4,1,1,1,1,1,0,0,0,0,0,0
0,0,0,0,0,0,0,0,0,0,0,0,0,0,0,2,2,2,2,4,4,4,4,4,4,4,4,4,4,4,4,4,4,4,4,4,4,4,4,4,4,4,4,1,1,1,1,1,0,0,0,0,0,0
0,0,0,0,0,0,0,0,0,0,0,0,0,0,0,2,2,2,2,4,4,4,4,4,4,4,4,4,4,4,4,4,4,4,4,4,4,4,4,4,4,4,4,1,1,1,1,1,0,0,0,0,0,0
0,0,0,0,0,0,0,0,0,0,0,0,0,0,0,2,2,2,2,4,4,4,4,4,4,4,4,4,4,4,4,4,4,4,4,4,4,4,4,4,4,4,4,1,1,1,1,1,0,0,0,0,0,0
0,0,0,0,0,0,0,0,0,0,0,0,0,0,0,2,2,2,2,4,4,4,4,4,4,4,4,4,4,4,4,4,4,4,4,4,4,4,4,4,4,4,4,1,1,1,1,1,0,0,0,0,0,0
0,0,0,0,0,0,0,0,0,0,0,0,0,0,0,2,2,2,2,4,4,4,4,4,4,4,4,4,4,4,4,4,4,4,4,4,4,4,4,4,4,4,4,1,1,1,1,1,0,0,0,0,0,0
0,0,0,0,0,0,0,0,0,0,0,0,0,0,0,2,2,2,2,4,4,4,4,4,4,4,4,4,4,4,4,4,4,4,4,4,4,4,4,4,4,4,4,1,1,1,1,1,0,0,0,0,0,0
0,0,0,0,0,0,0,0,0,0,0,0,0,0,0,0,0,0,0,1,1,1,1,1,1,1,1,4,4,4,4,4,4,4,4,4,4,4,4,4,4,4,4,1,1,1,1,1,0,0,0,0,0,0
0,0,0,0,0,0,0,0,0,0,0,0,0,0,0,0,0,0,0,1,1,1,1,1,1,1,1,4,4,4,4,4,4,4,4,4,4,4,4,4,4,4,4,1,1,1,1,1,0,0,0,0,0,0
0,0,0,0,0,0,0,0,0,0,0,0,0,0,0,0,0,0,0,1,1,1,1,1,1,1,1,4,4,4,4,4,4,4,4,4,4,4,4,4,4,4,4,1,1,1,1,1,0,0,0,0,0,0
0,0,0,0,0,0,0,0,0,0,0,0,0,0,0,0,0,0,0,1,1,1,1,1,1,1,1,4,4,4,4,4,4,4,4,4,4,4,4,4,4,4,4,1,1,1,1,1,0,0,0,0,0,0
0,0,0,0,0,0,0,0,0,0,0,0,0,0,0,0,0,0,0,1,1,1,1,1,1,1,1,4,4,4,4,4,4,4,4,4,4,4,4,4,4,4,4,1,1,1,1,1,0,0,0,0,0,0
0,0,0,0,0,0,0,0,0,0,0,0,0,0,0,0,0,0,0,1,1,1,1,1,1,1,1,4,4,4,4,4,4,4,4,4,4,4,4,4,4,4,4,1,1,1,1,1,0,0,0,0,0,0
0,0,0,0,0,0,0,0,0,0,0,0,0,0,0,0,0,0,0,1,1,1,1,1,1,1,1,4,4,4,4,4,4,4,4,4,4,4,4,4,4,4,4,1,1,1,1,1,0,0,0,0,0,0
0,0,0,0,0,0,0,0,0,0,0,0,0,0,0,0,0,0,0,1,1,1,1,1,1,1,1,4,4,4,4,4,4,4,4,4,4,4,4,4,4,4,4,1,1,1,1,1,0,0,0,0,0,0
0,0,0,0,0,0,0,0,0,0,0,0,0,0,0,0,0,0,0,1,1,1,1,1,1,1,1,2,2,2,2,2,2,2,2,2,2,2,2,2,2,2,2,1,1,1,1,1,0,0,0,0,0,0
0,0,0,0,0,0,0,0,0,0,0,0,0,0,0,0,0,0,0,1,1,1,1,1,1,1,1,2,2,2,2,2,2,2,2,2,2,2,2,2,2,2,2,1,1,1,1,1,0,0,0,0,0,0
0,0,0,0,0,0,0,0,0,0,0,0,0,0,0,0,0,0,0,1,1,1,1,1,1,1,1,2,2,2,2,2,2,2,2,2,2,2,2,2,2,2,2,1,1,1,1,1,0,0,0,0,0,0
0,0,0,0,0,0,0,0,0,0,0,0,0,0,0,0,0,0,0,1,1,1,1,1,1,1,1,2,2,2,2,2,2,2,2,2,2,2,2,2,2,2,2,1,1,1,1,1,0,0,0,0,0,0
endlayer

layer
0,0,0,0,0,0,0,0,0,0,0,0,0,0,0,0,0,0,0,1,1,1,1,1,1,1,1,2,2,2,2,2,2,2,2,2,2,2,2,2,2,2,2,1,1,1,1,1,0,0,0,0,0,0
0,0,0,0,0,0,0,0,0,0,0,0,0,0,0,0,0,0,0,1,1,1,1,1,1,1,1,2,2,2,2,2,2,2,2,2,2,2,2,2,2,2,2,1,1,1,1,1,0,0,0,0,0,0
0,0,3,3,3,3,3,3,3,3,3,3,3,3,3,3,3,3,3,1,1,1,1,1,1,1,1,2,2,2,2,2,2,2,2,2,2,2,2,2,2,2,2,1,1,1,1,1,0,0,0,0,0,0
0,0,0,0,0,0,0,0,0,0,0,0,0,0,0,0,0,0,0,1,1,1,1,1,1,1,1,4,4,4,4,4,4,4,4,4,4,4,4,4,4,4,4,1,1,1,1,1,0,0,0,0,0,0
0,0,0,0,0,0,0,0,0,0,0,0,0,0,0,0,0,0,0,1,1,1,1,1,1,1,4,6,6,6,6,6,0,0,0,0,0,0,0,0,0,0,0,4,1,1,1,1,0,0,0,0,0,0
0,0,0,0,0,0,0,0,0,0,0,0,0,0,0,0,0,0,0,1,1,1,1,1,1,1,4,6,6,6,6,6,0,0,0,0,0,0,0,0,0,0,0,4,1,1,1,1,0,0,0,0,0,0
0,0,0,0,0,0,0,0,0,0,0,0,0,0,0,0,0,0,0,1,1,1,1,1,1,1,4,6,6,6,6,6,0,0,0,0,0,0,0,0,0,0,0,4,1,1,1,1,0,0,0,0,0,0
0,0,0,0,0,0,0,0,0,0,0,0,0,0,0,0,0,0,0,1,1,1,1,1,1,1,4,6,6,6,6,6,0,0,0,0,0,0,0,0,0,0,0,4,1,1,1,1,0,0,0,0,0,0
0,0,0,0,0,0,0,0,0,0,0,0,0,0,0,0,0,0,0,1,1,1,1,1,1,1,4,6,6,6,6,6,0,0,0,0,0,0,0,0,0,0,0,4,1,1,1,1,0,0,0,0,0,0
0,0,0,0,0,0,0,0,0,0,0,0,0,0,0,0,0,0,0,1,1,1,1,1,1,1,4,7,7,7,7,7,0,0,0,0,0,0,0,0,0,0,0,4,1,1,1,1,0,0,0,0,0,0
0,0,0,0,0,0,0,0,0,0,0,0,0,0,0,0,0,0,0,1,1,1,1,1,1,1,4,7,7,7,7,7,0,0,0,0,0,0,0,0,0,0,0,4,1,1,1,1,0,0,0,0,0,0
0,0,0,0,0,0,0,0,0,0,0,0,0,0,0,0,0,0,0,1,1,1,1,1,1,1,4,7,7,7,7,7,0,0,0,0,0,0,0,0,0,0,0,4,1,1,1,1,0,0,0,0,0,0
0,0,0,0,0,0,0,0,0,0,0,0,0,0,0,2,2,2,2,4,4,4,4,4,4,4,4,7,7,7,7,7,0,0,0,0,0,0,0,0,0,0,0,4,1,1,1,1,0,0,0,0,0,0
0,0,0,0,0,0,0,0,0,0,0,0,0,0,0,2,2,2,2,4,0,0,0,0,0,8,7,7,7,7,7,7,0,0,0,0,0,0,0,0,0,0,0,4,1,1,1,1,0,0,0,0,0,0
0,0,0,0,0,0,0,0,0,0,0,0,0,0,0,2,2,2,2,4,0,0,0,0,0,8,7,7,7,7,7,7,0,0,0,0,0,0,0,0,0,0,0,4,1,1,1,1,0,0,0,0,0,0
0,0,0,0,0,0,0,0,0,0,0,0,0,0,0,2,2,2,2,4,0,0,0,0,0,8,7,7,7,7,7,7,0,0,0,0,0,0,0,0,0,0,0,4,1,1,1,1,0,0,0,0,0,0
0,0,0,0,0,0,0,0,0,0,0,0,0,0,0,2,2,2,2,4,0,0,0,0,0,8,7,7,7,7,7,7,0,0,0,0,0,0,0,0,0,0,0,4,1,1,1,1,0,0,0,0,0,0
0,0,0,0,0,0,0,0,0,0,0,0,0,0,0,2,2,2,2,4,0,0,0,0,0,8,7,7,7,7,7,7,0,0,0,0,0,0,0,0,0,0,0,4,1,1,1,1,0,0,0,0,0,0
0,0,0,0,0,0,0,0,0,0,0,0,0,0,0,2,2,2,2,4,0,0,0,0,0,8,7,7,7,7,7,7,0,0,0,0,0,0,0,0,0,0,0,4,1,1,1,1,0,0,0,0,0,0
0,0,0,0,0,0,0,0,0,0,0,0,0,0,0,2,2,2,2,4,0,0,0,0,0,8,7,7,7,7,7,7,0,0,0,0,0,0,6,6,6,6,6,4,4,4,1,1,0,0,0,0,0,0
0,0,0,0,0,0,0,0,0,0,0,0,0,0,0,2,2,2,2,4,0,0,0,0,0,8,7,7,7,7,7,7,0,0,0,0,0,0,6,6,6,6,6,0,0,0,4,1,0,0,0,0,0,0
0,0,0,0,0,0,0,0,0,0,0,0,0,0,0,2,2,2,2,4,0,0,0,0,0,8,7,7,7,7,7,7,0,0,0,0,0,0,6,6,6,6,6,0,0,0,4,1,0,0,0,0,0,0
0,0,0,0,0,0,0,0,0,0,0,0,0,0,0,2,2,2,2,4,0,0,0,0,0,8,7,7,7,7,7,7,0,0,0,0,0,0,6,6,6,6,6,0,0,0,4,1,0,0,0,0,0,0
0,0,0,0,0,0,0,0,0,0,0,0,0,0,0,2,2,2,2,4,0,0,0,0,0,8,7,7,7,7,7,7,0,0,0,0,0,0,6,6,6,6,6,0,0,0,4,1,0,0,0,0,0,0
0,0,0,0,0,0,0,0,0,0,0,0,0,0,0,2,2,2,2,4,0,0,0,0,0,8,7,7,7,7,7,7,0,0,0,0,0,0,6,6,6,6,6,4,4,4,1,1,0,0,0,0,0,0
0,0,0,0,0,0,0,0,0,0,0,0,0,0,0,2,2,2,2,4,0,0,0,0,0,8,7,7,7,7,7,7,0,0,0,0,0,0,6,6,6,6,6,4,1,1,1,1,0,0,0,0,0,0
0,0,0,0,0,0,0,0,0,0,0,0,0,0,0,2,2,2,2,4,0,0,0,0,0,8,7,7,7,7,7,7,0,0,0,0,0,0,6,6,6,6,6,4,1,1,1,1,0,0,0,0,0,0
0,0,0,0,0,0,0,0,0,0,0,0,0,0,0,2,2,2,2,4,0,0,0,0,0,8,7,7,7,7,7,7,0,0,0,0,0,0,6,6,6,6,6,4,1,1,1,1,0,0,0,0,0,0
0,0,0,0,0,0,0,0,0,0,0,0,0,0,0,2,2,2,2,4,0,0,0,0,0,8,7,7,7,7,7,7,0,0,0,0,0,0,6,6,6,6,6,4,1,1,1,1,0,0,0,0,0,0
0,0,0,0,0,0,0,0,0,0,0,0,0,0,0,2,2,2,2,4,0,0,0,0,0,8,7,7,7,7,7,7,0,0,0,0,0,0,6,6,6,6,6,4,1,1,1,1,0,0,0,0,0,0
0,0,0,0,0,0,0,0,0,0,0,0,0,0,0,2,2,2,2,4,0,0,0,0,0,8,7,7,7,7,7,7,0,0,0,0,0,0,6,6,6,6,6,4,1,1,1,1,0,0,0,0,0,0
0,0,0,0,0,0,0,0,0,0,0,0,0,0,0,2,2,2,2,4,4,4,4,4,4,4,4,7,7,7,7,7,0,0,0,0,0,0,6,6,6,6,6,4,1,1,1,1,0,0,0,0,0,0
0,0,0,0,0,0,0,0,0,0,0,0,0,0,0,0,0,0,0,1,1,1,1,1,1,1,4,7,7,7,7,7,0,0,0,0,0,0,6,6,6,6,6,4,1,1,1,1,0,0,0,0,0,0
0,0,0,0,0,0,0,0,0,0,0,0,0,0,0,0,0,0,0,1,1,1,1,1,1,1,4,7,7,7,7,7,0,0,0,0,0,0,6,6,6,6,6,4,1,1,1,1,0,0,0,0,0,0
0,0,0,0,0,0,0,0,0,0,0,0,0,0,0,0,0,0,0,1,1,1,1,1,1,1,4,7,7,7,7,7,0,0,0,0,0,0,6,6,6,6,6,4,1,1,1,1,0,0,0,0,0,0
0,0,0,0,0,0,0,0,0,0,0,0,0,0,0,0,0,0,0,1,1,1,1,1,1,1,4,6,6,6,6,6,6,6,6,6,6,6,6,6,6,6,6,4,1,1,1,1,0,0,0,0,0,0
0,0,0,0,0,0,0,0,0,0,0,0,0,0,0,0,0,0,0,1,1,1,1,1,1,1,4,6,6,6,6,6,6,6,6,6,6,6,6,6,6,6,6,4,1,1,1,1,0,0,0,0,0,0
0,0,0,0,0,0,0,0,0,0,0,0,0,0,0,0,0,0,0,1,1,1,1,1,1,1,4,6,6,6,6,6,6,6,6,6,6,6,6,6,6,6,6,4,1,1,1,1,0,0,0,0,0,0
0,0,0,0,0,0,0,0,0,0,0,0,0,0,0,0,0,0,0,1,1,1,1,1,1,1,4,6,6,6,6,6,6,6,6,6,6,6,6,6,6,6,6,4,1,1,1,1,0,0,0,0,0,0
0,0,0,0,0,0,0,0,0,0,0,0,0,0,0,0,0,0,0,1,1,1,1,1,1,1,4,6,6,6,6,6,6,6,6,6,6,6,6,6,6,6,6,4,1,1,1,1,0,0,0,0,0,0
0,0,0,0,0,0,0,0,0,0,0,0,0,0,0,0,0,0,0,1,1,1,1,1,1,1,1,4,4,4,4,4,4,4,4,4,4,4,4,4,4,4,4,1,1,1,1,1,0,0,0,0,0,0
0,0,0,0,0,0,0,0,0,0,0,0,0,0,0,0,0,0,0,1,1,1,1,1,1,1,1,2,2,2,2,2,2,2,2,2,2,2,2,2,2,2,2,1,1,1,1,1,0,0,0,0,0,0
0,0,0,0,0,0,0,0,0,0,0,0,0,0,0,0,0,0,0,1,1,1,1,1,1,1,1,2,2,2,2,2,2,2,2,2,2,2,2,2,2,2,2,1,1,1,1,1,0,0,0,0,0,0
0,0,0,0,0,0,0,0,0,0,0,0,0,0,0,0,0,0,0,1,1,1,1,1,1,1,1,2,2,2,2,2,2,2,2,2,2,2,2,2,2,2,2,1,1,1,1,1,0,0,0,0,0,0
endlayer

layer
0,0,0,0,0,0,0,0,0,0,0,0,0,0,0,0,0,0,0,1,1,1,1,1,1,1,1,2,2,2,2,2,2,2,2,2,2,2,2,2,2,2,2,1,1,1,1,1,0,0,0,0,0,0
0,0,3,0,0,0,0,0,0,0,0,0,0,0,0,0,0,0,0,1,1,1,1,1,1,1,1,2,2,2,2,2,2,2,2,2,2,2,2,2,2,2,2,1,1,1,1,1,0,0,0,0,0,0
0,0,3,3,3,3,3,3,3,3,3,3,3,3,3,3,3,3,3,1,1,1,1,1,1,1,1,2,2,2,2,2,2,2,2,2,2,2,2,2,2,2,2,1,1,1,1,1,0,0,0,0,0,0
0,0,0,0,0,0,0,0,0,0,0,0,0,0,0,0,0,0,0,1,1,1,1,1,1,1,1,4,4,4,4,4,4,4,4,4,4,4,4,4,4,4,4,1,1,1,1,1,0,0,0,0,0,0
0,0,0,0,0,0,0,0,0,0,0,0,0,0,0,0,0,0,0,1,1,1,1,1,1,1,4,6,6,6,6,6,0,0,0,0,0,0,0,0,0,0,0,4,1,1,1,1,0,0,0,0,0,0
0,0,0,0,0,0,0,0,0,0,0,0,0,0,0,0,0,0,0,1,1,1,1,1,1,1,4,6,0,0,0,6,0,0,0,0,0,0,0,0,0,0,0,4,1,1,1,1,0,0,0,0,0,0
0,0,0,0,0,0,0,0,0,0,0,0,0,0,0,0,0,0,0,1,1,1,1,1,1,1,4,6,0,0,0,6,0,0,0,0,0,0,0,0,0,0,0,4,1,1,1,1,0,0,0,0,0,0
0,0,0,0,0,0,0,0,0,0,0,0,0,0,0,0,0,0,0,1,1,1,1,1,1,1,4,6,0,0,0,6,0,0,0,0,0,0,0,0,0,0,0,4,1,1,1,1,0,0,0,0,0,0
0,0,0,0,0,0,0,0,0,0,0,0,0,0,0,0,0,0,0,1,1,1,1,1,1,1,4,6,0,0,0,6,0,0,0,0,0,0,0,0,0,0,0,4,1,1,1,1,0,0,0,0,0,0
0,0,0,0,0,0,0,0,0,0,0,0,0,0,0,0,0,0,0,1,1,1,1,1,1,1,4,7,0,0,0,7,0,0,0,0,0,0,0,0,0,0,0,4,1,1,1,1,0,0,0,0,0,0
0,0,0,0,0,0,0,0,0,0,0,0,0,0,0,0,0,0,0,1,1,1,1,1,1,1,4,7,0,0,0,0,0,0,0,0,0,0,0,0,0,0,0,4,1,1,1,1,0,0,0,0,0,0
0,0,0,0,0,0,0,0,0,0,0,0,0,0,0,0,0,0,0,1,1,1,1,1,1,1,4,7,0,0,0,0,0,0,0,0,0,0,0,0,0,0,0,4,1,1,1,1,0,0,0,0,0,0
0,0,0,0,0,0,0,0,0,0,0,0,0,0,0,2,2,2,2,4,4,4,4,4,4,4,4,7,0,0,0,0,0,0,0,0,0,0,0,0,0,0,0,4,1,1,1,1,0,0,0,0,0,0
0,0,0,0,0,0,0,0,0,0,0,0,0,0,0,2,2,2,2,4,0,0,0,0,0,8,7,7,0,0,0,0,0,0,0,0,0,0,0,0,0,0,0,4,1,1,1,1,0,0,0,0,0,0
0,0,0,0,0,0,0,0,0,0,0,0,0,0,0,2,2,2,2,4,0,0,0,0,0,8,7,7,0,0,0,0,0,0,0,0,0,0,0,0,0,0,0,4,1,1,1,1,0,0,0,0,0,0
0,0,0,0,0,0,0,0,0,0,0,0,0,0,0,2,2,2,2,4,0,0,0,0,0,8,7,7,0,0,0,0,0,0,0,0,0,0,0,0,0,0,0,4,1,1,1,1,0,0,0,0,0,0
0,0,0,0,0,0,0,0,0,0,0,0,0,0,0,2,2,2,2,4,0,0,0,0,0,8,7,7,0,0,0,0,0,0,0,0,0,0,0,0,0,0,0,4,1,1,1,1,0,0,0,0,0,0
0,0,0,0,0,0,0,0,0,0,0,0,0,0,0,2,2,2,2,4,0,0,0,0,0,8,7,7,0,0,0,0,0,0,0,0,0,0,0,0,0,0,0,4,1,1,1,1,0,0,0,0,0,0
0,0,0,0,0,0,0,0,0,0,0,0,0,0,0,2,2,2,2,4,0,0,0,0,0,8,7,7,0,0,0,0,0,0,0,0,0,0,0,0,0,0,0,4,1,1,1,1,0,0,0,0,0,0
0,0,0,0,0,0,0,0,0,0,0,0,0,0,0,2,2,2,2,4,0,0,0,0,0,8,7,7,0,0,0,0,0,0,0,0,0,0,6,6,6,6,6,4,4,4,1,1,0,0,0,0,0,0
0,0,0,0,0,0,0,0,0,0,0,0,0,0,0,2,2,2,2,4,0,0,0,0,0,8,7,7,0,0,0,0,0,0,0,0,0,0,6,0,0,0,0,0,0,0,4,1,0,0,0,0,0,0
0,0,0,0,0,0,0,0,0,0,0,0,0,0,0,2,2,2,2,4,0,0,0,0,0,8,7,7,0,0,0,0,0,0,0,0,0,0,6,0,0,0,0,0,0,0,4,1,0,0,0,0,0,0
0,0,0,0,0,0,0,0,0,0,0,0,0,0,0,2,2,2,2,4,0,0,0,0,0,8,7,7,0,0,0,0,0,0,0,0,0,0,6,0,0,0,0,0,0,0,4,1,0,0,0,0,0,0
0,0,0,0,0,0,0,0,0,0,0,0,0,0,0,2,2,2,2,4,0,0,0,0,0,8,7,7,0,0,0,0,0,0,0,0,0,0,6,0,0,0,0,0,0,0,4,1,0,0,0,0,0,0
0,0,0,0,0,0,0,0,0,0,0,0,0,0,0,2,2,2,2,4,0,0,0,0,0,8,7,7,0,0,0,0,0,0,0,0,0,0,6,0,0,0,6,4,4,4,1,1,0,0,0,0,0,0
0,0,0,0,0,0,0,0,0,0,0,0,0,0,0,2,2,2,2,4,0,0,0,0,0,8,7,7,0,0,0,0,0,0,0,0,0,0,6,0,0,0,6,4,1,1,1,1,0,0,0,0,0,0
0,0,0,0,0,0,0,0,0,0,0,0,0,0,0,2,2,2,2,4,0,0,0,0,0,8,7,7,0,0,0,0,0,0,0,0,0,0,6,0,0,0,6,4,1,1,1,1,0,0,0,0,0,0
0,0,0,0,0,0,0,0,0,0,0,0,0,0,0,2,2,2,2,4,0,0,0,0,0,8,7,7,0,0,0,0,0,0,0,0,0,0,6,0,0,0,6,4,1,1,1,1,0,0,0,0,0,0
0,0,0,0,0,0,0,0,0,0,0,0,0,0,0,2,2,2,2,4,0,0,0,0,0,8,7,7,0,0,0,0,0,0,0,0,0,0,6,0,0,0,6,4,1,1,1,1,0,0,0,0,0,0
0,0,0,0,0,0,0,0,0,0,0,0,0,0,0,2,2,2,2,4,0,0,0,0,0,8,7,7,0,0,0,0,0,0,0,0,0,0,6,0,0,0,6,4,1,1,1,1,0,0,0,0,0,0
0,0,0,0,0,0,0,0,0,0,0,0,0,0,0,2,2,2,2,4,0,0,0,0,0,8,7,7,0,0,0,0,0,0,0,0,0,0,6,0,0,0,6,4,1,1,1,1,0,0,0,0,0,0
0,0,0,0,0,0,0,0,0,0,0,0,0,0,0,2,2,2,2,4,4,4,4,4,4,4,4,7,0,0,0,0,0,0,0,0,0,0,6,0,0,0,6,4,1,1,1,1,0,0,0,0,0,0
0,0,0,0,0,0,0,0,0,0,0,0,0,0,0,0,0,0,0,1,1,1,1,1,1,1,4,7,0,0,0,0,0,0,0,0,0,0,6,0,0,0,6,4,1,1,1,1,0,0,0,0,0,0
0,0,0,0,0,0,0,0,0,0,0,0,0,0,0,0,0,0,0,1,1,1,1,1,1,1,4,7,0,0,0,0,0,0,0,0,0,0,6,0,0,0,6,4,1,1,1,1,0,0,0,0,0,0
0,0,0,0,0,0,0,0,0,0,0,0,0,0,0,0,0,0,0,1,1,1,1,1,1,1,4,7,7,7,7,7,0,0,0,0,0,0,6,0,0,0,6,4,1,1,1,1,0,0,0,0,0,0
0,0,0,0,0,0,0,0,0,0,0,0,0,0,0,0,0,0,0,1,1,1,1,1,1,1,4,6,6,6,6,6,6,6,6,6,6,6,6,0,0,0,6,4,1,1,1,1,0,0,0,0,0,0
0,0,0,0,0,0,0,0,0,0,0,0,0,0,0,0,0,0,0,1,1,1,1,1,1,1,4,6,0,0,0,0,0,0,0,0,0,0,0,0,0,0,6,4,1,1,1,1,0,0,0,0,0,0
0,0,0,0,0,0,0,0,0,0,0,0,0,0,0,0,0,0,0,1,1,1,1,1,1,1,4,6,0,0,0,0,0,0,0,0,0,0,0,0,0,0,6,4,1,1,1,1,0,0,0,0,0,0
0,0,0,0,0,0,0,0,0,0,0,0,0,0,0,0,0,0,0,1,1,1,1,1,1,1,4,6,0,0,0,0,0,0,0,0,0,0,0,0,0,0,6,4,1,1,1,1,0,0,0,0,0,0
0,0,0,0,0,0,0,0,0,0,0,0,0,0,0,0,0,0,0,1,1,1,1,1,1,1,4,6,6,6,6,6,6,6,6,6,6,6,6,6,6,6,6,4,1,1,1,1,0,0,0,0,0,0
0,0,0,0,0,0,0,0,0,0,0,0,0,0,0,0,0,0,0,1,1,1,1,1,1,1,1,4,4,4,4,4,4,4,4,4,4,4,4,4,4,4,4,1,1,1,1,1,0,0,0,0,0,0
0,0,0,0,0,0,0,0,0,0,0,0,0,0,0,0,0,0,0,1,1,1,1,1,1,1,1,2,2,2,2,2,2,2,2,2,2,2,2,2,2,2,2,1,1,1,1,1,0,0,0,0,0,0
0,0,0,0,0,0,0,0,0,0,0,0,0,0,0,0,0,0,0,1,1,1,1,1,1,1,1,2,2,2,2,2,2,2,2,2,2,2,2,2,2,2,2,1,1,1,1,1,0,0,0,0,0,0
0,0,0,0,0,0,0,0,0,0,0,0,0,0,0,0,0,0,0,1,1,1,1,1,1,1,1,2,2,2,2,2,2,2,2,2,2,2,2,2,2,2,2,1,1,1,1,1,0,0,0,0,0,0
endlayer

layer
0,0,0,0,0,0,0,0,0,0,0,0,0,0,0,0,0,0,0,1,1,1,1,1,1,1,1,2,2,2,2,2,2,2,2,2,2,2,2,2,2,2,2,1,1,1,1,1,0,0,0,0,0,0
0,0,3,3,3,3,3,3,3,3,3,3,3,3,3,3,3,3,3,1,1,1,1,1,1,1,1,2,2,2,2,2,2,2,2,2,2,2,2,2,2,2,2,1,1,1,1,1,0,0,0,0,0,0
0,0,0,0,0,0,0,0,0,0,0,0,0,0,0,0,0,0,0,1,1,1,1,1,1,1,1,2,2,2,2,2,2,2,2,2,2,2,2,2,2,2,2,1,1,1,1,1,0,0,0,0,0,0
0,0,0,0,0,0,0,0,0,0,0,0,0,0,0,0,0,0,0,1,1,1,1,1,1,1,1,4,4,4,4,4,4,4,4,4,4,4,4,4,4,4,4,1,1,1,1,1,0,0,0,0,0,0
0,0,0,0,0,0,0,0,0,0,0,0,0,0,0,0,0,0,0,1,1,1,1,1,1,1,4,6,6,6,6,6,0,0,0,0,0,0,0,0,0,0,0,4,1,1,1,1,0,0,0,0,0,0
0,0,0,0,0,0,0,0,0,0,0,0,0,0,0,0,0,0,0,1,1,1,1,1,1,1,4,6,0,0,0,6,0,0,0,0,0,0,0,0,0,0,0,4,1,1,1,1,0,0,0,0,0,0
0,0,0,0,0,0,0,0,0,0,0,0,0,0,0,0,0,0,0,1,1,1,1,1,1,1,4,6,0,0,0,6,0,0,0,0,0,0,0,0,0,0,0,4,1,1,1,1,0,0,0,0,0,0
0,0,0,0,0,0,0,0,0,0,0,0,0,0,0,0,0,0,0,1,1,1,1,1,1,1,4,6,0,0,0,6,0,0,0,0,0,0,0,0,0,0,0,4,1,1,1,1,0,0,0,0,0,0
0,0,0,0,0,0,0,0,0,0,0,0,0,0,0,0,0,0,0,1,1,1,1,1,1,1,4,6,0,0,0,6,0,0,0,0,0,0,0,0,0,0,0,4,1,1,1,1,0,0,0,0,0,0
0,0,0,0,0,0,0,0,0,0,0,0,0,0,0,0,0,0,0,1,1,1,1,1,1,1,4,7,0,0,0,7,0,0,0,0,0,0,0,0,0,0,0,4,1,1,1,1,0,0,0,0,0,0
0,0,0,0,0,0,0,0,0,0,0,0,0,0,0,0,0,0,0,1,1,1,1,1,1,1,4,7,0,0,0,0,0,0,0,0,0,0,0,0,0,0,0,4,1,1,1,1,0,0,0,0,0,0
0,0,0,0,0,0,0,0,0,0,0,0,0,0,0,0,0,0,0,1,1,1,1,1,1,1,4,7,0,0,0,0,0,0,0,0,0,0,0,0,0,0,0,4,1,1,1,1,0,0,0,0,0,0
0,0,0,0,0,0,0,0,0,0,0,0,0,0,0,2,2,2,2,4,4,4,4,4,4,4,4,7,0,0,0,0,0,0,0,0,0,0,0,0,0,0,0,4,1,1,1,1,0,0,0,0,0,0
0,0,0,0,0,0,0,0,0,0,0,0,0,0,0,2,2,2,2,4,0,0,0,0,0,8,7,7,0,0,0,0,0,0,0,0,0,0,0,0,0,0,0,4,1,1,1,1,0,0,0,0,0,0
0,0,0,0,0,0,0,0,0,0,0,0,0,0,0,2,2,2,2,4,0,0,0,0,0,8,7,7,0,0,0,0,0,0,0,0,0,0,0,0,0,0,0,4,1,1,1,1,0,0,0,0,0,0
0,0,0,0,0,0,0,0,0,0,0,0,0,0,0,2,2,2,2,4,0,0,0,0,0,8,7,7,0,0,0,0,0,0,0,0,0,0,0,0,0,0,0,4,1,1,1,1,0,0,0,0,0,0
0,0,0,0,0,0,0,0,0,0,0,0,0,0,0,2,2,2,2,4,0,0,0,0,0,8,7,7,0,0,0,0,0,0,0,0,0,0,0,0,0,0,0,4,1,1,1,1,0,0,0,0,0,0
0,0,0,0,0,0,0,0,0,0,0,0,0,0,0,2,2,2,2,4,0,0,0,0,0,8,7,7,0,0,0,0,0,0,0,0,0,0,0,0,0,0,0,4,1,1,1,1,0,0,0,0,0,0
0,0,0,0,0,0,0,0,0,0,0,0,0,0,0,2,2,2,2,4,0,0,0,0,0,8,7,7,0,0,0,0,0,0,0,0,0,0,0,0,0,0,0,4,1,1,1,1,0,0,0,0,0,0
0,0,0,0,0,0,0,0,0,0,0,0,0,0,0,2,2,2,2,4,0,0,0,0,0,8,7,7,0,0,0,0,0,0,0,0,0,0,6,6,6,6,6,4,4,4,1,1,0,0,0,0,0,0
0,0,0,0,0,0,0,0,0,0,0,0,0,0,0,2,2,2,2,4,0,0,0,0,0,8,7,7,0,0,0,0,0,0,0,0,0,0,6,0,0,0,0,0,0,0,4,1,0,0,0,0,0,0
0,0,0,0,0,0,0,0,0,0,0,0,0,0,0,2,2,2,2,4,0,0,0,0,0,8,7,7,0,0,0,0,0,0,0,0,0,0,6,0,0,0,0,0,0,0,4,1,0,0,0,0,0,0
0,0,0,0,0,0,0,0,0,0,0,0,0,0,0,2,2,2,2,4,0,0,0,0,0,8,7,7,0,0,0,0,0,0,0,0,0,0,6,0,0,0,0,0,0,0,4,1,0,0,0,0,0,0
0,0,0,0,0,0,0,0,0,0,0,0,0,0,0,2,2,2,2,4,0,0,0,0,0,8,7,7,0,0,0,0,0,0,0,0,0,0,6,0,0,0,0,0,0,0,4,1,0,0,0,0,0,0
0,0,0,0,0,0,0,0,0,0,0,0,0,0,0,2,2,2,2,4,0,0,0,0,0,8,7,7,0,0,0,0,0,0,0,0,0,0,6,0,0,0,6,4,4,4,1,1,0,0,0,0,0,0
0,0,0,0,0,0,0,0,0,0,0,0,0,0,0,2,2,2,2,4,0,0,0,0,0,8,7,7,0,0,0,0,0,0,0,0,0,0,6,0,0,0,6,4,1,1,1,1,0,0,0,0,0,0
0,0,0,0,0,0,0,0,0,0,0,0,0,0,0,2,2,2,2,4,0,0,0,0,0,8,7,7,0,0,0,0,0,0,0,0,0,0,6,0,0,0,6,4,1,1,1,1,0,0,0,0,0,0
0,0,0,0,0,0,0,0,0,0,0,0,0,0,0,2,2,2,2,4,0,0,0,0,0,8,7,7,0,0,0,0,0,0,0,0,0,0,6,0,0,0,6,4,1,1,1,1,0,0,0,0,0,0
0,0,0,0,0,0,0,0,0,0,0,0,0,0,0,2,2,2,2,4,0,0,0,0,0,8,7,7,0,0,0,0,0,0,0,0,0,0,6,0,0,0,6,4,1,1,1,1,0,0,0,0,0,0
0,0,0,0,0,0,0,0,0,0,0,0,0,0,0,2,2,2,2,4,0,0,0,0,0,8,7,7,0,0,0,0,0,0,0,0,0,0,6,0,0,0,6,4,1,1,1,1,0,0,0,0,0,0
0,0,0,0,0,0,0,0,0,0,0,0,0,0,0,2,2,2,2,4,0,0,0,0,0,8,7,7,0,0,0,0,0,0,0,0,0,0,6,0,0,0,6,4,1,1,1,1,0,0,0,0,0,0
0,0,0,0,0,0,0,0,0,0,0,0,0,0,0,2,2,2,2,4,4,4,4,4,4,4,4,7,0,0,0,0,0,0,0,0,0,0,6,0,0,0,6,4,1,1,1,1,0,0,0,0,0,0
0,0,0,0,0,0,0,0,0,0,0,0,0,0,0,0,0,0,0,1,1,1,1,1,1,1,4,7,0,0,0,0,0,0,0,0,0,0,6,0,0,0,6,4,1,1,1,1,0,0,0,0,0,0
0,0,0,0,0,0,0,0,0,0,0,0,0,0,0,0,0,0,0,1,1,1,1,1,1,1,4,7,0,0,0,0,0,0,0,0,0,0,6,0,0,0,6,4,1,1,1,1,0,0,0,0,0,0
0,0,0,0,0,0,0,0,0,0,0,0,0,0,0,0,0,0,0,1,1,1,1,1,1,1,4,7,7,7,7,7,0,0,0,0,0,0,6,0,0,0,6,4,1,1,1,1,0,0,0,0,0,0
0,0,0,0,0,0,0,0,0,0,0,0,0,0,0,0,0,0,0,1,1,1,1,1,1,1,4,6,6,6,6,6,6,6,6,6,6,6,6,0,0,0,6,4,1,1,1,1,0,0,0,0,0,0
0,0,0,0,0,0,0,0,0,0,0,0,0,0,0,0,0,0,0,1,1,1,1,1,1,1,4,6,0,0,0,0,0,0,0,0,0,0,0,0,0,0,6,4,1,1,1,1,0,0,0,0,0,0
0,0,0,0,0,0,0,0,0,0,0,0,0,0,0,0,0,0,0,1,1,1,1,1,1,1,4,6,0,0,0,0,0,0,0,0,0,0,0,0,0,0,6,4,1,1,1,1,0,0,0,0,0,0
0,0,0,0,0,0,0,0,0,0,0,0,0,0,0,0,0,0,0,1,1,1,1,1,1,1,4,6,0,0,0,0,0,0,0,0,0,0,0,0,0,0,6,4,1,1,1,1,0,0,0,0,0,0
0,0,0,0,0,0,0,0,0,0,0,0,0,0,0,0,0,0,0,1,1,1,1,1,1,1,4,6,6,6,6,6,6,6,6,6,6,6,6,6,6,6,6,4,1,1,1,1,0,0,0,0,0,0
0,0,0,0,0,0,0,0,0,0,0,0,0,0,0,0,0,0,0,1,1,1,1,1,1,1,1,4,4,4,4,4,4,4,4,4,4,4,4,4,4,4,4,1,1,1,1,1,0,0,0,0,0,0
0,0,0,0,0,0,0,0,0,0,0,0,0,0,0,0,0,0,0,1,1,1,1,1,1,1,1,2,2,2,2,2,2,2,2,2,2,2,2,2,2,2,2,1,1,1,1,1,0,0,0,0,0,0
0,0,0,0,0,0,0,0,0,0,0,0,0,0,0,0,0,0,0,1,1,1,1,1,1,1,1,2,2,2,2,2,2,2,2,2,2,2,2,2,2,2,2,1,1,1,1,1,0,0,0,0,0,0
0,0,0,0,0,0,0,0,0,0,0,0,0,0,0,0,0,0,0,1,1,1,1,1,1,1,1,2,2,2,2,2,2,2,2,2,2,2,2,2,2,2,2,1,1,1,1,1,0,0,0,0,0,0
endlayer

layer
0,0,3,0,0,0,0,0,0,0,0,0,0,0,0,0,0,0,0,1,1,1,1,1,1,1,1,2,2,2,2,2,2,2,2,2,2,2,2,2,2,2,2,1,1,1,1,1,0,0,0,0,0,0
0,0,3,3,3,3,3,3,3,3,3,3,3,3,3,3,3,3,3,1,1,1,1,1,1,1,1,2,2,2,2,2,2,2,2,2,2,2,2,2,2,2,2,1,1,1,1,1,0,0,0,0,0,0
0,0,0,0,0,0,0,0,0,0,0,0,0,0,0,0,0,0,0,1,1,1,1,1,1,1,1,2,2,2,2,2,2,2,2,2,2,2,2,2,2,2,2,1,1,1,1,1,0,0,0,0,0,0
0,0,0,0,0,0,0,0,0,0,0,0,0,0,0,0,0,0,0,1,1,1,1,1,1,1,1,4,4,4,4,4,4,4,4,4,4,4,4,4,4,4,4,1,1,1,1,1,0,0,0,0,0,0
0,0,0,0,0,0,0,0,0,0,0,0,0,0,0,0,0,0,0,1,1,1,1,1,1,1,4,6,6,6,6,6,0,0,0,0,0,0,0,0,0,0,0,4,1,1,1,1,0,0,0,0,0,0
0,0,0,0,0,0,0,0,0,0,0,0,0,0,0,0,0,0,0,1,1,1,1,1,1,1,4,6,0,0,0,6,0,0,0,0,0,0,0,0,0,0,0,4,1,1,1,1,0,0,0,0,0,0
0,0,0,0,0,0,0,0,0,0,0,0,0,0,0,0,0,0,0,1,1,1,1,1,1,1,4,6,0,0,0,6,0,0,0,0,0,0,0,0,0,0,0,4,1,1,1,1,0,0,0,0,0,0
0,0,0,0,0,0,0,0,0,0,0,0,0,0,0,0,0,0,0,1,1,1,1,1,1,1,4,6,0,0,0,6,0,0,0,0,0,0,0,0,0,0,0,4,1,1,1,1,0,0,0,0,0,0
0,0,0,0,0,0,0,0,0,0,0,0,0,0,0,1,1,1,1,4,4,4,4,4,4,4,4,6,0,0,0,6,0,0,0,0,0,0,0,0,0,0,0,4,1,1,1,1,0,0,0,0,0,0
0,0,0,0,0,0,0,0,0,0,0,0,0,0,0,1,1,1,1,4,4,4,4,4,4,4,4,7,0,0,0,7,0,0,0,0,0,0,0,0,0,0,0,4,1,1,1,1,0,0,0,0,0,0
0,0,0,0,0,0,0,0,0,0,0,0,0,0,0,1,1,1,1,4,4,4,4,4,4,4,4,7,0,0,0,0,0,0,0,0,0,0,0,0,0,0,0,4,1,1,1,1,0,0,0,0,0,0
0,0,0,0,0,0,0,0,0,0,0,0,0,0,0,1,1,1,1,4,4,4,4,4,4,4,4,7,0,0,0,0,0,0,0,0,0,0,0,0,0,0,0,4,1,1,1,1,0,0,0,0,0,0
0,0,0,0,0,0,0,0,0,0,0,0,0,0,0,2,2,2,2,4,4,4,4,4,4,4,4,7,0,0,0,0,0,0,0,0,0,0,0,0,0,0,0,4,1,1,1,1,0,0,0,0,0,0
0,0,0,0,0,0,0,0,0,0,0,0,0,0,0,2,2,2,2,4,0,0,0,0,0,8,7,7,0,0,0,0,0,0,0,0,0,0,0,0,0,0,0,4,1,1,1,1,0,0,0,0,0,0
0,0,0,0,0,0,0,0,0,0,0,0,0,0,0,2,2,2,2,4,0,0,0,0,0,8,7,7,0,0,0,0,0,0,0,0,0,0,0,0,0,0,0,4,1,1,1,1,0,0,0,0,0,0
0,0,0,0,0,0,0,0,0,0,0,0,0,0,0,2,2,2,2,4,0,0,0,0,0,8,7,7,0,0,0,0,0,0,0,0,0,0,0,0,0,0,0,4,1,1,1,1,0,0,0,0,0,0
0,0,0,0,0,0,0,0,0,0,0,2,2,2,2,4,4,4,4,4,0,0,0,0,0,8,7,7,0,0,0,0,0,0,0,0,0,0,0,0,0,0,0,4,1,1,1,1,0,0,0,0,0,0
0,0,0,0,0,0,0,0,0,0,0,2,2,2,2,4,4,4,4,4,0,0,0,0,0,8,7,7,0,0,0,0,0,0,0,0,0,0,0,0,0,0,0,4,1,1,1,1,0,0,0,0,0,0
0,0,0,0,0,0,0,0,0,0,0,2,2,2,2,4,4,4,4,4,0,0,0,0,0,8,7,7,0,0,0,0,0,0,0,0,0,0,0,0,0,0,0,4,1,1,1,1,0,0,0,0,0,0
0,0,0,0,0,0,0,0,0,0,0,2,2,2,2,4,4,4,4,4,0,0,0,0,0,8,7,7,0,0,0,0,0,0,0,0,0,0,6,6,6,6,6,4,4,4,1,1,0,0,0,0,0,0
0,0,0,0,0,0,0,0,0,0,0,2,2,2,2,4,4,4,4,4,0,0,0,0,0,8,7,7,0,0,0,0,0,0,0,0,0,0,6,0,0,0,0,0,0,0,4,1,0,0,0,0,0,0
0,0,0,0,0,0,0,0,0,0,0,2,2,2,2,4,4,4,4,4,0,0,0,0,0,8,7,7,0,0,0,0,0,0,0,0,0,0,6,0,0,0,0,0,0,0,4,1,0,0,0,0,0,0
0,0,0,0,0,0,0,0,0,0,0,2,2,2,2,4,4,4,4,4,0,0,0,0,0,8,7,7,0,0,0,0,0,0,0,0,0,0,6,0,0,0,0,0,0,0,4,1,0,0,0,0,0,0
0,0,0,0,0,0,0,0,0,0,0,2,2,2,2,4,4,4,4,4,0,0,0,0,0,8,7,7,0,0,0,0,0,0,0,0,0,0,6,0,0,0,0,0,0,0,4,1,0,0,0,0,0,0
0,0,0,0,0,0,0,0,0,0,0,2,2,2,2,4,4,4,4,4,0,0,0,0,0,8,7,7,0,0,0,0,0,0,0,0,0,0,6,0,0,0,6,4,4,4,1,1,0,0,0,0,0,0
0,0,0,0,0,0,0,0,0,0,0,2,2,2,2,4,4,4,4,4,0,0,0,0,0,8,7,7,0,0,0,0,0,0,0,0,0,0,6,0,0,0,6,4,1,1,1,1,0,0,0,0,0,0
0,0,0,0,0,0,0,0,0,0,0,2,2,2,2,4,4,4,4,4,0,0,0,0,0,8,7,7,0,0,0,0,0,0,0,0,0,0,6,0,0,0,6,4,1,1,1,1,0,0,0,0,0,0
0,0,0,0,0,0,0,0,0,0,0,2,2,2,2,4,4,4,4,4,0,0,0,0,0,8,7,7,0,0,0,0,0,0,0,0,0,0,6,0,0,0,6,4,1,1,1,1,0,0,0,0,0,0
0,0,0,0,0,0,0,0,0,0,0,0,0,0,0,2,2,2,2,4,0,0,0,0,0,8,7,7,0,0,0,0,0,0,0,0,0,0,6,0,0,0,6,4,1,1,1,1,0,0,0,0,0,0
0,0,0,0,0,0,0,0,0,0,0,0,0,0,0,2,2,2,2,4,0,0,0,0,0,8,7,7,0,0,0,0,0,0,0,0,0,0,6,0,0,0,6,4,1,1,1,1,0,0,0,0,0,0
0,0,0,0,0,0,0,0,0,0,0,0,0,0,0,2,2,2,2,4,0,0,0,0,0,8,7,7,0,0,0,0,0,0,0,0,0,0,6,0,0,0,6,4,1,1,1,1,0,0,0,0,0,0
0,0,0,0,0,0,0,0,0,0,0,0,0,0,0,2,2,2,2,4,4,4,4,4,4,4,4,7,0,0,0,0,0,0,0,0,0,0,6,0,0,0,6,4,1,1,1,1,0,0,0,0,0,0
0,0,0,0,0,0,0,0,0,0,0,0,0,0,0,1,1,1,1,4,4,4,4,4,4,4,4,7,0,0,0,0,0,0,0,0,0,0,6,0,0,0,6,4,1,1,1,1,0,0,0,0,0,0
0,0,0,0,0,0,0,0,0,0,0,0,0,0,0,1,1,1,1,4,4,4,4,4,4,4,4,7,0,0,0,0,0,0,0,0,0,0,6,0,0,0,6,4,1,1,1,1,0,0,0,0,0,0
0,0,0,0,0,0,0,0,0,0,0,0,0,0,0,1,1,1,1,4,4,4,4,4,4,4,4,7,7,7,7,7,0,0,0,0,0,0,6,0,0,0,6,4,1,1,1,1,0,0,0,0,0,0
0,0,0,0,0,0,0,0,0,0,0,0,0,0,0,1,1,1,1,4,4,4,4,4,4,4,4,6,6,6,6,6,6,6,6,6,6,6,6,0,0,0,6,4,1,1,1,1,0,0,0,0,0,0
0,0,0,0,0,0,0,0,0,0,0,0,0,0,0,0,0,0,0,1,1,1,1,1,1,1,4,6,0,0,0,0,0,0,0,0,0,0,0,0,0,0,6,4,1,1,1,1,0,0,0,0,0,0
0,0,0,0,0,0,0,0,0,0,0,0,0,0,0,0,0,0,0,1,1,1,1,1,1,1,4,6,0,0,0,0,0,0,0,0,0,0,0,0,0,0,6,4,1,1,1,1,0,0,0,0,0,0
0,0,0,0,0,0,0,0,0,0,0,0,0,0,0,0,0,0,0,1,1,1,1,1,1,1,4,6,0,0,0,0,0,0,0,0,0,0,0,0,0,0,6,4,1,1,1,1,0,0,0,0,0,0
0,0,0,0,0,0,0,0,0,0,0,0,0,0,0,0,0,0,0,1,1,1,1,1,1,1,4,6,6,6,6,6,6,6,6,6,6,6,6,6,6,6,6,4,1,1,1,1,0,0,0,0,0,0
0,0,0,0,0,0,0,0,0,0,0,0,0,0,0,0,0,0,0,1,1,1,1,1,1,1,1,4,4,4,4,4,4,4,4,4,4,4,4,4,4,4,4,1,1,1,1,1,0,0,0,0,0,0
0,0,0,0,0,0,0,0,0,0,0,0,0,0,0,0,0,0,0,1,1,1,1,1,1,1,1,2,2,2,2,2,2,2,2,2,2,2,2,2,2,2,2,1,1,1,1,1,0,0,0,0,0,0
0,0,0,0,0,0,0,0,0,0,0,0,0,0,0,0,0,0,0,1,1,1,1,1,1,1,1,2,2,2,2,2,2,2,2,2,2,2,2,2,2,2,2,1,1,1,1,1,0,0,0,0,0,0
0,0,0,0,0,0,0,0,0,0,0,0,0,0,0,0,0,0,0,1,1,1,1,1,1,1,1,2,2,2,2,2,2,2,2,2,2,2,2,2,2,2,2,1,1,1,1,1,0,0,0,0,0,0
endlayer

layer
0,0,3,3,3,3,3,3,3,3,3,3,3,3,3,3,3,3,3,1,1,1,1,1,1,1,1,2,2,2,2,2,2,2,2,2,2,2,2,2,2,2,2,1,1,1,1,1,0,0,0,0,0,0
0,0,0,0,0,0,0,0,0,0,0,0,0,0,0,0,0,0,0,1,1,1,1,1,1,1,1,2,2,2,2,2,2,2,2,2,2,2,2,2,2,2,2,1,1,1,1,1,0,0,0,0,0,0
0,0,0,0,0,0,0,0,0,0,0,0,0,0,0,0,0,0,0,1,1,1,1,1,1,1,1,2,2,2,2,2,2,2,2,2,2,2,2,2,2,2,2,1,1,1,1,1,0,0,0,0,0,0
0,0,0,0,0,0,0,0,0,0,0,0,0,0,0,0,0,0,0,1,1,1,1,1,1,1,1,4,4,4,4,4,4,4,4,4,4,4,4,4,4,4,4,1,1,1,1,1,0,0,0,0,0,0
0,0,0,0,0,0,0,0,0,0,0,0,0,0,0,0,0,0,0,1,1,1,1,1,1,1,4,6,6,6,6,6,0,0,0,0,0,0,0,0,0,0,0,4,1,1,1,1,0,0,0,0,0,0
0,0,0,0,0,0,0,0,0,0,0,0,0,0,0,0,0,0,0,1,1,1,1,1,1,1,4,6,0,0,0,6,0,0,0,0,0,0,0,0,0,0,0,4,1,1,1,1,0,0,0,0,0,0
0,0,0,0,0,0,0,0,0,0,0,0,0,0,0,0,0,0,0,1,1,1,1,1,1,1,4,6,0,0,0,6,0,0,0,0,0,0,0,0,0,0,0,4,1,1,1,1,0,0,0,0,0,0
0,0,0,0,0,0,0,0,0,0,0,0,0,0,0,0,0,0,0,1,1,1,1,1,1,1,4,6,0,0,0,6,0,0,0,0,0,0,0,0,0,0,0,4,1,1,1,1,0,0,0,0,0,0
0,0,0,0,0,0,0,0,0,0,0,0,0,0,0,1,1,1,1,4,4,4,4,4,4,4,4,6,6,6,6,6,0,0,0,0,0,0,0,0,0,0,0,4,1,1,1,1,0,0,0,0,0,0
0,0,0,0,0,0,0,0,0,0,0,0,0,0,0,1,1,1,1,4,0,0,0,0,0,0,8,7,7,7,7,7,0,0,0,0,0,0,0,0,0,0,0,4,1,1,1,1,0,0,0,0,0,0
0,0,0,0,0,0,0,0,0,0,0,0,0,0,0,1,1,1,1,4,0,0,0,0,0,0,8,7,7,7,7,7,0,0,0,0,0,0,0,0,0,0,0,4,1,1,1,1,0,0,0,0,0,0
0,0,0,0,0,0,0,0,0,0,0,0,0,0,0,1,1,1,1,4,0,0,0,0,0,0,8,7,7,7,7,7,0,0,0,0,0,0,0,0,0,0,0,4,1,1,1,1,0,0,0,0,0,0
0,0,0,0,0,0,0,0,0,0,0,0,0,0,0,2,2,2,2,4,0,0,0,0,0,0,8,7,7,7,7,7,0,0,0,0,0,0,0,0,0,0,0,4,1,1,1,1,0,0,0,0,0,0
0,0,0,0,0,0,0,0,0,0,0,0,0,0,0,2,2,2,2,4,0,0,0,0,0,0,8,7,7,7,7,7,0,0,0,0,0,0,0,0,0,0,0,4,1,1,1,1,0,0,0,0,0,0
0,0,0,0,0,0,0,0,0,0,0,0,0,0,0,2,2,2,2,4,0,0,0,0,0,0,8,7,7,7,7,7,0,0,0,0,0,0,0,0,0,0,0,4,1,1,1,1,0,0,0,0,0,0
0,0,0,0,0,0,0,0,0,0,0,0,0,0,0,2,2,2,2,4,0,0,0,0,0,0,8,7,7,7,7,7,0,0,0,0,0,0,0,0,0,0,0,4,1,1,1,1,0,0,0,0,0,0
0,0,0,0,0,0,0,0,0,0,0,2,2,2,2,4,4,4,4,4,0,0,0,0,0,0,8,7,7,7,7,7,0,0,0,0,0,0,0,0,0,0,0,4,1,1,1,1,0,0,0,0,0,0
0,0,0,0,0,0,0,0,0,0,0,2,2,2,2,4,0,0,0,0,0,0,0,0,0,0,8,7,7,7,7,7,0,0,0,0,0,0,0,0,0,0,0,4,1,1,1,1,0,0,0,0,0,0
0,0,0,0,0,0,0,0,0,0,0,2,2,2,2,4,0,0,0,0,0,0,0,0,0,0,8,7,7,7,7,7,0,0,0,0,0,0,0,0,0,0,0,4,1,1,1,1,0,0,0,0,0,0
0,0,0,0,0,0,0,0,0,0,0,2,2,2,2,4,0,0,0,0,0,0,0,0,0,0,8,7,7,7,7,7,0,0,0,0,0,0,6,6,6,6,6,4,4,4,1,1,0,0,0,0,0,0
0,0,0,0,0,0,0,0,0,0,0,2,2,2,2,4,0,0,0,0,0,0,0,0,0,0,8,7,7,7,7,7,0,0,0,0,0,0,6,0,0,0,0,0,0,0,4,1,0,0,0,0,0,0
0,0,0,0,0,0,0,0,0,0,0,2,2,2,2,4,0,0,0,0,0,0,0,0,0,0,8,7,7,7,7,7,0,0,0,0,0,0,6,0,0,0,0,0,0,0,4,1,0,0,0,0,0,0
0,0,0,0,0,0,0,0,0,0,0,2,2,2,2,4,0,0,0,0,0,0,0,0,0,0,8,7,7,7,7,7,0,0,0,0,0,0,6,0,0,0,0,0,0,0,4,1,0,0,0,0,0,0
0,0,0,0,0,0,0,0,0,0,0,2,2,2,2,4,0,0,0,0,0,0,0,0,0,0,8,7,7,7,7,7,0,0,0,0,0,0,6,0,0,0,0,0,0,0,0,0,0,0,0,0,0,0
0,0,0,0,0,0,0,0,0,0,0,2,2,2,2,4,0,0,0,0,0,0,0,0,0,0,8,7,7,7,7,7,0,0,0,0,0,0,6,0,0,0,6,4,4,4,1,1,0,0,0,0,0,0
0,0,0,0,0,0,0,0,0,0,0,2,2,2,2,4,0,0,0,0,0,0,0,0,0,0,8,7,7,7,7,7,0,0,0,0,0,0,6,0,0,0,6,4,1,1,1,1,0,0,0,0,0,0
0,0,0,0,0,0,0,0,0,0,0,2,2,2,2,4,0,0,0,0,0,0,0,0,0,0,8,7,7,7,7,7,0,0,0,0,0,0,6,0,0,0,6,4,1,1,1,1,0,0,0,0,0,0
0,0,0,0,0,0,0,0,0,0,0,2,2,2,2,4,4,4,4,4,0,0,0,0,0,0,8,7,7,7,7,7,0,0,0,0,0,0,6,0,0,0,6,4,1,1,1,1,0,0,0,0,0,0
0,0,0,0,0,0,0,0,0,0,0,0,0,0,0,2,2,2,2,4,0,0,0,0,0,0,8,7,7,7,7,7,0,0,0,0,0,0,6,0,0,0,6,4,1,1,1,1,0,0,0,0,0,0
0,0,0,0,0,0,0,0,0,0,0,0,0,0,0,2,2,2,2,4,0,0,0,0,0,0,8,7,7,7,7,7,0,0,0,0,0,0,6,0,0,0,6,4,1,1,1,1,0,0,0,0,0,0
0,0,0,0,0,0,0,0,0,0,0,0,0,0,0,2,2,2,2,4,0,0,0,0,0,0,8,7,7,7,7,7,0,0,0,0,0,0,6,0,0,0,6,4,1,1,1,1,0,0,0,0,0,0
0,0,0,0,0,0,0,0,0,0,0,0,0,0,0,2,2,2,2,4,0,0,0,0,0,8,7,7,7,7,7,7,0,0,0,0,0,0,6,0,0,0,6,4,1,1,1,1,0,0,0,0,0,0
0,0,0,0,0,0,0,0,0,0,0,0,0,0,0,1,1,1,1,4,0,0,0,0,0,8,7,0,0,0,0,0,0,0,0,0,0,0,6,0,0,0,6,4,1,1,1,1,0,0,0,0,0,0
0,0,0,0,0,0,0,0,0,0,0,0,0,0,0,1,1,1,1,4,0,0,0,0,0,8,7,0,0,0,0,0,0,0,0,0,0,0,6,0,0,0,6,4,1,1,1,1,0,0,0,0,0,0
0,0,0,0,0,0,0,0,0,0,0,0,0,0,0,1,1,1,1,4,0,0,0,0,0,0,8,7,7,7,7,7,0,0,0,0,0,0,6,0,0,0,6,4,1,1,1,1,0,0,0,0,0,0
0,0,0,0,0,0,0,0,0,0,0,0,0,0,0,1,1,1,1,4,4,4,4,4,4,4,4,6,6,6,6,6,6,6,6,6,6,6,6,0,0,0,6,4,1,1,1,1,0,0,0,0,0,0
0,0,0,0,0,0,0,0,0,0,0,0,0,0,0,0,0,0,0,1,1,1,1,1,1,1,4,6,0,0,0,0,0,0,0,0,0,0,0,0,0,0,6,4,1,1,1,1,0,0,0,0,0,0
0,0,0,0,0,0,0,0,0,0,0,0,0,0,0,0,0,0,0,1,1,1,1,1,1,1,4,6,0,0,0,0,0,0,0,0,0,0,0,0,0,0,6,4,1,1,1,1,0,0,0,0,0,0
0,0,0,0,0,0,0,0,0,0,0,0,0,0,0,0,0,0,0,1,1,1,1,1,1,1,4,6,0,0,0,0,0,0,0,0,0,0,0,0,0,0,6,4,1,1,1,1,0,0,0,0,0,0
0,0,0,0,0,0,0,0,0,0,0,0,0,0,0,0,0,0,0,1,1,1,1,1,1,1,4,6,6,6,6,6,6,6,6,6,6,6,6,6,6,6,6,4,1,1,1,1,0,0,0,0,0,0
0,0,0,0,0,0,0,0,0,0,0,0,0,0,0,0,0,0,0,1,1,1,1,1,1,1,1,4,4,4,4,4,4,4,4,4,4,4,4,4,4,4,4,1,1,1,1,1,0,0,0,0,0,0
0,0,0,0,0,0,0,0,0,0,0,0,0,0,0,0,0,0,0,1,1,1,1,1,1,1,1,2,2,2,2,2,2,2,2,2,2,2,2,2,2,2,2,1,1,1,1,1,0,0,0,0,0,0
0,0,0,0,0,0,0,0,0,0,0,0,0,0,0,0,0,0,0,1,1,1,1,1,1,1,1,2,2,2,2,2,2,2,2,2,2,2,2,2,2,2,2,1,1,1,1,1,0,0,0,0,0,0
0,0,0,0,0,0,0,0,0,0,0,0,0,0,0,0,0,0,0,1,1,1,1,1,1,1,1,2,2,2,2,2,2,2,2,2,2,2,2,2,2,2,2,1,1,1,1,1,0,0,0,0,0,0
endlayer

layer
0,0,3,3,3,3,3,3,3,3,3,3,3,3,3,3,3,3,3,1,1,1,1,1,1,1,1,2,2,2,2,2,2,2,2,2,2,2,2,2,2,2,2,1,1,1,1,1,0,0,0,0,0,0
0,0,0,0,0,0,0,0,0,0,0,0,0,0,0,0,0,0,0,1,1,1,1,1,1,1,1,2,2,2,2,2,2,2,2,2,2,2,2,2,2,2,2,1,1,1,1,1,0,0,0,0,0,0
0,0,0,0,0,0,0,0,0,0,0,0,0,0,0,0,0,0,0,1,1,1,1,1,1,1,1,2,2,2,2,2,2,2,2,2,2,2,2,2,2,2,2,1,1,1,1,1,0,0,0,0,0,0
0,0,0,0,0,0,0,0,0,0,0,0,0,0,0,0,0,0,0,1,1,1,1,1,1,1,1,4,4,4,4,4,4,4,4,4,4,4,4,4,4,4,4,1,1,1,1,1,0,0,0,0,0,0
0,0,0,0,0,0,0,0,0,0,0,0,0,0,0,0,0,0,0,1,1,1,1,1,1,1,4,6,6,6,6,6,0,0,0,0,0,0,0,0,0,0,0,4,1,1,1,1,0,0,0,0,0,0
0,0,0,0,0,0,0,0,0,0,0,0,0,0,0,0,0,0,0,1,1,1,1,1,1,1,4,6,0,0,0,6,0,0,0,0,0,0,0,0,0,0,0,4,1,1,1,1,0,0,0,0,0,0
0,0,0,0,0,0,0,0,0,0,0,0,0,0,0,0,0,0,0,1,1,1,1,1,1,1,4,6,0,0,0,6,0,0,0,0,0,0,0,0,0,0,0,4,1,1,1,1,0,0,0,0,0,0
0,0,0,0,0,0,0,0,0,0,0,0,0,0,0,0,0,0,0,1,1,1,1,1,1,1,4,6,0,0,0,6,0,0,0,0,0,0,0,0,0,0,0,4,1,1,1,1,0,0,0,0,0,0
0,0,0,0,0,0,0,0,0,0,0,0,0,0,0,1,1,1,1,4,4,4,4,4,4,4,4,6,6,6,6,6,0,0,0,0,0,0,0,0,0,0,0,4,1,1,1,1,0,0,0,0,0,0
0,0,0,0,0,0,0,0,0,0,0,0,0,0,0,1,1,1,1,4,0,0,0,0,0,0,8,7,7,7,7,7,0,0,0,0,0,0,0,0,0,0,0,4,1,1,1,1,0,0,0,0,0,0
0,0,0,0,0,0,0,0,0,0,0,0,0,0,0,1,1,1,1,4,0,0,0,0,0,8,7,0,0,0,0,0,0,0,0,0,0,0,0,0,0,0,0,4,1,1,1,1,0,0,0,0,0,0
0,0,0,0,0,0,0,0,0,0,0,0,0,0,0,1,1,1,1,4,0,0,0,0,0,8,7,0,0,0,0,0,0,0,0,0,0,0,0,0,0,0,0,4,1,1,1,1,0,0,0,0,0,0
0,0,0,0,0,0,0,0,0,0,0,0,0,0,0,2,2,2,2,4,0,0,0,0,0,8,7,0,0,0,0,0,0,0,0,0,0,0,0,0,0,0,0,4,1,1,1,1,0,0,0,0,0,0
0,0,0,0,0,0,0,0,0,0,0,0,0,0,0,2,2,2,2,4,0,0,0,0,0,8,7,0,0,0,0,0,0,0,0,0,0,0,0,0,0,0,0,4,1,1,1,1,0,0,0,0,0,0
0,0,0,0,0,0,0,0,0,0,0,0,0,0,0,2,2,2,2,4,0,0,0,0,0,8,7,0,0,0,0,0,0,0,0,0,0,0,0,0,0,0,0,4,1,1,1,1,0,0,0,0,0,0
0,0,0,0,0,0,0,0,0,0,0,0,0,0,0,2,2,2,2,4,0,0,0,0,0,8,7,0,0,0,0,0,0,0,0,0,0,0,0,0,0,0,0,4,1,1,1,1,0,0,0,0,0,0
0,0,0,0,0,0,0,0,0,0,0,2,2,2,2,4,4,4,4,4,0,0,0,0,0,8,7,0,0,0,0,0,0,0,0,0,0,0,0,0,0,0,0,4,1,1,1,1,0,0,0,0,0,0
0,0,0,0,0,0,0,0,0,0,0,2,2,2,2,4,0,0,0,0,0,0,0,0,0,8,7,0,0,0,0,0,0,0,0,0,0,0,0,0,0,0,0,4,1,1,1,1,0,0,0,0,0,0
0,0,0,0,0,0,0,0,0,0,0,2,2,2,2,4,0,0,0,0,0,0,0,0,0,8,7,0,0,0,0,0,0,0,0,0,0,0,0,0,0,0,0,4,1,1,1,1,0,0,0,0,0,0
0,0,0,0,0,0,0,0,0,0,0,2,2,2,2,4,0,0,0,0,0,0,0,0,0,8,7,0,0,0,0,0,0,0,0,0,0,0,6,6,6,6,6,4,1,1,1,1,0,0,0,0,0,0
0,0,0,0,0,0,0,0,0,0,0,2,2,2,2,4,0,0,0,0,0,0,0,0,0,8,7,0,0,0,0,0,0,0,0,0,0,0,6,6,6,6,6,4,4,4,1,1,0,0,0,0,0,0
0,0,0,0,0,0,0,0,0,0,0,2,2,2,2,4,0,0,0,0,0,0,0,0,0,8,7,0,0,0,0,0,0,0,0,0,0,0,6,6,6,6,6,4,4,4,1,1,0,0,0,0,0,0
0,0,0,0,0,0,0,0,0,0,0,2,2,2,2,4,0,0,0,0,0,0,0,0,0,8,7,0,0,0,0,0,0,0,0,0,0,0,6,6,6,6,6,4,4,4,1,1,0,0,0,0,0,0
0,0,0,0,0,0,0,0,0,0,0,2,2,2,2,4,0,0,0,0,0,0,0,0,0,8,7,0,0,0,0,0,0,0,0,0,0,0,6,6,6,6,6,4,4,4,1,1,0,0,0,0,0,0
0,0,0,0,0,0,0,0,0,0,0,2,2,2,2,4,0,0,0,0,0,0,0,0,0,8,7,0,0,0,0,0,0,0,0,0,0,0,6,6,6,6,6,4,1,1,1,1,0,0,0,0,0,0
0,0,0,0,0,0,0,0,0,0,0,2,2,2,2,4,0,0,0,0,0,0,0,0,0,8,7,0,0,0,0,0,0,0,0,0,0,0,6,6,6,6,6,4,1,1,1,1,0,0,0,0,0,0
0,0,0,0,0,0,0,0,0,0,0,2,2,2,2,4,0,0,0,0,0,0,0,0,0,8,7,0,0,0,0,0,0,0,0,0,0,0,6,6,6,6,6,4,1,1,1,1,0,0,0,0,0,0
0,0,0,0,0,0,0,0,0,0,0,2,2,2,2,4,4,4,4,4,0,0,0,0,0,8,7,0,0,0,0,0,0,0,0,0,0,0,6,6,6,6,6,4,1,1,1,1,0,0,0,0,0,0
0,0,0,0,0,0,0,0,0,0,0,0,0,0,0,2,2,2,2,4,0,0,0,0,0,8,7,0,0,0,0,0,0,0,0,0,0,0,6,6,6,6,6,4,1,1,1,1,0,0,0,0,0,0
0,0,0,0,0,0,0,0,0,0,0,0,0,0,0,2,2,2,2,4,0,0,0,0,0,8,7,0,0,0,0,0,0,0,0,0,0,0,6,6,6,6,6,4,1,1,1,1,0,0,0,0,0,0
0,0,0,0,0,0,0,0,0,0,0,0,0,0,0,2,2,2,2,4,0,0,0,0,0,8,7,0,0,0,0,0,0,0,0,0,0,0,6,6,6,6,6,4,1,1,1,1,0,0,0,0,0,0
0,0,0,0,0,0,0,0,0,0,0,0,0,0,0,2,2,2,2,4,0,0,0,0,0,8,7,0,0,0,0,0,0,0,0,0,0,0,6,6,6,6,6,4,1,1,1,1,0,0,0,0,0,0
0,0,0,0,0,0,0,0,0,0,0,0,0,0,0,1,1,1,1,4,0,0,0,0,0,8,7,0,0,0,0,0,0,0,0,0,0,0,6,6,6,6,6,4,1,1,1,1,0,0,0,0,0,0
0,0,0,0,0,0,0,0,0,0,0,0,0,0,0,1,1,1,1,4,0,0,0,0,0,8,7,0,0,0,0,0,0,0,0,0,0,0,6,6,6,6,6,4,1,1,1,1,0,0,0,0,0,0
0,0,0,0,0,0,0,0,0,0,0,0,0,0,0,1,1,1,1,4,0,0,0,0,0,0,8,7,7,7,7,7,0,0,0,0,0,0,6,6,6,6,6,4,1,1,1,1,0,0,0,0,0,0
0,0,0,0,0,0,0,0,0,0,0,0,0,0,0,1,1,1,1,4,4,4,4,4,4,4,4,6,6,6,6,6,6,6,6,6,6,6,6,6,6,6,6,4,1,1,1,1,0,0,0,0,0,0
0,0,0,0,0,0,0,0,0,0,0,0,0,0,0,0,0,0,0,1,1,1,1,1,1,1,4,6,0,0,0,6,6,6,6,6,6,6,6,6,6,6,6,4,1,1,1,1,0,0,0,0,0,0
0,0,0,0,0,0,0,0,0,0,0,0,0,0,0,0,0,0,0,1,1,1,1,1,1,1,4,6,0,0,0,6,6,6,6,6,6,6,6,6,6,6,6,4,1,1,1,1,0,0,0,0,0,0
0,0,0,0,0,0,0,0,0,0,0,0,0,0,0,0,0,0,0,1,1,1,1,1,1,1,4,6,0,0,0,6,6,0,6,6,6,6,6,6,6,6,6,4,1,1,1,1,0,0,0,0,0,0
0,0,0,0,0,0,0,0,0,0,0,0,0,0,0,0,0,0,0,1,1,1,1,1,1,1,4,6,6,6,6,6,6,6,6,6,6,6,6,6,6,6,6,4,1,1,1,1,0,0,0,0,0,0
0,0,0,0,0,0,0,0,0,0,0,0,0,0,0,0,0,0,0,1,1,1,1,1,1,1,1,4,4,4,4,4,4,4,4,4,4,4,4,4,4,4,4,1,1,1,1,1,0,0,0,0,0,0
0,0,0,0,0,0,0,0,0,0,0,0,0,0,0,0,0,0,0,1,1,1,1,1,1,1,1,2,2,2,2,2,2,2,2,2,2,2,2,2,2,2,2,1,1,1,1,1,0,0,0,0,0,0
0,0,0,0,0,0,0,0,0,0,0,0,0,0,0,0,0,0,0,1,1,1,1,1,1,1,1,2,2,2,2,2,2,2,2,2,2,2,2,2,2,2,2,1,1,1,1,1,0,0,0,0,0,0
0,0,0,0,0,0,0,0,0,0,0,0,0,0,0,0,0,0,0,1,1,1,1,1,1,1,1,2,2,2,2,2,2,2,2,2,2,2,2,2,2,2,2,1,1,1,1,1,0,0,0,0,0,0
endlayer

layer
0,0,0,0,0,0,0,0,0,0,0,0,0,0,0,0,0,0,0,1,1,1,1,1,1,1,1,2,2,2,2,2,2,2,2,2,2,2,2,2,2,2,2,1,1,1,1,1,0,0,0,0,0,0
0,0,0,0,0,0,0,0,0,0,0,0,0,0,0,0,0,0,0,1,1,1,1,1,1,1,1,2,2,2,2,2,2,2,2,2,2,2,2,2,2,2,2,1,1,1,1,1,0,0,0,0,0,0
0,0,0,0,0,0,0,0,0,0,0,0,0,0,0,0,0,0,0,1,1,1,1,1,1,1,1,2,2,2,2,2,2,2,2,2,2,2,2,2,2,2,2,1,1,1,1,1,0,0,0,0,0,0
0,0,0,0,0,0,0,0,0,0,0,0,0,0,0,0,0,0,0,1,1,1,1,1,1,1,1,4,4,4,4,4,4,4,4,4,4,4,4,4,4,4,4,1,1,1,1,1,0,0,0,0,0,0
0,0,0,0,0,0,0,0,0,0,0,0,0,0,0,0,0,0,0,1,1,1,1,1,1,1,4,6,6,6,6,6,0,0,0,0,0,0,0,0,0,0,0,4,1,1,1,1,0,0,0,0,0,0
0,0,0,0,0,0,0,0,0,0,0,0,0,0,0,0,0,0,0,1,1,1,1,1,1,1,4,6,0,0,0,6,0,0,0,0,0,0,0,0,0,0,0,4,1,1,1,1,0,0,0,0,0,0
0,0,0,0,0,0,0,0,0,0,0,0,0,0,0,0,0,0,0,1,1,1,1,1,1,1,4,6,0,0,0,6,0,0,0,0,0,0,0,0,0,0,0,4,1,1,1,1,0,0,0,0,0,0
0,0,0,0,0,0,0,0,0,0,0,0,0,0,0,0,0,0,0,1,1,1,1,1,1,1,4,6,0,0,0,6,0,0,0,0,0,0,0,0,0,0,0,4,1,1,1,1,0,0,0,0,0,0
0,0,0,0,0,0,0,0,0,0,0,0,0,0,0,1,1,1,1,4,4,4,4,4,4,4,4,6,6,6,6,6,0,0,0,0,0,0,0,0,0,0,0,4,1,1,1,1,0,0,0,0,0,0
0,0,0,0,0,0,0,0,0,0,0,0,0,0,0,1,1,1,1,4,0,0,0,0,0,0,8,7,7,7,7,7,0,0,0,0,0,0,0,0,0,0,0,4,1,1,1,1,0,0,0,0,0,0
0,0,0,0,0,0,0,0,0,0,0,0,0,0,0,1,1,1,1,4,0,0,0,0,0,8,7,0,0,0,0,0,0,0,0,0,0,0,0,0,0,0,0,4,1,1,1,1,0,0,0,0,0,0
0,0,0,0,0,0,0,0,0,0,0,0,0,0,0,1,1,1,1,4,0,0,0,0,0,8,7,0,0,0,0,0,0,0,0,0,0,0,0,0,0,0,0,4,1,1,1,1,0,0,0,0,0,0
0,0,0,0,0,0,0,0,0,0,0,0,0,0,0,2,2,2,2,4,0,0,0,0,0,8,7,0,0,0,0,0,0,0,0,0,0,0,0,0,0,0,0,4,1,1,1,1,0,0,0,0,0,0
0,0,0,0,0,0,0,0,0,0,0,0,0,0,0,2,2,2,2,4,0,0,0,0,0,8,7,0,0,0,0,0,0,0,0,0,0,0,0,0,0,0,0,4,1,1,1,1,0,0,0,0,0,0
0,0,0,0,0,0,0,0,0,0,0,0,0,0,0,2,2,2,2,4,0,0,0,0,0,8,7,0,0,0,0,0,0,0,0,0,0,0,0,0,0,0,0,4,1,1,1,1,0,0,0,0,0,0
0,0,0,0,0,0,0,0,0,0,0,0,0,0,0,2,2,2,2,4,0,0,0,0,0,8,7,0,0,0,0,0,0,0,0,0,0,0,0,0,0,0,0,4,1,1,1,1,0,0,0,0,0,0
0,0,0,0,0,0,0,0,0,0,0,2,2,2,2,4,4,4,4,4,0,0,0,0,0,8,7,0,0,0,0,0,0,0,0,0,0,0,0,0,0,0,0,4,1,1,1,1,0,0,0,0,0,0
0,0,0,0,0,0,0,0,0,0,0,2,2,2,2,4,0,0,0,0,0,0,0,0,0,8,7,0,0,0,0,0,0,0,0,0,0,0,0,0,0,0,0,4,1,1,1,1,0,0,0,0,0,0
0,0,0,0,0,0,0,0,0,0,0,2,2,2,2,4,0,0,0,0,0,0,0,0,0,8,7,0,0,0,0,0,0,0,0,0,0,0,0,0,0,0,0,4,1,1,1,1,0,0,0,0,0,0
0,0,0,0,0,0,0,0,0,0,0,2,2,2,2,4,0,0,0,0,0,0,0,0,0,8,7,0,0,0,0,0,0,0,0,0,0,0,0,0,0,0,0,4,1,1,1,1,0,0,0,0,0,0
0,0,0,0,0,0,0,0,0,0,0,2,2,2,2,4,0,0,0,0,0,0,0,0,0,8,7,0,0,0,0,0,0,0,0,0,0,0,0,0,0,0,0,4,1,1,1,1,0,0,0,0,0,0
0,0,0,0,0,0,0,0,0,0,0,2,2,2,2,4,0,0,0,0,0,0,0,0,0,8,7,0,0,0,0,0,0,0,0,0,0,0,0,0,0,0,0,4,1,1,1,1,0,0,0,0,0,0
0,0,0,0,0,0,0,0,0,0,0,2,2,2,2,4,0,0,0,0,0,0,0,0,0,8,7,0,0,0,0,0,0,0,0,0,0,0,0,0,0,0,0,4,1,1,1,1,0,0,0,0,0,0
0,0,0,0,0,0,0,0,0,0,0,2,2,2,2,4,0,0,0,0,0,0,0,0,0,8,7,0,0,0,0,0,0,0,0,0,0,0,0,0,0,0,0,4,1,1,1,1,0,0,0,0,0,0
0,0,0,0,0,0,0,0,0,0,0,2,2,2,2,4,0,0,0,0,0,0,0,0,0,8,7,0,0,0,0,0,0,0,0,0,0,0,0,0,0,0,0,4,1,1,1,1,0,0,0,0,0,0
0,0,0,0,0,0,0,0,0,0,0,2,2,2,2,4,0,0,0,0,0,0,0,0,0,8,7,0,0,0,0,0,0,0,0,0,0,0,0,0,0,0,0,4,1,1,1,1,0,0,0,0,0,0
0,0,0,0,0,0,0,0,0,0,0,2,2,2,2,4,0,0,0,0,0,0,0,0,0,8,7,0,0,0,0,0,0,0,0,0,0,0,0,0,0,0,0,4,1,1,1,1,0,0,0,0,0,0
0,0,0,0,0,0,0,0,0,0,0,2,2,2,2,4,4,4,4,4,0,0,0,0,0,8,7,0,0,0,0,0,0,0,0,0,0,0,0,0,0,0,0,4,1,1,1,1,0,0,0,0,0,0
0,0,0,0,0,0,0,0,0,0,0,0,0,0,0,2,2,2,2,4,0,0,0,0,0,8,7,0,0,0,0,0,0,0,0,0,0,0,0,0,0,0,0,4,1,1,1,1,0,0,0,0,0,0
0,0,0,0,0,0,0,0,0,0,0,0,0,0,0,2,2,2,2,4,0,0,0,0,0,8,7,0,0,0,0,0,0,0,0,0,0,0,0,0,0,0,0,4,1,1,1,1,0,0,0,0,0,0
0,0,0,0,0,0,0,0,0,0,0,0,0,0,0,2,2,2,2,4,0,0,0,0,0,8,7,0,0,0,0,0,0,0,0,0,0,0,0,0,0,0,0,4,1,1,1,1,0,0,0,0,0,0
0,0,0,0,0,0,0,0,0,0,0,0,0,0,0,2,2,2,2,4,0,0,0,0,0,8,7,0,0,0,0,0,0,0,0,0,0,0,0,0,0,0,0,4,1,1,1,1,0,0,0,0,0,0
0,0,0,0,0,0,0,0,0,0,0,0,0,0,0,1,1,1,1,4,0,0,0,0,0,8,7,0,0,0,0,0,0,0,0,0,0,0,0,0,0,0,0,4,1,1,1,1,0,0,0,0,0,0
0,0,0,0,0,0,0,0,0,0,0,0,0,0,0,1,1,1,1,4,0,0,0,0,0,8,7,0,0,0,0,0,0,0,0,0,0,0,0,0,0,0,0,4,1,1,1,1,0,0,0,0,0,0
0,0,0,0,0,0,0,0,0,0,0,0,0,0,0,1,1,1,1,4,0,0,0,0,0,0,8,7,7,7,7,7,0,0,0,0,0,0,0,0,0,0,0,4,1,1,1,1,0,0,0,0,0,0
0,0,0,0,0,0,0,0,0,0,0,0,0,0,0,1,1,1,1,4,4,4,4,4,4,4,4,6,6,6,6,6,0,0,0,0,0,0,0,0,0,0,0,4,1,1,1,1,0,0,0,0,0,0
0,0,0,0,0,0,0,0,0,0,0,0,0,0,0,0,0,0,0,1,1,1,1,1,1,1,4,6,0,0,0,6,0,0,0,0,0,0,0,0,0,0,0,4,1,1,1,1,0,0,0,0,0,0
0,0,0,0,0,0,0,0,0,0,0,0,0,0,0,0,0,0,0,1,1,1,1,1,1,1,4,6,0,0,0,6,0,0,0,0,0,0,0,0,0,0,0,4,1,1,1,1,0,0,0,0,0,0
0,0,0,0,0,0,0,0,0,0,0,0,0,0,0,0,0,0,0,1,1,1,1,1,1,1,4,6,0,0,0,6,0,0,0,0,0,0,0,0,0,0,0,4,1,1,1,1,0,0,0,0,0,0
0,0,0,0,0,0,0,0,0,0,0,0,0,0,0,0,0,0,0,1,1,1,1,1,1,1,4,6,6,6,6,6,0,0,0,0,0,0,0,0,0,0,0,4,1,1,1,1,0,0,0,0,0,0
0,0,0,0,0,0,0,0,0,0,0,0,0,0,0,0,0,0,0,1,1,1,1,1,1,1,1,4,4,4,4,4,4,4,4,4,4,4,4,4,4,4,4,1,1,1,1,1,0,0,0,0,0,0
0,0,0,0,0,0,0,0,0,0,0,0,0,0,0,0,0,0,0,1,1,1,1,1,1,1,1,2,2,2,2,2,2,2,2,2,2,2,2,2,2,2,2,1,1,1,1,1,0,0,0,0,0,0
0,0,0,0,0,0,0,0,0,0,0,0,0,0,0,0,0,0,0,1,1,1,1,1,1,1,1,2,2,2,2,2,2,2,2,2,2,2,2,2,2,2,2,1,1,1,1,1,0,0,0,0,0,0
0,0,0,0,0,0,0,0,0,0,0,0,0,0,0,0,0,0,0,1,1,1,1,1,1,1,1,2,2,2,2,2,2,2,2,2,2,2,2,2,2,2,2,1,1,1,1,1,0,0,0,0,0,0
endlayer

layer
0,0,0,0,0,0,0,0,0,0,0,0,0,0,0,0,0,0,0,1,1,1,1,1,1,1,1,2,2,2,2,2,2,2,2,2,2,2,2,2,2,2,2,1,1,1,1,1,0,0,0,0,0,0
0,0,0,0,0,0,0,0,0,0,0,0,0,0,0,0,0,0,0,1,1,1,1,1,1,1,1,2,2,2,2,2,2,2,2,2,2,2,2,2,2,2,2,1,1,1,1,1,0,0,0,0,0,0
0,0,0,0,0,0,0,0,0,0,0,0,0,0,0,0,0,0,0,1,1,1,1,1,1,1,1,2,2,2,2,2,2,2,2,2,2,2,2,2,2,2,2,1,1,1,1,1,0,0,0,0,0,0
0,0,0,0,0,0,0,0,0,0,0,0,0,0,0,0,0,0,0,1,1,1,1,1,1,1,1,4,4,4,4,4,4,4,4,4,4,4,4,4,4,4,4,1,1,1,1,1,0,0,0,0,0,0
0,0,0,0,0,0,0,0,0,0,0,0,0,0,0,1,1,1,1,4,4,4,4,4,4,4,4,6,6,6,6,6,0,0,0,0,0,0,0,0,0,0,0,4,1,1,1,1,0,0,0,0,0,0
0,0,0,0,0,0,0,0,0,0,0,0,0,0,0,1,1,1,1,4,4,4,4,4,4,4,4,6,0,0,0,6,0,0,0,0,0,0,0,0,0,0,0,4,1,1,1,1,0,0,0,0,0,0
0,0,0,0,0,0,0,0,0,0,0,0,0,0,0,1,1,1,1,4,4,4,4,4,4,4,4,6,0,0,0,6,0,0,0,0,0,0,0,0,0,0,0,4,1,1,1,1,0,0,0,0,0,0
0,0,0,0,0,0,0,0,0,0,0,0,0,0,0,1,1,1,1,4,4,4,4,4,4,4,4,6,0,0,0,6,0,0,0,0,0,0,0,0,0,0,0,4,1,1,1,1,0,0,0,0,0,0
0,0,0,0,0,0,0,0,0,0,0,1,1,1,1,4,4,4,4,4,4,4,4,4,4,4,4,6,6,6,6,6,0,0,0,0,0,0,0,0,0,0,0,4,1,1,1,1,0,0,0,0,0,0
0,0,0,0,0,0,0,0,0,0,0,1,1,1,1,4,4,4,4,4,0,0,0,0,0,0,8,7,7,7,7,7,0,0,0,0,0,0,0,0,0,0,0,4,1,1,1,1,0,0,0,0,0,0
0,0,0,0,0,0,0,0,0,0,0,1,1,1,1,4,4,4,4,4,0,0,0,0,0,8,7,0,0,0,0,0,0,0,0,0,0,0,0,0,0,0,0,4,1,1,1,1,0,0,0,0,0,0
0,0,0,0,0,0,0,0,0,0,0,1,1,1,1,4,4,4,4,4,0,0,0,0,0,8,7,0,0,0,0,0,0,0,0,0,0,0,0,0,0,0,0,4,1,1,1,1,0,0,0,0,0,0
0,0,0,0,0,0,0,0,0,0,0,2,2,2,2,4,4,4,4,4,0,0,0,0,0,0,8,7,7,7,7,7,0,0,0,0,0,0,0,0,0,0,0,4,1,1,1,1,0,0,0,0,0,0
0,0,0,0,0,0,0,0,0,0,0,2,2,2,2,4,4,4,4,4,0,0,0,0,0,0,8,7,7,7,7,7,0,0,0,0,0,0,0,0,0,0,0,4,1,1,1,1,0,0,0,0,0,0
0,0,0,0,0,0,0,0,0,0,0,2,2,2,2,4,4,4,4,4,0,0,0,0,0,0,8,7,7,7,7,7,0,0,0,0,0,0,0,0,0,0,0,4,1,1,1,1,0,0,0,0,0,0
0,0,0,0,0,0,0,0,0,0,0,2,2,2,2,4,4,4,4,4,0,0,0,0,0,0,8,7,7,7,7,7,0,0,0,0,0,0,0,0,0,0,0,4,1,1,1,1,0,0,0,0,0,0
0,0,0,0,0,0,0,0,0,0,0,2,2,2,2,4,4,4,4,4,0,0,0,0,0,0,8,7,7,7,7,7,0,0,0,0,0,0,0,0,0,0,0,4,1,1,1,1,0,0,0,0,0,0
0,0,0,0,0,0,0,0,0,0,0,2,2,2,2,4,0,0,0,0,0,0,0,0,0,0,8,7,7,7,7,7,0,0,0,0,0,0,0,0,0,0,0,4,1,1,1,1,0,0,0,0,0,0
0,0,0,0,0,0,0,0,0,0,0,2,2,2,2,4,0,0,0,0,0,0,0,0,0,0,8,7,7,7,7,7,0,0,0,0,0,0,0,0,0,0,0,4,1,1,1,1,0,0,0,0,0,0
0,0,0,0,0,0,0,0,0,0,0,2,2,2,2,4,0,0,0,0,0,0,0,0,0,0,8,7,7,7,7,7,0,0,0,0,0,0,0,0,0,0,0,4,1,1,1,1,0,0,0,0,0,0
0,0,0,0,0,0,0,0,0,0,0,2,2,2,2,4,0,0,0,0,0,0,0,0,0,0,8,7,7,7,7,7,0,0,0,0,0,0,0,0,0,0,0,4,1,1,1,1,0,0,0,0,0,0
0,0,0,0,0,0,0,0,0,0,0,2,2,2,2,4,0,0,0,0,0,0,0,0,0,0,8,7,7,7,7,7,0,0,0,0,0,0,0,0,0,0,0,4,1,1,1,1,0,0,0,0,0,0
0,0,0,0,0,0,0,0,0,0,0,2,2,2,2,4,0,0,0,0,0,0,0,0,0,0,8,7,7,7,7,7,0,0,0,0,0,0,0,0,0,0,0,4,1,1,1,1,0,0,0,0,0,0
0,0,0,0,0,0,0,0,0,0,0,2,2,2,2,4,0,0,0,0,0,0,0,0,0,0,8,7,7,7,7,7,0,0,0,0,0,0,0,0,0,0,0,4,1,1,1,1,0,0,0,0,0,0
0,0,0,0,0,0,0,0,0,0,0,2,2,2,2,4,0,0,0,0,0,0,0,0,0,0,8,7,7,7,7,7,0,0,0,0,0,0,0,0,0,0,0,4,1,1,1,1,0,0,0,0,0,0
0,0,0,0,0,0,0,0,0,0,0,2,2,2,2,4,0,0,0,0,0,0,0,0,0,0,8,7,7,7,7,7,0,0,0,0,0,0,0,0,0,0,0,4,1,1,1,1,0,0,0,0,0,0
0,0,0,0,0,0,0,0,0,0,0,2,2,2,2,4,0,0,0,0,0,0,0,0,0,0,8,7,7,7,7,7,0,0,0,0,0,0,0,0,0,0,0,4,1,1,1,1,0,0,0,0,0,0
0,0,0,0,0,0,0,0,0,0,0,2,2,2,2,4,4,4,4,4,0,0,0,0,0,0,8,7,7,7,7,7,0,0,0,0,0,0,0,0,0,0,0,4,1,1,1,1,0,0,0,0,0,0
0,0,0,0,0,0,0,0,0,0,0,2,2,2,2,4,4,4,4,4,0,0,0,0,0,0,8,7,7,7,7,7,0,0,0,0,0,0,0,0,0,0,0,4,1,1,1,1,0,0,0,0,0,0
0,0,0,0,0,0,0,0,0,0,0,2,2,2,2,4,4,4,4,4,0,0,0,0,0,0,8,7,7,7,7,7,0,0,0,0,0,0,0,0,0,0,0,4,1,1,1,1,0,0,0,0,0,0
0,0,0,0,0,0,0,0,0,0,0,2,2,2,2,4,4,4,4,4,0,0,0,0,0,0,8,7,7,7,7,7,0,0,0,0,0,0,0,0,0,0,0,4,1,1,1,1,0,0,0,0,0,0
0,0,0,0,0,0,0,0,0,0,0,2,2,2,2,4,4,4,4,4,0,0,0,0,0,0,8,7,7,7,7,7,0,0,0,0,0,0,0,0,0,0,0,4,1,1,1,1,0,0,0,0,0,0
0,0,0,0,0,0,0,0,0,0,0,1,1,1,1,4,4,4,4,4,0,0,0,0,0,0,8,7,7,7,7,7,0,0,0,0,0,0,0,0,0,0,0,4,1,1,1,1,0,0,0,0,0,0
0,0,0,0,0,0,0,0,0,0,0,1,1,1,1,4,4,4,4,4,0,0,0,0,0,0,8,7,7,7,7,7,0,0,0,0,0,0,0,0,0,0,0,4,1,1,1,1,0,0,0,0,0,0
0,0,0,0,0,0,0,0,0,0,0,1,1,1,1,4,4,4,4,4,0,0,0,0,0,0,8,7,7,7,7,7,0,0,0,0,0,0,0,0,0,0,0,4,1,1,1,1,0,0,0,0,0,0
0,0,0,0,0,0,0,0,0,0,0,1,1,1,1,4,4,4,4,4,4,4,4,4,4,4,4,6,6,6,6,6,0,0,0,0,0,0,0,0,0,0,0,4,1,1,1,1,0,0,0,0,0,0
0,0,0,0,0,0,0,0,0,0,0,0,0,0,0,1,1,1,1,4,4,4,4,4,4,4,4,6,0,0,0,6,0,0,0,0,0,0,0,0,0,0,0,4,1,1,1,1,0,0,0,0,0,0
0,0,0,0,0,0,0,0,0,0,0,0,0,0,0,1,1,1,1,4,4,4,4,4,4,4,4,6,0,0,0,6,0,0,0,0,0,0,0,0,0,0,0,4,1,1,1,1,0,0,0,0,0,0
0,0,0,0,0,0,0,0,0,0,0,0,0,0,0,1,1,1,1,4,4,4,4,4,4,4,4,6,0,0,0,6,0,0,0,0,0,0,0,0,0,0,0,4,1,1,1,1,0,0,0,0,0,0
0,0,0,0,0,0,0,0,0,0,0,0,0,0,0,1,1,1,1,4,4,4,4,4,4,4,4,6,6,6,6,6,0,0,0,0,0,0,0,0,0,0,0,4,1,1,1,1,0,0,0,0,0,0
0,0,0,0,0,0,0,0,0,0,0,0,0,0,0,0,0,0,0,1,1,1,1,1,1,1,1,4,4,4,4,4,4,4,4,4,4,4,4,4,4,4,4,1,1,1,1,1,0,0,0,0,0,0
0,0,0,0,0,0,0,0,0,0,0,0,0,0,0,0,0,0,0,1,1,1,1,1,1,1,1,2,2,2,2,2,2,2,2,2,2,2,2,2,2,2,2,1,1,1,1,1,0,0,0,0,0,0
0,0,0,0,0,0,0,0,0,0,0,0,0,0,0,0,0,0,0,1,1,1,1,1,1,1,1,2,2,2,2,2,2,2,2,2,2,2,2,2,2,2,2,1,1,1,1,1,0,0,0,0,0,0
0,0,0,0,0,0,0,0,0,0,0,0,0,0,0,0,0,0,0,1,1,1,1,1,1,1,1,2,2,2,2,2,2,2,2,2,2,2,2,2,2,2,2,1,1,1,1,1,0,0,0,0,0,0
endlayer

layer
0,0,0,0,0,0,0,0,0,0,0,0,0,0,0,0,0,0,0,1,1,1,1,1,1,1,1,2,2,2,2,2,2,2,2,2,2,2,2,2,2,2,2,1,1,1,1,1,0,0,0,0,0,0
0,0,0,0,0,0,0,0,0,0,0,0,0,0,0,0,0,0,0,1,1,1,1,1,1,1,1,2,2,2,2,2,2,2,2,2,2,2,2,2,2,2,2,1,1,1,1,1,0,0,0,0,0,0
0,0,0,0,0,0,0,0,0,0,0,0,0,0,0,0,0,0,0,1,1,1,1,1,1,1,1,2,2,2,2,2,2,2,2,2,2,2,2,2,2,2,2,1,1,1,1,1,0,0,0,0,0,0
0,0,0,0,0,0,0,0,0,0,0,0,0,0,0,0,0,0,0,1,1,1,1,1,1,1,1,4,4,4,4,4,4,4,4,4,4,4,4,4,4,4,4,1,1,1,1,1,0,0,0,0,0,0
0,0,0,0,0,0,0,0,0,0,0,0,0,0,0,1,1,1,1,4,4,4,4,4,4,4,4,6,6,6,6,6,0,0,0,0,0,0,0,0,0,0,0,4,1,1,1,1,0,0,0,0,0,0
0,0,0,0,0,0,0,0,0,0,0,0,0,0,0,1,1,1,1,4,0,0,0,0,0,0,6,6,0,0,0,6,0,0,0,0,0,0,0,0,0,0,0,4,1,1,1,1,0,0,0,0,0,0
0,0,0,0,0,0,0,0,0,0,0,0,0,0,0,1,1,1,1,4,0,0,0,0,0,6,6,6,0,0,0,6,0,0,0,0,0,0,0,0,0,0,0,4,1,1,1,1,0,0,0,0,0,0
0,0,0,0,0,0,0,0,0,0,0,0,0,0,0,1,1,1,1,4,0,0,0,0,0,0,6,6,0,0,0,6,0,0,0,0,0,0,0,0,0,0,0,4,1,1,1,1,0,0,0,0,0,0
0,0,0,0,0,0,0,0,0,0,0,1,1,1,1,4,4,4,4,4,0,0,0,0,0,0,0,6,6,6,6,6,0,0,0,0,0,0,0,0,0,0,0,4,1,1,1,1,0,0,0,0,0,0
0,0,0,0,0,0,0,0,0,0,0,1,1,1,1,4,0,0,0,0,0,0,0,0,0,0,8,7,7,7,7,7,0,0,0,0,0,0,0,0,0,0,0,4,1,1,1,1,0,0,0,0,0,0
0,0,0,0,0,0,0,0,0,0,0,1,1,1,1,4,0,0,0,0,0,0,0,0,0,8,7,0,0,0,0,0,0,0,0,0,0,0,0,0,0,0,0,4,1,1,1,1,0,0,0,0,0,0
0,0,0,0,0,0,0,0,0,0,0,1,1,1,1,4,0,0,0,0,0,0,0,0,0,8,7,0,0,0,0,0,0,0,0,0,0,0,0,0,0,0,0,4,1,1,1,1,0,0,0,0,0,0
0,0,0,0,0,0,0,0,0,0,0,2,2,2,2,4,0,0,0,0,0,0,0,0,0,8,7,0,0,0,0,0,0,0,0,0,0,0,0,0,0,0,0,4,1,1,1,1,0,0,0,0,0,0
0,0,0,0,0,0,0,0,0,0,0,2,2,2,2,4,0,0,0,0,0,0,0,0,0,8,7,0,0,0,0,0,0,0,0,0,0,0,0,0,0,0,0,4,1,1,1,1,0,0,0,0,0,0
0,0,0,0,0,0,0,0,0,0,0,2,2,2,2,4,0,0,0,0,0,0,0,0,0,8,7,0,0,0,0,0,0,0,0,0,0,0,0,0,0,0,0,4,1,1,1,1,0,0,0,0,0,0
0,0,0,0,0,0,0,0,0,0,0,2,2,2,2,4,0,0,0,0,0,0,0,0,0,8,7,0,0,0,0,0,0,0,0,0,0,0,0,0,0,0,0,4,1,1,1,1,0,0,0,0,0,0
0,0,0,0,0,0,0,0,0,0,0,2,2,2,2,4,0,0,0,0,0,0,0,0,0,8,7,0,0,0,0,0,0,0,0,0,0,0,0,0,0,0,0,4,1,1,1,1,0,0,0,0,0,0
0,0,0,0,0,0,0,0,0,0,0,2,2,2,2,4,0,0,0,0,0,0,0,0,0,8,7,0,0,0,0,0,0,0,0,0,0,0,0,0,0,0,0,4,1,1,1,1,0,0,0,0,0,0
0,0,0,0,0,0,0,0,0,0,0,2,2,2,2,4,0,0,0,0,0,0,0,0,0,8,7,0,0,0,0,0,0,0,0,0,0,0,0,0,0,0,0,4,1,1,1,1,0,0,0,0,0,0
0,0,0,0,0,0,0,0,0,0,0,2,2,2,2,4,0,0,0,0,0,0,0,0,0,8,7,0,0,0,0,0,0,0,0,0,0,0,0,0,0,0,0,4,1,1,1,1,0,0,0,0,0,0
0,0,0,0,0,0,0,0,0,0,0,2,2,2,2,4,0,0,0,0,0,0,0,0,0,8,7,0,0,0,0,0,0,0,0,0,0,0,0,0,0,0,0,4,1,1,1,1,0,0,0,0,0,0
0,0,0,0,0,0,0,0,0,0,0,2,2,2,2,4,0,0,0,0,0,0,0,0,0,8,7,0,0,0,0,0,0,0,0,0,0,0,0,0,0,0,0,4,1,1,1,1,0,0,0,0,0,0
0,0,0,0,0,0,0,0,0,0,0,2,2,2,2,4,0,0,0,0,0,0,0,0,0,8,7,0,0,0,0,0,0,0,0,0,0,0,0,0,0,0,0,4,1,1,1,1,0,0,0,0,0,0
0,0,0,0,0,0,0,0,0,0,0,2,2,2,2,4,0,0,0,0,0,0,0,0,0,8,7,0,0,0,0,0,0,0,0,0,0,0,0,0,0,0,0,4,1,1,1,1,0,0,0,0,0,0
0,0,0,0,0,0,0,0,0,0,0,2,2,2,2,4,0,0,0,0,0,0,0,0,0,8,7,0,0,0,0,0,0,0,0,0,0,0,0,0,0,0,0,4,1,1,1,1,0,0,0,0,0,0
0,0,0,0,0,0,0,0,0,0,0,2,2,2,2,4,0,0,0,0,0,0,0,0,0,8,7,0,0,0,0,0,0,0,0,0,0,0,0,0,0,0,0,4,1,1,1,1,0,0,0,0,0,0
0,0,0,0,0,0,0,0,0,0,0,2,2,2,2,4,0,0,0,0,0,0,0,0,0,8,7,0,0,0,0,0,0,0,0,0,0,0,0,0,0,0,0,4,1,1,1,1,0,0,0,0,0,0
0,0,0,0,0,0,0,0,0,0,0,2,2,2,2,4,0,0,0,0,0,0,0,0,0,8,7,0,0,0,0,0,0,0,0,0,0,0,0,0,0,0,0,4,1,1,1,1,0,0,0,0,0,0
0,0,0,0,0,0,0,0,0,0,0,2,2,2,2,4,0,0,0,0,0,0,0,0,0,8,7,0,0,0,0,0,0,0,0,0,0,0,0,0,0,0,0,4,1,1,1,1,0,0,0,0,0,0
0,0,0,0,0,0,0,0,0,0,0,2,2,2,2,4,0,0,0,0,0,0,0,0,0,8,7,0,0,0,0,0,0,0,0,0,0,0,0,0,0,0,0,4,1,1,1,1,0,0,0,0,0,0
0,0,0,0,0,0,0,0,0,0,0,2,2,2,2,4,0,0,0,0,0,0,0,0,0,8,7,0,0,0,0,0,0,0,0,0,0,0,0,0,0,0,0,4,1,1,1,1,0,0,0,0,0,0
0,0,0,0,0,0,0,0,0,0,0,2,2,2,2,4,0,0,0,0,0,0,0,0,0,8,7,0,0,0,0,0,0,0,0,0,0,0,0,0,0,0,0,4,1,1,1,1,0,0,0,0,0,0
0,0,0,0,0,0,0,0,0,0,0,1,1,1,1,4,0,0,0,0,0,0,0,0,0,8,7,0,0,0,0,0,0,0,0,0,0,0,0,0,0,0,0,4,1,1,1,1,0,0,0,0,0,0
0,0,0,0,0,0,0,0,0,0,0,1,1,1,1,4,0,0,0,0,0,0,0,0,0,8,7,0,0,0,0,0,0,0,0,0,0,0,0,0,0,0,0,4,1,1,1,1,0,0,0,0,0,0
0,0,0,0,0,0,0,0,0,0,0,1,1,1,1,4,0,0,0,0,0,0,0,0,0,0,8,7,7,7,7,7,0,0,0,0,0,0,0,0,0,0,0,4,1,1,1,1,0,0,0,0,0,0
0,0,0,0,0,0,0,0,0,0,0,1,1,1,1,4,4,4,4,4,0,0,0,0,0,0,0,6,6,6,6,6,0,0,0,0,0,0,0,0,0,0,0,4,1,1,1,1,0,0,0,0,0,0
0,0,0,0,0,0,0,0,0,0,0,0,0,0,0,1,1,1,1,4,0,0,0,0,0,0,6,6,0,0,0,6,0,0,0,0,0,0,0,0,0,0,0,4,1,1,1,1,0,0,0,0,0,0
0,0,0,0,0,0,0,0,0,0,0,0,0,0,0,1,1,1,1,4,0,0,0,0,0,6,6,6,0,0,0,6,0,0,0,0,0,0,0,0,0,0,0,4,1,1,1,1,0,0,0,0,0,0
0,0,0,0,0,0,0,0,0,0,0,0,0,0,0,1,1,1,1,4,0,0,0,0,0,6,6,6,0,0,0,6,0,0,0,0,0,0,0,0,0,0,0,4,1,1,1,1,0,0,0,0,0,0
0,0,0,0,0,0,0,0,0,0,0,0,0,0,0,1,1,1,1,4,4,4,4,4,4,4,4,6,6,6,6,6,0,0,0,0,0,0,0,0,0,0,0,4,1,1,1,1,0,0,0,0,0,0
0,0,0,0,0,0,0,0,0,0,0,0,0,0,0,0,0,0,0,1,1,1,1,1,1,1,1,4,4,4,4,4,4,4,4,4,4,4,4,4,4,4,4,1,1,1,1,1,0,0,0,0,0,0
0,0,0,0,0,0,0,0,0,0,0,0,0,0,0,0,0,0,0,1,1,1,1,1,1,1,1,2,2,2,2,2,2,2,2,2,2,2,2,2,2,2,2,1,1,1,1,1,0,0,0,0,0,0
0,0,0,0,0,0,0,0,0,0,0,0,0,0,0,0,0,0,0,1,1,1,1,1,1,1,1,2,2,2,2,2,2,2,2,2,2,2,2,2,2,2,2,1,1,1,1,1,0,0,0,0,0,0
0,0,0,0,0,0,0,0,0,0,0,0,0,0,0,0,0,0,0,1,1,1,1,1,1,1,1,2,2,2,2,2,2,2,2,2,2,2,2,2,2,2,2,1,1,1,1,1,0,0,0,0,0,0
endlayer

layer
0,0,0,0,0,0,0,0,0,0,0,0,0,0,0,0,0,0,0,1,1,1,1,1,1,1,1,2,2,2,2,2,2,2,2,2,2,2,2,2,2,2,2,1,1,1,1,1,0,0,0,0,0,0
0,0,0,0,0,0,0,0,0,0,0,0,0,0,0,0,0,0,0,1,1,1,1,1,1,1,1,2,2,2,2,2,2,2,2,2,2,2,2,2,2,2,2,1,1,1,1,1,0,0,0,0,0,0
0,0,0,0,0,0,0,0,0,0,0,0,0,0,0,0,0,0,0,1,1,1,1,1,1,1,1,2,2,2,2,2,2,2,2,2,2,2,2,2,2,2,2,1,1,1,1,1,0,0,0,0,0,0
0,0,0,0,0,0,0,0,0,0,0,0,0,0,0,0,0,0,0,1,1,1,1,1,1,1,1,4,4,4,4,4,4,4,4,4,4,4,4,4,4,4,4,1,1,1,1,1,0,0,0,0,0,0
0,0,0,0,0,0,0,0,0,0,0,0,0,0,0,1,1,1,1,4,4,4,4,4,4,4,4,6,6,6,6,6,0,0,0,0,0,0,0,0,0,0,0,4,1,1,1,1,0,0,0,0,0,0
0,0,0,0,0,0,0,0,0,0,0,0,0,0,0,1,1,1,1,4,0,0,0,0,0,0,6,6,0,0,0,6,0,0,0,0,0,0,0,0,0,0,0,4,1,1,1,1,0,0,0,0,0,0
0,0,0,0,0,0,0,0,0,0,0,0,0,0,0,1,1,1,1,4,0,0,0,0,0,6,6,6,0,0,0,6,0,0,0,0,0,0,0,0,0,0,0,4,1,1,1,1,0,0,0,0,0,0
0,0,0,0,0,0,0,0,0,0,0,0,0,0,0,1,1,1,1,4,0,0,0,0,0,0,6,6,0,0,0,6,0,0,0,0,0,0,0,0,0,0,0,4,1,1,1,1,0,0,0,0,0,0
0,0,0,0,0,0,0,0,0,0,0,1,1,1,1,4,4,4,4,4,0,0,0,0,0,0,0,6,6,6,6,6,0,0,0,0,0,0,0,0,0,0,0,4,1,1,1,1,0,0,0,0,0,0
0,0,0,0,0,0,0,0,0,0,0,1,1,1,1,4,0,0,0,0,0,0,0,0,0,0,8,7,7,7,7,7,0,0,0,0,0,0,0,0,0,0,0,4,1,1,1,1,0,0,0,0,0,0
0,0,0,0,0,0,0,0,0,0,0,1,1,1,1,4,0,0,0,0,0,0,0,0,0,8,7,0,0,0,0,0,0,0,0,0,0,0,0,0,0,0,0,4,1,1,1,1,0,0,0,0,0,0
0,0,0,0,0,0,0,0,0,0,0,1,1,1,1,4,0,0,0,0,0,0,0,0,0,8,7,0,0,0,0,0,0,0,0,0,0,0,0,0,0,0,0,4,1,1,1,1,0,0,0,0,0,0
0,0,0,0,0,0,0,0,0,0,0,2,2,2,2,4,0,0,0,0,0,0,0,0,0,8,7,0,0,0,0,0,0,0,0,0,0,0,0,0,0,0,0,4,1,1,1,1,0,0,0,0,0,0
0,0,0,0,0,0,0,0,0,0,0,2,2,2,2,4,0,0,0,0,0,0,0,0,0,8,7,0,0,0,0,0,0,0,0,0,0,0,0,0,0,0,0,4,1,1,1,1,0,0,0,0,0,0
0,0,0,0,0,0,0,0,0,0,0,2,2,2,2,4,0,0,0,0,0,0,0,0,0,8,7,0,0,0,0,0,0,0,0,0,0,0,0,0,0,0,0,4,1,1,1,1,0,0,0,0,0,0
0,0,0,0,0,0,0,0,0,0,0,2,2,2,2,4,0,0,0,0,0,0,0,0,0,8,7,0,0,0,0,0,0,0,0,0,0,0,0,0,0,0,0,4,1,1,1,1,0,0,0,0,0,0
0,0,0,0,0,0,0,0,0,0,0,2,2,2,2,4,0,0,0,0,0,0,0,0,0,8,7,0,0,0,0,0,0,0,0,0,0,0,0,0,0,0,0,4,1,1,1,1,0,0,0,0,0,0
0,0,0,0,0,0,0,0,0,0,0,2,2,2,2,4,0,0,0,0,0,0,0,0,0,8,7,0,0,0,0,0,0,0,0,0,0,0,0,0,0,0,0,4,1,1,1,1,0,0,0,0,0,0
0,0,0,0,0,0,0,0,0,0,0,2,2,2,2,4,0,0,0,0,0,0,0,0,0,8,7,0,0,0,0,0,0,0,0,0,0,0,0,0,0,0,0,4,1,1,1,1,0,0,0,0,0,0
0,0,0,0,0,0,0,0,0,0,0,2,2,2,2,4,0,0,0,0,0,0,0,0,0,8,7,0,0,0,0,0,0,0,0,0,0,0,0,0,0,0,0,4,1,1,1,1,0,0,0,0,0,0
0,0,0,0,0,0,0,0,0,0,0,2,2,2,2,4,0,0,0,0,0,0,0,0,0,8,7,0,0,0,0,0,0,0,0,0,0,0,0,0,0,0,0,4,1,1,1,1,0,0,0,0,0,0
0,0,0,0,0,0,0,0,0,0,0,2,2,2,2,4,0,0,0,0,0,0,0,0,0,8,7,0,0,0,0,0,0,0,0,0,0,0,0,0,0,0,0,4,1,1,1,1,0,0,0,0,0,0
0,0,0,0,0,0,0,0,0,0,0,2,2,2,2,4,0,0,0,0,0,0,0,0,0,8,7,0,0,0,0,0,0,0,0,0,0,0,0,0,0,0,0,4,1,1,1,1,0,0,0,0,0,0
0,0,0,0,0,0,0,0,0,0,0,2,2,2,2,4,0,0,0,0,0,0,0,0,0,8,7,0,0,0,0,0,0,0,0,0,0,0,0,0,0,0,0,4,1,1,1,1,0,0,0,0,0,0
0,0,0,0,0,0,0,0,0,0,0,2,2,2,2,4,0,0,0,0,0,0,0,0,0,8,7,0,0,0,0,0,0,0,0,0,0,0,0,0,0,0,0,4,1,1,1,1,0,0,0,0,0,0
0,0,0,0,0,0,0,0,0,0,0,2,2,2,2,4,0,0,0,0,0,0,0,0,0,8,7,0,0,0,0,0,0,0,0,0,0,0,0,0,0,0,0,4,1,1,1,1,0,0,0,0,0,0
0,0,0,0,0,0,0,0,0,0,0,2,2,2,2,4,0,0,0,0,0,0,0,0,0,8,7,0,0,0,0,0,0,0,0,0,0,0,0,0,0,0,0,4,1,1,1,1,0,0,0,0,0,0
0,0,0,0,0,0,0,0,0,0,0,2,2,2,2,4,0,0,0,0,0,0,0,0,0,8,7,0,0,0,0,0,0,0,0,0,0,0,0,0,0,0,0,4,1,1,1,1,0,0,0,0,0,0
0,0,0,0,0,0,0,0,0,0,0,2,2,2,2,4,0,0,0,0,0,0,0,0,0,8,7,0,0,0,0,0,0,0,0,0,0,0,0,0,0,0,0,4,1,1,1,1,0,0,0,0,0,0
0,0,0,0,0,0,0,0,0,0,0,2,2,2,2,4,0,0,0,0,0,0,0,0,0,8,7,0,0,0,0,0,0,0,0,0,0,0,0,0,0,0,0,4,1,1,1,1,0,0,0,0,0,0
0,0,0,0,0,0,0,0,0,0,0,2,2,2,2,4,0,0,0,0,0,0,0,0,0,8,7,0,0,0,0,0,0,0,0,0,0,0,0,0,0,0,0,4,1,1,1,1,0,0,0,0,0,0
0,0,0,0,0,0,0,0,0,0,0,2,2,2,2,4,0,0,0,0,0,0,0,0,0,8,7,0,0,0,0,0,0,0,0,0,0,0,0,0,0,0,0,4,1,1,1,1,0,0,0,0,0,0
0,0,0,0,0,0,0,0,0,0,0,1,1,1,1,4,0,0,0,0,0,0,0,0,0,8,7,0,0,0,0,0,0,0,0,0,0,0,0,0,0,0,0,4,1,1,1,1,0,0,0,0,0,0
0,0,0,0,0,0,0,0,0,0,0,1,1,1,1,4,0,0,0,0,0,0,0,0,0,8,7,0,0,0,0,0,0,0,0,0,0,0,0,0,0,0,0,4,1,1,1,1,0,0,0,0,0,0
0,0,0,0,0,0,0,0,0,0,0,1,1,1,1,4,0,0,0,0,0,0,0,0,0,0,8,7,7,7,7,7,0,0,0,0,0,0,0,0,0,0,0,4,1,1,1,1,0,0,0,0,0,0
0,0,0,0,0,0,0,0,0,0,0,1,1,1,1,4,4,4,4,4,0,0,0,0,0,0,0,6,6,6,6,6,0,0,0,0,0,0,0,0,0,0,0,4,1,1,1,1,0,0,0,0,0,0
0,0,0,0,0,0,0,0,0,0,0,0,0,0,0,1,1,1,1,4,0,0,0,0,0,0,6,6,0,0,0,6,0,0,0,0,0,0,0,0,0,0,0,4,1,1,1,1,0,0,0,0,0,0
0,0,0,0,0,0,0,0,0,0,0,0,0,0,0,1,1,1,1,4,0,0,0,0,0,6,6,6,0,0,0,6,0,0,0,0,0,0,0,0,0,0,0,4,1,1,1,1,0,0,0,0,0,0
0,0,0,0,0,0,0,0,0,0,0,0,0,0,0,1,1,1,1,4,0,0,0,0,0,6,6,6,0,0,0,6,0,0,0,0,0,0,0,0,0,0,0,4,1,1,1,1,0,0,0,0,0,0
0,0,0,0,0,0,0,0,0,0,0,0,0,0,0,1,1,1,1,4,4,4,4,4,4,4,4,6,6,6,6,6,0,0,0,0,0,0,0,0,0,0,0,4,1,1,1,1,0,0,0,0,0,0
0,0,0,0,0,0,0,0,0,0,0,0,0,0,0,0,0,0,0,1,1,1,1,1,1,1,1,4,4,4,4,4,4,4,4,4,4,4,4,4,4,4,4,1,1,1,1,1,0,0,0,0,0,0
0,0,0,0,0,0,0,0,0,0,0,0,0,0,0,0,0,0,0,1,1,1,1,1,1,1,1,2,2,2,2,2,2,2,2,2,2,2,2,2,2,2,2,1,1,1,1,1,0,0,0,0,0,0
0,0,0,0,0,0,0,0,0,0,0,0,0,0,0,0,0,0,0,1,1,1,1,1,1,1,1,2,2,2,2,2,2,2,2,2,2,2,2,2,2,2,2,1,1,1,1,1,0,0,0,0,0,0
0,0,0,0,0,0,0,0,0,0,0,0,0,0,0,0,0,0,0,1,1,1,1,1,1,1,1,2,2,2,2,2,2,2,2,2,2,2,2,2,2,2,2,1,1,1,1,1,0,0,0,0,0,0
endlayer

layer
0,0,0,0,0,0,0,0,0,0,0,0,0,0,0,0,0,0,0,1,1,1,1,1,1,1,1,2,2,2,2,2,2,2,2,2,2,2,2,2,2,2,2,1,1,1,1,1,0,0,0,0,0,0
0,0,0,0,0,0,0,0,0,0,0,0,0,0,0,0,0,0,0,1,1,1,1,1,1,1,1,2,2,2,2,2,2,2,2,2,2,2,2,2,2,2,2,1,1,1,1,1,0,0,0,0,0,0
0,0,0,0,0,0,0,0,0,0,0,0,0,0,0,0,0,0,0,1,1,1,1,1,1,1,1,2,2,2,2,2,2,2,2,2,2,2,2,2,2,2,2,1,1,1,1,1,0,0,0,0,0,0
0,0,0,0,0,0,0,0,0,0,0,0,0,0,0,0,0,0,0,1,1,1,1,1,1,1,1,4,4,4,4,4,4,4,4,4,4,4,4,4,4,4,4,1,1,1,1,1,0,0,0,0,0,0
0,0,0,0,0,0,0,0,0,0,0,0,0,0,0,1,1,1,1,4,4,4,4,4,4,4,4,6,6,6,6,6,0,0,0,0,0,0,0,0,0,0,0,4,1,1,1,1,0,0,0,0,0,0
0,0,0,0,0,0,0,0,0,0,0,0,0,0,0,1,1,1,1,4,0,0,0,0,0,0,6,6,0,0,0,6,0,0,0,0,0,0,0,0,0,0,0,4,1,1,1,1,0,0,0,0,0,0
0,0,0,0,0,0,0,0,0,0,0,0,0,0,0,1,1,1,1,4,0,0,0,0,0,6,6,6,0,0,0,6,0,0,0,0,0,0,0,0,0,0,0,4,1,1,1,1,0,0,0,0,0,0
0,0,0,0,0,0,0,0,0,0,0,0,0,0,0,1,1,1,1,4,0,0,0,0,0,0,6,6,0,0,0,6,0,0,0,0,0,0,0,0,0,0,0,4,1,1,1,1,0,0,0,0,0,0
0,0,0,0,0,0,0,0,0,0,0,1,1,1,1,4,4,4,4,4,0,0,0,0,0,0,0,6,6,6,6,6,0,0,0,0,0,0,0,0,0,0,0,4,1,1,1,1,0,0,0,0,0,0
0,0,0,0,0,0,0,0,0,0,0,1,1,1,1,4,0,0,0,0,0,0,0,0,0,0,8,7,7,7,7,7,0,0,0,0,0,0,0,0,0,0,0,4,1,1,1,1,0,0,0,0,0,0
0,0,0,0,0,0,0,0,0,0,0,1,1,1,1,4,0,0,0,0,0,0,0,0,0,0,8,7,7,7,7,7,0,0,0,0,0,0,0,0,0,0,0,4,1,1,1,1,0,0,0,0,0,0
0,0,0,0,0,0,0,0,0,0,0,1,1,1,1,4,0,0,0,0,0,0,0,0,0,0,8,7,7,7,7,7,0,0,0,0,0,0,0,0,0,0,0,4,1,1,1,1,0,0,0,0,0,0
0,0,0,0,0,0,0,0,0,0,0,2,2,2,2,4,0,0,0,0,0,0,0,0,0,0,8,7,7,7,7,7,0,0,0,0,0,0,0,0,0,0,0,4,1,1,1,1,0,0,0,0,0,0
0,0,0,0,0,0,0,0,0,0,0,2,2,2,2,4,0,0,0,0,0,0,0,0,0,0,8,7,7,7,7,7,0,0,0,0,0,0,0,0,0,0,0,4,1,1,1,1,0,0,0,0,0,0
0,0,0,0,0,0,0,0,0,0,0,2,2,2,2,4,0,0,0,0,0,0,0,0,0,0,8,7,7,7,7,7,0,0,0,0,0,0,0,0,0,0,0,4,1,1,1,1,0,0,0,0,0,0
0,0,0,0,0,0,0,0,0,0,0,2,2,2,2,4,0,0,0,0,0,0,0,0,0,0,8,7,7,7,7,7,0,0,0,0,0,0,0,0,0,0,0,4,1,1,1,1,0,0,0,0,0,0
0,0,0,0,0,0,0,0,0,0,0,2,2,2,2,4,0,0,0,0,0,0,0,0,0,0,8,7,7,7,7,7,0,0,0,0,0,0,0,0,0,0,0,4,1,1,1,1,0,0,0,0,0,0
0,0,0,0,0,0,0,0,0,0,0,2,2,2,2,4,0,0,0,0,0,0,0,0,0,0,8,7,7,7,7,7,0,0,0,0,0,0,0,0,0,0,0,4,1,1,1,1,0,0,0,0,0,0
0,0,0,0,0,0,0,0,0,0,0,2,2,2,2,4,0,0,0,0,0,0,0,0,0,0,8,7,7,7,7,7,0,0,0,0,0,0,0,0,0,0,0,4,1,1,1,1,0,0,0,0,0,0
0,0,0,0,0,0,0,0,0,0,0,2,2,2,2,4,0,0,0,0,0,0,0,0,0,0,8,7,7,7,7,7,0,0,0,0,0,0,0,0,0,0,0,4,1,1,1,1,0,0,0,0,0,0
0,0,0,0,0,0,0,0,0,0,0,2,2,2,2,4,0,0,0,0,0,0,0,0,0,0,8,7,7,7,7,7,0,0,0,0,0,0,0,0,0,0,0,4,1,1,1,1,0,0,0,0,0,0
0,0,0,0,0,0,0,0,0,0,0,2,2,2,2,4,0,0,0,0,0,0,0,0,0,0,8,7,7,7,7,7,0,0,0,0,0,0,0,0,0,0,0,4,1,1,1,1,0,0,0,0,0,0
0,0,0,0,0,0,0,0,0,0,0,2,2,2,2,4,0,0,0,0,0,0,0,0,0,0,8,7,7,7,7,7,0,0,0,0,0,0,0,0,0,0,0,4,1,1,1,1,0,0,0,0,0,0
0,0,0,0,0,0,0,0,0,0,0,2,2,2,2,4,0,0,0,0,0,0,0,0,0,0,8,7,7,7,7,7,0,0,0,0,0,0,0,0,0,0,0,4,1,1,1,1,0,0,0,0,0,0
0,0,0,0,0,0,0,0,0,0,0,2,2,2,2,4,0,0,0,0,0,0,0,0,0,0,8,7,7,7,7,7,0,0,0,0,0,0,0,0,0,0,0,4,1,1,1,1,0,0,0,0,0,0
0,0,0,0,0,0,0,0,0,0,0,2,2,2,2,4,0,0,0,0,0,0,0,0,0,0,8,7,7,7,7,7,0,0,0,0,0,0,0,0,0,0,0,4,1,1,1,1,0,0,0,0,0,0
0,0,0,0,0,0,0,0,0,0,0,2,2,2,2,4,0,0,0,0,0,0,0,0,0,0,8,7,7,7,7,7,0,0,0,0,0,0,0,0,0,0,0,4,1,1,1,1,0,0,0,0,0,0
0,0,0,0,0,0,0,0,0,0,0,2,2,2,2,4,0,0,0,0,0,0,0,0,0,0,8,7,7,7,7,7,0,0,0,0,0,0,0,0,0,0,0,4,1,1,1,1,0,0,0,0,0,0
0,0,0,0,0,0,0,0,0,0,0,2,2,2,2,4,0,0,0,0,0,0,0,0,0,0,8,7,7,7,7,7,0,0,0,0,0,0,0,0,0,0,0,4,1,1,1,1,0,0,0,0,0,0
0,0,0,0,0,0,0,0,0,0,0,2,2,2,2,4,0,0,0,0,0,0,0,0,0,0,8,7,7,7,7,7,0,0,0,0,0,0,0,0,0,0,0,4,1,1,1,1,0,0,0,0,0,0
0,0,0,0,0,0,0,0,0,0,0,2,2,2,2,4,0,0,0,0,0,0,0,0,0,0,8,7,7,7,7,7,0,0,0,0,0,0,0,0,0,0,0,4,1,1,1,1,0,0,0,0,0,0
0,0,0,0,0,0,0,0,0,0,0,2,2,2,2,4,0,0,0,0,0,0,0,0,0,0,8,7,7,7,7,7,0,0,0,0,0,0,0,0,0,0,0,4,1,1,1,1,0,0,0,0,0,0
0,0,0,0,0,0,0,0,0,0,0,1,1,1,1,4,0,0,0,0,0,0,0,0,0,8,7,0,0,0,0,0,0,0,0,0,0,0,0,0,0,0,0,4,1,1,1,1,0,0,0,0,0,0
0,0,0,0,0,0,0,0,0,0,0,1,1,1,1,4,0,0,0,0,0,0,0,0,0,8,7,0,0,0,0,0,0,0,0,0,0,0,0,0,0,0,0,4,1,1,1,1,0,0,0,0,0,0
0,0,0,0,0,0,0,0,0,0,0,1,1,1,1,4,0,0,0,0,0,0,0,0,0,0,8,7,7,7,7,7,0,0,0,0,0,0,0,0,0,0,0,4,1,1,1,1,0,0,0,0,0,0
0,0,0,0,0,0,0,0,0,0,0,1,1,1,1,4,4,4,4,4,0,0,0,0,0,0,0,6,6,6,6,6,0,0,0,0,0,0,0,0,0,0,0,4,1,1,1,1,0,0,0,0,0,0
0,0,0,0,0,0,0,0,0,0,0,0,0,0,0,1,1,1,1,4,0,0,0,0,0,0,6,6,0,0,0,6,0,0,0,0,0,0,0,0,0,0,0,4,1,1,1,1,0,0,0,0,0,0
0,0,0,0,0,0,0,0,0,0,0,0,0,0,0,1,1,1,1,4,0,0,0,0,0,6,6,6,0,0,0,6,0,0,0,0,0,0,0,0,0,0,0,4,1,1,1,1,0,0,0,0,0,0
0,0,0,0,0,0,0,0,0,0,0,0,0,0,0,1,1,1,1,4,0,0,0,0,0,6,6,6,0,0,0,6,0,0,0,0,0,0,0,0,0,0,0,4,1,1,1,1,0,0,0,0,0,0
0,0,0,0,0,0,0,0,0,0,0,0,0,0,0,1,1,1,1,4,4,4,4,4,4,4,4,6,6,6,6,6,0,0,0,0,0,0,0,0,0,0,0,4,1,1,1,1,0,0,0,0,0,0
0,0,0,0,0,0,0,0,0,0,0,0,0,0,0,0,0,0,0,1,1,1,1,1,1,1,1,4,4,4,4,4,4,4,4,4,4,4,4,4,4,4,4,1,1,1,1,1,0,0,0,0,0,0
0,0,0,0,0,0,0,0,0,0,0,0,0,0,0,0,0,0,0,1,1,1,1,1,1,1,1,2,2,2,2,2,2,2,2,2,2,2,2,2,2,2,2,1,1,1,1,1,0,0,0,0,0,0
0,0,0,0,0,0,0,0,0,0,0,0,0,0,0,0,0,0,0,1,1,1,1,1,1,1,1,2,2,2,2,2,2,2,2,2,2,2,2,2,2,2,2,1,1,1,1,1,0,0,0,0,0,0
0,0,0,0,0,0,0,0,0,0,0,0,0,0,0,0,0,0,0,1,1,1,1,1,1,1,1,2,2,2,2,2,2,2,2,2,2,2,2,2,2,2,2,1,1,1,1,1,0,0,0,0,0,0
endlayer

layer
0,0,0,0,0,0,0,0,0,0,0,0,0,0,0,0,0,0,0,1,1,1,1,1,1,1,1,2,2,2,2,2,2,2,2,2,2,2,2,2,2,2,2,1,1,1,1,1,0,0,0,0,0,0
0,0,0,0,0,0,0,0,0,0,0,0,0,0,0,0,0,0,0,1,1,1,1,1,1,1,1,2,2,2,2,2,2,2,2,2,2,2,2,2,2,2,2,1,1,1,1,1,0,0,0,0,0,0
0,0,0,0,0,0,0,0,0,0,0,0,0,0,0,0,0,0,0,1,1,1,1,1,1,1,1,2,2,2,2,2,2,2,2,2,2,2,2,2,2,2,2,1,1,1,1,1,0,0,0,0,0,0
0,0,0,0,0,0,0,0,0,0,0,0,0,0,0,0,0,0,0,1,1,1,1,1,1,1,1,4,4,4,4,4,4,4,4,4,4,4,4,4,4,4,4,1,1,1,1,1,0,0,0,0,0,0
0,0,0,0,0,0,0,0,0,0,0,0,0,0,0,1,1,1,1,4,4,4,4,4,4,4,4,6,6,6,6,6,0,0,0,0,0,0,0,0,0,0,0,4,1,1,1,1,0,0,0,0,0,0
0,0,0,0,0,0,0,0,0,0,0,0,0,0,0,1,1,1,1,4,0,0,0,0,0,0,6,6,0,0,0,6,0,0,0,0,0,0,0,0,0,0,0,4,1,1,1,1,0,0,0,0,0,0
0,0,0,0,0,0,0,0,0,0,0,0,0,0,0,1,1,1,1,4,0,0,0,0,0,6,6,6,0,0,0,6,0,0,0,0,0,0,0,0,0,0,0,4,1,1,1,1,0,0,0,0,0,0
0,0,0,0,0,0,0,0,0,0,0,0,0,0,0,1,1,1,1,4,0,0,0,0,0,0,6,6,0,0,0,6,0,0,0,0,0,0,0,0,0,0,0,4,1,1,1,1,0,0,0,0,0,0
0,0,0,0,0,0,0,0,0,0,0,1,1,1,1,4,4,4,4,4,0,0,0,0,0,0,0,6,6,6,6,6,0,0,0,0,0,0,0,0,0,0,0,4,1,1,1,1,0,0,0,0,0,0
0,0,0,0,0,0,0,0,0,0,0,1,1,1,1,4,0,0,0,0,0,0,0,0,0,0,8,7,7,7,7,7,0,0,0,0,0,0,0,0,0,0,0,4,1,1,1,1,0,0,0,0,0,0
0,0,0,0,0,0,0,0,0,0,0,1,1,1,1,4,0,0,0,0,0,0,0,0,0,8,7,0,0,0,0,0,0,0,0,0,0,0,0,0,0,0,0,4,1,1,1,1,0,0,0,0,0,0
0,0,0,0,0,0,0,0,0,0,0,1,1,1,1,4,0,0,0,0,0,0,0,0,0,8,7,0,0,0,0,0,0,0,0,0,0,0,0,0,0,0,0,4,1,1,1,1,0,0,0,0,0,0
0,0,0,0,0,0,0,0,0,0,0,2,2,2,2,4,0,0,0,0,0,0,0,0,0,8,7,0,0,0,0,0,0,0,0,0,0,0,0,0,0,0,0,4,1,1,1,1,0,0,0,0,0,0
0,0,0,0,0,0,0,0,0,0,0,2,2,2,2,4,0,0,0,0,0,0,0,0,0,8,7,0,0,0,0,0,0,0,0,0,0,0,0,0,0,0,0,4,1,1,1,1,0,0,0,0,0,0
0,0,0,0,0,0,0,0,0,0,0,2,2,2,2,4,0,0,0,0,0,0,0,0,0,8,7,0,0,0,0,0,0,0,0,0,0,0,0,0,0,0,0,4,1,1,1,1,0,0,0,0,0,0
0,0,0,0,0,0,0,0,0,0,0,2,2,2,2,4,0,0,0,0,0,0,0,0,0,8,7,0,0,0,0,0,0,0,0,0,0,0,0,0,0,0,0,4,1,1,1,1,0,0,0,0,0,0
0,0,0,0,0,0,0,0,0,0,0,2,2,2,2,4,0,0,0,0,0,0,0,0,0,8,7,0,0,0,0,0,0,0,0,0,0,0,0,0,0,0,0,4,1,1,1,1,0,0,0,0,0,0
0,0,0,0,0,0,0,0,0,0,0,2,2,2,2,4,0,0,0,0,0,0,0,0,0,8,7,0,0,0,0,0,0,0,0,0,0,0,0,0,0,0,0,4,1,1,1,1,0,0,0,0,0,0
0,0,0,0,0,0,0,0,0,0,0,2,2,2,2,4,0,0,0,0,0,0,0,0,0,8,7,0,0,0,0,0,0,0,0,0,0,0,0,0,0,0,0,4,1,1,1,1,0,0,0,0,0,0
0,0,0,0,0,0,0,0,0,0,0,2,2,2,2,4,0,0,0,0,0,0,0,0,0,8,7,0,0,0,0,0,0,0,0,0,0,0,0,0,0,0,0,4,1,1,1,1,0,0,0,0,0,0
0,0,0,0,0,0,0,0,0,0,0,2,2,2,2,4,0,0,0,0,0,0,0,0,0,8,7,0,0,0,0,0,0,0,0,0,0,0,0,0,0,0,0,4,1,1,1,1,0,0,0,0,0,0
0,0,0,0,0,0,0,0,0,0,0,2,2,2,2,4,0,0,0,0,0,0,0,0,0,8,7,0,0,0,0,0,0,0,0,0,0,0,0,0,0,0,0,4,1,1,1,1,0,0,0,0,0,0
0,0,0,0,0,0,0,0,0,0,0,2,2,2,2,4,0,0,0,0,0,0,0,0,0,8,7,0,0,0,0,0,0,0,0,0,0,0,0,0,0,0,0,4,1,1,1,1,0,0,0,0,0,0
0,0,0,0,0,0,0,0,0,0,0,2,2,2,2,4,0,0,0,0,0,0,0,0,0,8,7,0,0,0,0,0,0,0,0,0,0,0,0,0,0,0,0,4,1,1,1,1,0,0,0,0,0,0
0,0,0,0,0,0,0,0,0,0,0,2,2,2,2,4,0,0,0,0,0,0,0,0,0,8,7,0,0,0,0,0,0,0,0,0,0,0,0,0,0,0,0,4,1,1,1,1,0,0,0,0,0,0
0,0,0,0,0,0,0,0,0,0,0,2,2,2,2,4,0,0,0,0,0,0,0,0,0,8,7,0,0,0,0,0,0,0,0,0,0,0,0,0,0,0,0,4,1,1,1,1,0,0,0,0,0,0
0,0,0,0,0,0,0,0,0,0,0,2,2,2,2,4,0,0,0,0,0,0,0,0,0,8,7,0,0,0,0,0,0,0,0,0,0,0,0,0,0,0,0,4,1,1,1,1,0,0,0,0,0,0
0,0,0,0,0,0,0,0,0,0,0,2,2,2,2,4,0,0,0,0,0,0,0,0,0,8,7,0,0,0,0,0,0,0,0,0,0,0,0,0,0,0,0,4,1,1,1,1,0,0,0,0,0,0
0,0,0,0,0,0,0,0,0,0,0,2,2,2,2,4,0,0,0,0,0,0,0,0,0,8,7,0,0,0,0,0,0,0,0,0,0,0,0,0,0,0,0,4,1,1,1,1,0,0,0,0,0,0
0,0,0,0,0,0,0,0,0,0,0,2,2,2,2,4,0,0,0,0,0,0,0,0,0,8,7,0,0,0,0,0,0,0,0,0,0,0,0,0,0,0,0,4,1,1,1,1,0,0,0,0,0,0
0,0,0,0,0,0,0,0,0,0,0,2,2,2,2,4,0,0,0,0,0,0,0,0,0,8,7,0,0,0,0,0,0,0,0,0,0,0,0,0,0,0,0,4,1,1,1,1,0,0,0,0,0,0
0,0,0,0,0,0,0,0,0,0,0,2,2,2,2,4,0,0,0,0,0,0,0,0,0,8,7,0,0,0,0,0,0,0,0,0,0,0,0,0,0,0,0,4,1,1,1,1,0,0,0,0,0,0
0,0,0,0,0,0,0,0,0,0,0,1,1,1,1,4,0,0,0,0,0,0,0,0,0,8,7,0,0,0,0,0,0,0,0,0,0,0,0,0,0,0,0,4,1,1,1,1,0,0,0,0,0,0
0,0,0,0,0,0,0,0,0,0,0,1,1,1,1,4,0,0,0,0,0,0,0,0,0,8,7,0,0,0,0,0,0,0,0,0,0,0,0,0,0,0,0,4,1,1,1,1,0,0,0,0,0,0
0,0,0,0,0,0,0,0,0,0,0,1,1,1,1,4,0,0,0,0,0,0,0,0,0,0,8,7,7,7,7,7,0,0,0,0,0,0,0,0,0,0,0,4,1,1,1,1,0,0,0,0,0,0
0,0,0,0,0,0,0,0,0,0,0,1,1,1,1,4,4,4,4,4,0,0,0,0,0,0,0,6,6,6,6,6,0,0,0,0,0,0,0,0,0,0,0,4,1,1,1,1,0,0,0,0,0,0
0,0,0,0,0,0,0,0,0,0,0,0,0,0,0,1,1,1,1,4,0,0,0,0,0,0,6,6,0,0,0,6,0,0,0,0,0,0,0,0,0,0,0,4,1,1,1,1,0,0,0,0,0,0
0,0,0,0,0,0,0,0,0,0,0,0,0,0,0,1,1,1,1,4,0,0,0,0,0,6,6,6,0,0,0,6,0,0,0,0,0,0,0,0,0,0,0,4,1,1,1,1,0,0,0,0,0,0
0,0,0,0,0,0,0,0,0,0,0,0,0,0,0,1,1,1,1,4,0,0,0,0,0,6,6,6,0,0,0,6,0,0,0,0,0,0,0,0,0,0,0,4,1,1,1,1,0,0,0,0,0,0
0,0,0,0,0,0,0,0,0,0,0,0,0,0,0,1,1,1,1,4,4,4,4,4,4,4,4,6,6,6,6,6,0,0,0,0,0,0,0,0,0,0,0,4,1,1,1,1,0,0,0,0,0,0
0,0,0,0,0,0,0,0,0,0,0,0,0,0,0,0,0,0,0,1,1,1,1,1,1,1,1,4,4,4,4,4,4,4,4,4,4,4,4,4,4,4,4,1,1,1,1,1,0,0,0,0,0,0
0,0,0,0,0,0,0,0,0,0,0,0,0,0,0,0,0,0,0,1,1,1,1,1,1,1,1,2,2,2,2,2,2,2,2,2,2,2,2,2,2,2,2,1,1,1,1,1,0,0,0,0,0,0
0,0,0,0,0,0,0,0,0,0,0,0,0,0,0,0,0,0,0,1,1,1,1,1,1,1,1,2,2,2,2,2,2,2,2,2,2,2,2,2,2,2,2,1,1,1,1,1,0,0,0,0,0,0
0,0,0,0,0,0,0,0,0,0,0,0,0,0,0,0,0,0,0,1,1,1,1,1,1,1,1,2,2,2,2,2,2,2,2,2,2,2,2,2,2,2,2,1,1,1,1,1,0,0,0,0,0,0
endlayer

layer
0,0,0,0,0,0,0,0,0,0,0,0,0,0,0,0,0,0,0,1,1,1,1,1,1,1,1,2,2,2,2,2,2,2,2,2,2,2,2,2,2,2,2,1,1,1,1,1,0,0,0,0,0,0
0,0,0,0,0,0,0,0,0,0,0,0,0,0,0,0,0,0,0,1,1,1,1,1,1,1,1,2,2,2,2,2,2,2,2,2,2,2,2,2,2,2,2,1,1,1,1,1,0,0,0,0,0,0
0,0,0,0,0,0,0,0,0,0,0,0,0,0,0,0,0,0,0,1,1,1,1,1,1,1,1,2,2,2,2,2,2,2,2,2,2,2,2,2,2,2,2,1,1,1,1,1,0,0,0,0,0,0
0,0,0,0,0,0,0,0,0,0,0,0,0,0,0,0,0,0,0,1,1,1,1,1,1,1,1,4,4,4,4,4,4,4,4,4,4,4,4,4,4,4,4,1,1,1,1,1,0,0,0,0,0,0
0,0,0,0,0,0,0,0,0,0,0,0,0,0,0,1,1,1,1,4,4,4,4,4,4,4,4,6,6,6,6,6,0,0,0,0,0,0,0,0,0,0,0,4,1,1,1,1,0,0,0,0,0,0
0,0,0,0,0,0,0,0,0,0,0,0,0,0,0,1,1,1,1,4,0,0,0,0,0,0,6,6,0,0,0,6,0,0,0,0,0,0,0,0,0,0,0,4,1,1,1,1,0,0,0,0,0,0
0,0,0,0,0,0,0,0,0,0,0,0,0,0,0,1,1,1,1,4,0,0,0,0,0,6,6,6,0,0,0,6,0,0,0,0,0,0,0,0,0,0,0,4,1,1,1,1,0,0,0,0,0,0
0,0,0,0,0,0,0,0,0,0,0,0,0,0,0,1,1,1,1,4,0,0,0,0,0,0,6,6,0,0,0,6,0,0,0,0,0,0,0,0,0,0,0,4,1,1,1,1,0,0,0,0,0,0
0,0,0,0,0,0,0,0,0,0,0,1,1,1,1,4,4,4,4,4,0,0,0,0,0,0,0,6,6,6,6,6,0,0,0,0,0,0,0,0,0,0,0,4,1,1,1,1,0,0,0,0,0,0
0,0,0,0,0,0,0,0,0,0,0,1,1,1,1,4,0,0,0,0,0,0,0,0,0,0,8,7,7,7,7,7,0,0,0,0,0,0,0,0,0,0,0,4,1,1,1,1,0,0,0,0,0,0
0,0,0,0,0,0,0,0,0,0,0,1,1,1,1,4,0,0,0,0,0,0,0,0,0,8,7,0,0,0,0,0,0,0,0,0,0,0,0,0,0,0,0,4,1,1,1,1,0,0,0,0,0,0
0,0,0,0,0,0,0,0,0,0,0,1,1,1,1,4,0,0,0,0,0,0,0,0,0,8,7,0,0,0,0,0,0,0,0,0,0,0,0,0,0,0,0,4,1,1,1,1,0,0,0,0,0,0
0,0,0,0,0,0,0,0,0,0,0,2,2,2,2,4,0,0,0,0,0,0,0,0,0,8,7,0,0,0,0,0,0,0,0,0,0,0,0,0,0,0,0,4,1,1,1,1,0,0,0,0,0,0
0,0,0,0,0,0,0,0,0,0,0,2,2,2,2,4,0,0,0,0,0,0,0,0,0,8,7,0,0,0,0,0,0,0,0,0,0,0,0,0,0,0,0,4,1,1,1,1,0,0,0,0,0,0
0,0,0,0,0,0,0,0,0,0,0,2,2,2,2,4,0,0,0,0,0,0,0,0,0,8,7,0,0,0,0,0,0,0,0,0,0,0,0,0,0,0,0,4,1,1,1,1,0,0,0,0,0,0
0,0,0,0,0,0,0,0,0,0,0,2,2,2,2,4,0,0,0,0,0,0,0,0,0,8,7,0,0,0,0,0,0,0,0,0,0,0,0,0,0,0,0,4,1,1,1,1,0,0,0,0,0,0
0,0,0,0,0,0,0,0,0,0,0,2,2,2,2,4,0,0,0,0,0,0,0,0,0,8,7,0,0,0,0,0,0,0,0,0,0,0,0,0,0,0,0,4,1,1,1,1,0,0,0,0,0,0
0,0,0,0,0,0,0,0,0,0,0,2,2,2,2,4,0,0,0,0,0,0,0,0,0,8,7,0,0,0,0,0,0,0,0,0,0,0,0,0,0,0,0,4,1,1,1,1,0,0,0,0,0,0
0,0,0,0,0,0,0,0,0,0,0,2,2,2,2,4,0,0,0,0,0,0,0,0,0,8,7,0,0,0,0,0,0,0,0,0,0,0,0,0,0,0,0,4,1,1,1,1,0,0,0,0,0,0
0,0,0,0,0,0,0,0,0,0,0,2,2,2,2,4,0,0,0,0,0,0,0,0,0,8,7,0,0,0,0,0,0,0,0,0,0,0,0,0,0,0,0,4,1,1,1,1,0,0,0,0,0,0
0,0,0,0,0,0,0,0,0,0,0,2,2,2,2,4,0,0,0,0,0,0,0,0,0,8,7,0,0,0,0,0,0,0,0,0,0,0,0,0,0,0,0,4,1,1,1,1,0,0,0,0,0,0
0,0,0,0,0,0,0,0,0,0,0,2,2,2,2,4,0,0,0,0,0,0,0,0,0,8,7,0,0,0,0,0,0,0,0,0,0,0,0,0,0,0,0,4,1,1,1,1,0,0,0,0,0,0
0,0,0,0,0,0,0,0,0,0,0,2,2,2,2,4,0,0,0,0,0,0,0,0,0,8,7,0,0,0,0,0,0,0,0,0,0,0,0,0,0,0,0,4,1,1,1,1,0,0,0,0,0,0
0,0,0,0,0,0,0,0,0,0,0,2,2,2,2,4,0,0,0,0,0,0,0,0,0,8,7,0,0,0,0,0,0,0,0,0,0,0,0,0,0,0,0,4,1,1,1,1,0,0,0,0,0,0
0,0,0,0,0,0,0,0,0,0,0,2,2,2,2,4,0,0,0,0,0,0,0,0,0,8,7,0,0,0,0,0,0,0,0,0,0,0,0,0,0,0,0,4,1,1,1,1,0,0,0,0,0,0
0,0,0,0,0,0,0,0,0,0,0,2,2,2,2,4,0,0,0,0,0,0,0,0,0,8,7,0,0,0,0,0,0,0,0,0,0,0,0,0,0,0,0,4,1,1,1,1,0,0,0,0,0,0
0,0,0,0,0,0,0,0,0,0,0,2,2,2,2,4,0,0,0,0,0,0,0,0,0,8,7,0,0,0,0,0,0,0,0,0,0,0,0,0,0,0,0,4,1,1,1,1,0,0,0,0,0,0
0,0,0,0,0,0,0,0,0,0,0,2,2,2,2,4,0,0,0,0,0,0,0,0,0,8,7,0,0,0,0,0,0,0,0,0,0,0,0,0,0,0,0,4,1,1,1,1,0,0,0,0,0,0
0,0,0,0,0,0,0,0,0,0,0,2,2,2,2,4,0,0,0,0,0,0,0,0,0,8,7,0,0,0,0,0,0,0,0,0,0,0,0,0,0,0,0,4,1,1,1,1,0,0,0,0,0,0
0,0,0,0,0,0,0,0,0,0,0,2,2,2,2,4,0,0,0,0,0,0,0,0,0,8,7,0,0,0,0,0,0,0,0,0,0,0,0,0,0,0,0,4,1,1,1,1,0,0,0,0,0,0
0,0,0,0,0,0,0,0,0,0,0,2,2,2,2,4,0,0,0,0,0,0,0,0,0,8,7,0,0,0,0,0,0,0,0,0,0,0,0,0,0,0,0,4,1,1,1,1,0,0,0,0,0,0
0,0,0,0,0,0,0,0,0,0,0,2,2,2,2,4,0,0,0,0,0,0,0,0,0,8,7,0,0,0,0,0,0,0,0,0,0,0,0,0,0,0,0,4,1,1,1,1,0,0,0,0,0,0
0,0,0,0,0,0,0,0,0,0,0,1,1,1,1,4,0,0,0,0,0,0,0,0,0,8,7,0,0,0,0,0,0,0,0,0,0,0,0,0,0,0,0,4,1,1,1,1,0,0,0,0,0,0
0,0,0,0,0,0,0,0,0,0,0,1,1,1,1,4,0,0,0,0,0,0,0,0,0,8,7,0,0,0,0,0,0,0,0,0,0,0,0,0,0,0,0,4,1,1,1,1,0,0,0,0,0,0
0,0,0,0,0,0,0,0,0,0,0,1,1,1,1,4,0,0,0,0,0,0,0,0,0,0,8,7,7,7,7,7,0,0,0,0,0,0,0,0,0,0,0,4,1,1,1,1,0,0,0,0,0,0
0,0,0,0,0,0,0,0,0,0,0,1,1,1,1,4,4,4,4,4,0,0,0,0,0,0,0,6,6,6,6,6,0,0,0,0,0,0,0,0,0,0,0,4,1,1,1,1,0,0,0,0,0,0
0,0,0,0,0,0,0,0,0,0,0,0,0,0,0,1,1,1,1,4,0,0,0,0,0,0,6,6,0,0,0,6,0,0,0,0,0,0,0,0,0,0,0,4,1,1,1,1,0,0,0,0,0,0
0,0,0,0,0,0,0,0,0,0,0,0,0,0,0,1,1,1,1,4,0,0,0,0,0,6,6,6,0,0,0,6,0,0,0,0,0,0,0,0,0,0,0,4,1,1,1,1,0,0,0,0,0,0
0,0,0,0,0,0,0,0,0,0,0,0,0,0,0,1,1,1,1,4,0,0,0,0,0,6,6,6,0,0,0,6,0,0,0,0,0,0,0,0,0,0,0,4,1,1,1,1,0,0,0,0,0,0
0,0,0,0,0,0,0,0,0,0,0,0,0,0,0,1,1,1,1,4,4,4,4,4,4,4,4,6,6,6,6,6,0,0,0,0,0,0,0,0,0,0,0,4,1,1,1,1,0,0,0,0,0,0
0,0,0,0,0,0,0,0,0,0,0,0,0,0,0,0,0,0,0,1,1,1,1,1,1,1,1,4,4,4,4,4,4,4,4,4,4,4,4,4,4,4,4,1,1,1,1,1,0,0,0,0,0,0
0,0,0,0,0,0,0,0,0,0,0,0,0,0,0,0,0,0,0,1,1,1,1,1,1,1,1,2,2,2,2,2,2,2,2,2,2,2,2,2,2,2,2,1,1,1,1,1,0,0,0,0,0,0
0,0,0,0,0,0,0,0,0,0,0,0,0,0,0,0,0,0,0,1,1,1,1,1,1,1,1,2,2,2,2,2,2,2,2,2,2,2,2,2,2,2,2,1,1,1,1,1,0,0,0,0,0,0
0,0,0,0,0,0,0,0,0,0,0,0,0,0,0,0,0,0,0,1,1,1,1,1,1,1,1,2,2,2,2,2,2,2,2,2,2,2,2,2,2,2,2,1,1,1,1,1,0,0,0,0,0,0
endlayer

layer
0,0,0,0,0,0,0,0,0,0,0,0,0,0,0,0,0,0,0,1,1,1,1,1,1,1,1,2,2,2,2,2,2,2,2,2,2,2,2,2,2,2,2,1,1,1,1,1,0,0,0,0,0,0
0,0,0,0,0,0,0,0,0,0,0,0,0,0,0,0,0,0,0,1,1,1,1,1,1,1,1,2,2,2,2,2,2,2,2,2,2,2,2,2,2,2,2,1,1,1,1,1,0,0,0,0,0,0
0,0,0,0,0,0,0,0,0,0,0,0,0,0,0,0,0,0,0,1,1,1,1,1,1,1,1,2,2,2,2,2,2,2,2,2,2,2,2,2,2,2,2,1,1,1,1,1,0,0,0,0,0,0
0,0,0,0,0,0,0,0,0,0,0,0,0,0,0,0,0,0,0,1,1,1,1,1,1,1,1,4,4,4,4,4,4,4,4,4,4,4,4,4,4,4,4,1,1,1,1,1,0,0,0,0,0,0
0,0,0,0,0,0,0,0,0,0,0,0,0,0,0,1,1,1,1,4,4,4,4,4,4,4,4,6,6,6,6,6,0,0,0,0,0,0,0,0,0,0,0,4,1,1,1,1,0,0,0,0,0,0
0,0,0,0,0,0,0,0,0,0,0,0,0,0,0,1,1,1,1,4,0,0,0,0,0,0,6,6,0,0,0,6,0,0,0,0,0,0,0,0,0,0,0,4,1,1,1,1,0,0,0,0,0,0
0,0,0,0,0,0,0,0,0,0,0,0,0,0,0,1,1,1,1,4,0,0,0,0,0,6,6,6,0,0,0,6,0,0,0,0,0,0,0,0,0,0,0,4,1,1,1,1,0,0,0,0,0,0
0,0,0,0,0,0,0,0,0,0,0,0,0,0,0,1,1,1,1,4,0,0,0,0,0,0,6,6,0,0,0,6,0,0,0,0,0,0,0,0,0,0,0,4,1,1,1,1,0,0,0,0,0,0
0,0,0,0,0,0,0,0,0,0,0,1,1,1,1,4,4,4,4,4,0,0,0,0,0,0,0,6,6,6,6,6,0,0,0,0,0,0,0,0,0,0,0,4,1,1,1,1,0,0,0,0,0,0
0,0,0,0,0,0,0,0,0,0,0,1,1,1,1,4,0,0,0,0,0,0,0,0,0,0,8,7,7,7,7,7,0,0,0,0,0,0,0,0,0,0,0,4,1,1,1,1,0,0,0,0,0,0
0,0,0,0,0,0,0,0,0,0,0,1,1,1,1,4,0,0,0,0,0,0,0,0,0,8,7,0,0,0,0,0,0,0,0,0,0,0,0,0,0,0,0,4,1,1,1,1,0,0,0,0,0,0
0,0,0,0,0,0,0,0,0,0,0,1,1,1,1,4,0,0,0,0,0,0,0,0,0,8,7,0,0,0,0,0,0,0,0,0,0,0,0,0,0,0,0,4,1,1,1,1,0,0,0,0,0,0
0,0,0,0,0,0,0,0,0,0,0,2,2,2,2,4,0,0,0,0,0,0,0,0,0,0,8,7,7,7,7,7,0,0,0,0,0,0,0,0,0,0,0,4,1,1,1,1,0,0,0,0,0,0
0,0,0,0,0,0,0,0,0,0,0,2,2,2,2,4,0,0,0,0,0,0,0,0,0,0,8,7,7,7,7,7,0,0,0,0,0,0,0,0,0,0,0,4,1,1,1,1,0,0,0,0,0,0
0,0,0,0,0,0,0,0,0,0,0,2,2,2,2,4,0,0,0,0,0,0,0,0,0,0,8,7,7,7,7,7,0,0,0,0,0,0,0,0,0,0,0,4,1,1,1,1,0,0,0,0,0,0
0,0,0,0,0,0,0,0,0,0,0,2,2,2,2,4,0,0,0,0,0,0,0,0,0,0,8,7,7,7,7,7,0,0,0,0,0,0,0,0,0,0,0,4,1,1,1,1,0,0,0,0,0,0
0,0,0,0,0,0,0,0,0,0,0,2,2,2,2,4,0,0,0,0,0,0,0,0,0,0,8,7,7,7,7,7,0,0,0,0,0,0,0,0,0,0,0,4,1,1,1,1,0,0,0,0,0,0
0,0,0,0,0,0,0,0,0,0,0,2,2,2,2,4,0,0,0,0,0,0,0,0,0,0,8,7,7,7,7,7,0,0,0,0,0,0,0,0,0,0,0,4,1,1,1,1,0,0,0,0,0,0
0,0,0,0,0,0,0,0,0,0,0,2,2,2,2,4,0,0,0,0,0,0,0,0,0,0,8,7,7,7,7,7,0,0,0,0,0,0,0,0,0,0,0,4,1,1,1,1,0,0,0,0,0,0
0,0,0,0,0,0,0,0,0,0,0,2,2,2,2,4,0,0,0,0,0,0,0,0,0,0,8,7,7,7,7,7,0,0,0,0,0,0,0,0,0,0,0,4,1,1,1,1,0,0,0,0,0,0
0,0,0,0,0,0,0,0,0,0,0,2,2,2,2,4,0,0,0,0,0,0,0,0,0,0,8,7,7,7,7,7,0,0,0,0,0,0,0,0,0,0,0,4,1,1,1,1,0,0,0,0,0,0
0,0,0,0,0,0,0,0,0,0,0,2,2,2,2,4,0,0,0,0,0,0,0,0,0,0,8,7,7,7,7,7,0,0,0,0,0,0,0,0,0,0,0,4,1,1,1,1,0,0,0,0,0,0
0,0,0,0,0,0,0,0,0,0,0,2,2,2,2,4,0,0,0,0,0,0,0,0,0,0,8,7,7,7,7,7,0,0,0,0,0,0,0,0,0,0,0,4,1,1,1,1,0,0,0,0,0,0
0,0,0,0,0,0,0,0,0,0,0,2,2,2,2,4,0,0,0,0,0,0,0,0,0,0,8,7,7,7,7,7,0,0,0,0,0,0,0,0,0,0,0,4,1,1,1,1,0,0,0,0,0,0
0,0,0,0,0,0,0,0,0,0,0,2,2,2,2,4,0,0,0,0,0,0,0,0,0,0,8,7,7,7,7,7,0,0,0,0,0,0,0,0,0,0,0,4,1,1,1,1,0,0,0,0,0,0
0,0,0,0,0,0,0,0,0,0,0,2,2,2,2,4,0,0,0,0,0,0,0,0,0,0,8,7,7,7,7,7,0,0,0,0,0,0,0,0,0,0,0,4,1,1,1,1,0,0,0,0,0,0
0,0,0,0,0,0,0,0,0,0,0,2,2,2,2,4,0,0,0,0,0,0,0,0,0,0,8,7,7,7,7,7,0,0,0,0,0,0,0,0,0,0,0,4,1,1,1,1,0,0,0,0,0,0
0,0,0,0,0,0,0,0,0,0,0,2,2,2,2,4,0,0,0,0,0,0,0,0,0,0,8,7,7,7,7,7,0,0,0,0,0,0,0,0,0,0,0,4,1,1,1,1,0,0,0,0,0,0
0,0,0,0,0,0,0,0,0,0,0,2,2,2,2,4,0,0,0,0,0,0,0,0,0,0,8,7,7,7,7,7,0,0,0,0,0,0,0,0,0,0,0,4,1,1,1,1,0,0,0,0,0,0
0,0,0,0,0,0,0,0,0,0,0,2,2,2,2,4,0,0,0,0,0,0,0,0,0,0,8,7,7,7,7,7,0,0,0,0,0,0,0,0,0,0,0,4,1,1,1,1,0,0,0,0,0,0
0,0,0,0,0,0,0,0,0,0,0,2,2,2,2,4,0,0,0,0,0,0,0,0,0,0,8,7,7,7,7,7,0,0,0,0,0,0,0,0,0,0,0,4,1,1,1,1,0,0,0,0,0,0
0,0,0,0,0,0,0,0,0,0,0,2,2,2,2,4,0,0,0,0,0,0,0,0,0,0,8,7,7,7,7,7,0,0,0,0,0,0,0,0,0,0,0,4,1,1,1,1,0,0,0,0,0,0
0,0,0,0,0,0,0,0,0,0,0,1,1,1,1,4,0,0,0,0,0,0,0,0,0,0,8,7,7,7,7,7,0,0,0,0,0,0,0,0,0,0,0,4,1,1,1,1,0,0,0,0,0,0
0,0,0,0,0,0,0,0,0,0,0,1,1,1,1,4,0,0,0,0,0,0,0,0,0,0,8,7,7,7,7,7,0,0,0,0,0,0,0,0,0,0,0,4,1,1,1,1,0,0,0,0,0,0
0,0,0,0,0,0,0,0,0,0,0,1,1,1,1,4,0,0,0,0,0,0,0,0,0,0,8,7,7,7,7,7,0,0,0,0,0,0,0,0,0,0,0,4,1,1,1,1,0,0,0,0,0,0
0,0,0,0,0,0,0,0,0,0,0,1,1,1,1,4,4,4,4,4,0,0,0,0,0,0,0,6,6,6,6,6,0,0,0,0,0,0,0,0,0,0,0,4,1,1,1,1,0,0,0,0,0,0
0,0,0,0,0,0,0,0,0,0,0,0,0,0,0,1,1,1,1,4,0,0,0,0,0,0,6,6,0,0,0,6,0,0,0,0,0,0,0,0,0,0,0,4,1,1,1,1,0,0,0,0,0,0
0,0,0,0,0,0,0,0,0,0,0,0,0,0,0,1,1,1,1,4,0,0,0,0,0,6,6,6,0,0,0,6,0,0,0,0,0,0,0,0,0,0,0,4,1,1,1,1,0,0,0,0,0,0
0,0,0,0,0,0,0,0,0,0,0,0,0,0,0,1,1,1,1,4,0,0,0,0,0,6,6,6,0,0,0,6,0,0,0,0,0,0,0,0,0,0,0,4,1,1,1,1,0,0,0,0,0,0
0,0,0,0,0,0,0,0,0,0,0,0,0,0,0,1,1,1,1,4,4,4,4,4,4,4,4,6,6,6,6,6,0,0,0,0,0,0,0,0,0,0,0,4,1,1,1,1,0,0,0,0,0,0
0,0,0,0,0,0,0,0,0,0,0,0,0,0,0,0,0,0,0,1,1,1,1,1,1,1,1,4,4,4,4,4,4,4,4,4,4,4,4,4,4,4,4,1,1,1,1,1,0,0,0,0,0,0
0,0,0,0,0,0,0,0,0,0,0,0,0,0,0,0,0,0,0,1,1,1,1,1,1,1,1,2,2,2,2,2,2,2,2,2,2,2,2,2,2,2,2,1,1,1,1,1,0,0,0,0,0,0
0,0,0,0,0,0,0,0,0,0,0,0,0,0,0,0,0,0,0,1,1,1,1,1,1,1,1,2,2,2,2,2,2,2,2,2,2,2,2,2,2,2,2,1,1,1,1,1,0,0,0,0,0,0
0,0,0,0,0,0,0,0,0,0,0,0,0,0,0,0,0,0,0,1,1,1,1,1,1,1,1,2,2,2,2,2,2,2,2,2,2,2,2,2,2,2,2,1,1,1,1,1,0,0,0,0,0,0
endlayer

layer
0,0,0,0,0,0,0,0,0,0,0,0,0,0,0,0,0,0,0,1,1,1,1,1,1,1,1,2,2,2,2,2,2,2,2,2,2,2,2,2,2,2,2,1,1,1,1,1,0,0,0,0,0,0
0,0,0,0,0,0,0,0,0,0,0,0,0,0,0,0,0,0,0,1,1,1,1,1,1,1,1,2,2,2,2,2,2,2,2,2,2,2,2,2,2,2,2,1,1,1,1,1,0,0,0,0,0,0
0,0,0,0,0,0,0,0,0,0,0,0,0,0,0,0,0,0,0,1,1,1,1,1,1,1,1,2,2,2,2,2,2,2,2,2,2,2,2,2,2,2,2,1,1,1,1,1,0,0,0,0,0,0
0,0,0,0,0,0,0,0,0,0,0,0,0,0,0,0,0,0,0,1,1,1,1,1,1,1,1,4,4,4,4,4,4,4,4,4,4,4,4,4,4,4,4,1,1,1,1,1,0,0,0,0,0,0
0,0,0,0,0,0,0,0,0,0,0,0,0,0,0,1,1,1,1,4,4,4,4,4,4,4,4,6,6,6,6,6,0,0,0,0,0,0,0,0,0,0,0,4,1,1,1,1,0,0,0,0,0,0
0,0,0,0,0,0,0,0,0,0,0,0,0,0,0,1,1,1,1,4,0,0,0,0,0,0,6,6,0,0,0,6,0,0,0,0,0,0,0,0,0,0,0,4,1,1,1,1,0,0,0,0,0,0
0,0,0,0,0,0,0,0,0,0,0,0,0,0,0,1,1,1,1,4,0,0,0,0,0,6,6,6,0,0,0,6,0,0,0,0,0,0,0,0,0,0,0,4,1,1,1,1,0,0,0,0,0,0
0,0,0,0,0,0,0,0,0,0,0,0,0,0,0,1,1,1,1,4,0,0,0,0,0,0,6,6,0,0,0,6,0,0,0,0,0,0,0,0,0,0,0,4,1,1,1,1,0,0,0,0,0,0
0,0,0,0,0,0,0,0,0,0,0,1,1,1,1,4,4,4,4,4,0,0,0,0,0,0,0,6,6,6,6,6,0,0,0,0,0,0,0,0,0,0,0,4,1,1,1,1,0,0,0,0,0,0
0,0,0,0,0,0,0,0,0,0,0,1,1,1,1,4,0,0,0,0,0,0,0,0,0,0,8,7,7,7,7,7,0,0,0,0,0,0,0,0,0,0,0,4,1,1,1,1,0,0,0,0,0,0
0,0,0,0,0,0,0,0,0,0,0,1,1,1,1,4,0,0,0,0,0,0,0,0,0,8,7,0,0,0,0,0,0,0,0,0,0,0,0,0,0,0,0,4,1,1,1,1,0,0,0,0,0,0
0,0,0,0,0,0,0,0,0,0,0,1,1,1,1,4,0,0,0,0,0,0,0,0,0,8,7,0,0,0,0,0,0,0,0,0,0,0,0,0,0,0,0,4,1,1,1,1,0,0,0,0,0,0
0,0,0,0,0,0,0,0,0,0,0,2,2,2,2,4,0,0,0,0,0,0,0,0,0,8,7,0,0,0,0,0,0,0,0,0,0,0,0,0,0,0,0,4,1,1,1,1,0,0,0,0,0,0
0,0,0,0,0,0,0,0,0,0,0,2,2,2,2,4,0,0,0,0,0,0,0,0,0,8,7,0,0,0,0,0,0,0,0,0,0,0,0,0,0,0,0,4,1,1,1,1,0,0,0,0,0,0
0,0,0,0,0,0,0,0,0,0,0,2,2,2,2,4,0,0,0,0,0,0,0,0,0,8,7,0,0,0,0,0,0,0,0,0,0,0,0,0,0,0,0,4,1,1,1,1,0,0,0,0,0,0
0,0,0,0,0,0,0,0,0,0,0,2,2,2,2,4,0,0,0,0,0,0,0,0,0,8,7,0,0,0,0,0,0,0,0,0,0,0,0,0,0,0,0,4,1,1,1,1,0,0,0,0,0,0
0,0,0,0,0,0,0,0,0,0,0,2,2,2,2,4,0,0,0,0,0,0,0,0,0,8,7,0,0,0,0,0,0,0,0,0,0,0,0,0,0,0,0,4,1,1,1,1,0,0,0,0,0,0
0,0,0,0,0,0,0,0,0,0,0,2,2,2,2,4,0,0,0,0,0,0,0,0,0,8,7,0,0,0,0,0,0,0,0,0,0,0,0,0,0,0,0,4,1,1,1,1,0,0,0,0,0,0
0,0,0,0,0,0,0,0,0,0,0,2,2,2,2,4,0,0,0,0,0,0,0,0,0,8,7,0,0,0,0,0,0,0,0,0,0,0,0,0,0,0,0,4,1,1,1,1,0,0,0,0,0,0
0,0,0,0,0,0,0,0,0,0,0,2,2,2,2,4,0,0,0,0,0,0,0,0,0,8,7,0,0,0,0,0,0,0,0,0,0,0,0,0,0,0,0,4,1,1,1,1,0,0,0,0,0,0
0,0,0,0,0,0,0,0,0,0,0,2,2,2,2,4,0,0,0,0,0,0,0,0,0,8,7,0,0,0,0,0,0,0,0,0,0,0,0,0,0,0,0,4,1,1,1,1,0,0,0,0,0,0
0,0,0,0,0,0,0,0,0,0,0,2,2,2,2,4,0,0,0,0,0,0,0,0,0,8,7,0,0,0,0,0,0,0,0,0,0,0,0,0,0,0,0,4,1,1,1,1,0,0,0,0,0,0
0,0,0,0,0,0,0,0,0,0,0,2,2,2,2,4,0,0,0,0,0,0,0,0,0,8,7,0,0,0,0,0,0,0,0,0,0,0,0,0,0,0,0,4,1,1,1,1,0,0,0,0,0,0
0,0,0,0,0,0,0,0,0,0,0,2,2,2,2,4,0,0,0,0,0,0,0,0,0,8,7,0,0,0,0,0,0,0,0,0,0,0,0,0,0,0,0,4,1,1,1,1,0,0,0,0,0,0
0,0,0,0,0,0,0,0,0,0,0,2,2,2,2,4,0,0,0,0,0,0,0,0,0,8,7,0,0,0,0,0,0,0,0,0,0,0,0,0,0,0,0,4,1,1,1,1,0,0,0,0,0,0
0,0,0,0,0,0,0,0,0,0,0,2,2,2,2,4,0,0,0,0,0,0,0,0,0,8,7,0,0,0,0,0,0,0,0,0,0,0,0,0,0,0,0,4,1,1,1,1,0,0,0,0,0,0
0,0,0,0,0,0,0,0,0,0,0,2,2,2,2,4,0,0,0,0,0,0,0,0,0,8,7,0,0,0,0,0,0,0,0,0,0,0,0,0,0,0,0,4,1,1,1,1,0,0,0,0,0,0
0,0,0,0,0,0,0,0,0,0,0,2,2,2,2,4,0,0,0,0,0,0,0,0,0,8,7,0,0,0,0,0,0,0,0,0,0,0,0,0,0,0,0,4,1,1,1,1,0,0,0,0,0,0
0,0,0,0,0,0,0,0,0,0,0,2,2,2,2,4,0,0,0,0,0,0,0,0,0,8,7,0,0,0,0,0,0,0,0,0,0,0,0,0,0,0,0,4,1,1,1,1,0,0,0,0,0,0
0,0,0,0,0,0,0,0,0,0,0,2,2,2,2,4,0,0,0,0,0,0,0,0,0,8,7,0,0,0,0,0,0,0,0,0,0,0,0,0,0,0,0,4,1,1,1,1,0,0,0,0,0,0
0,0,0,0,0,0,0,0,0,0,0,2,2,2,2,4,0,0,0,0,0,0,0,0,0,8,7,0,0,0,0,0,0,0,0,0,0,0,0,0,0,0,0,4,1,1,1,1,0,0,0,0,0,0
0,0,0,0,0,0,0,0,0,0,0,2,2,2,2,4,0,0,0,0,0,0,0,0,0,8,7,0,0,0,0,0,0,0,0,0,0,0,0,0,0,0,0,4,1,1,1,1,0,0,0,0,0,0
0,0,0,0,0,0,0,0,0,0,0,1,1,1,1,4,0,0,0,0,0,0,0,0,0,8,7,0,0,0,0,0,0,0,0,0,0,0,0,0,0,0,0,4,1,1,1,1,0,0,0,0,0,0
0,0,0,0,0,0,0,0,0,0,0,1,1,1,1,4,0,0,0,0,0,0,0,0,0,8,7,0,0,0,0,0,0,0,0,0,0,0,0,0,0,0,0,4,1,1,1,1,0,0,0,0,0,0
0,0,0,0,0,0,0,0,0,0,0,1,1,1,1,4,0,0,0,0,0,0,0,0,0,0,8,7,7,7,7,7,0,0,0,0,0,0,0,0,0,0,0,4,1,1,1,1,0,0,0,0,0,0
0,0,0,0,0,0,0,0,0,0,0,1,1,1,1,4,4,4,4,4,0,0,0,0,0,0,0,6,6,6,6,6,0,0,0,0,0,0,0,0,0,0,0,4,1,1,1,1,0,0,0,0,0,0
0,0,0,0,0,0,0,0,0,0,0,0,0,0,0,1,1,1,1,4,0,0,0,0,0,0,6,6,0,0,0,6,0,0,0,0,0,0,0,0,0,0,0,4,1,1,1,1,0,0,0,0,0,0
0,0,0,0,0,0,0,0,0,0,0,0,0,0,0,1,1,1,1,4,0,0,0,0,0,6,6,6,0,0,0,6,0,0,0,0,0,0,0,0,0,0,0,4,1,1,1,1,0,0,0,0,0,0
0,0,0,0,0,0,0,0,0,0,0,0,0,0,0,1,1,1,1,4,0,0,0,0,0,6,6,6,0,0,0,6,0,0,0,0,0,0,0,0,0,0,0,4,1,1,1,1,0,0,0,0,0,0
0,0,0,0,0,0,0,0,0,0,0,0,0,0,0,1,1,1,1,4,4,4,4,4,4,4,4,6,6,6,6,6,0,0,0,0,0,0,0,0,0,0,0,4,1,1,1,1,0,0,0,0,0,0
0,0,0,0,0,0,0,0,0,0,0,0,0,0,0,0,0,0,1,1,1,1,1,1,1,1,1,4,4,4,4,4,4,4,4,4,4,4,4,4,4,4,4,1,1,1,1,1,0,0,0,0,0,0
0,0,0,0,0,0,0,0,0,0,0,0,0,0,0,0,0,0,1,1,1,1,1,1,1,1,1,2,2,2,2,2,2,2,2,2,2,2,2,2,2,2,2,1,1,1,1,1,0,0,0,0,0,0
0,0,0,0,0,0,0,0,0,0,0,0,0,0,0,0,0,0,1,1,1,1,1,1,1,1,1,2,2,2,2,2,2,2,2,2,2,2,2,2,2,2,2,1,1,1,1,1,0,0,0,0,0,0
0,0,0,0,0,0,0,0,0,0,0,0,0,0,0,0,0,0,1,1,1,1,1,1,1,1,1,2,2,2,2,2,2,2,2,2,2,2,2,2,2,2,2,1,1,1,1,1,0,0,0,0,0,0
endlayer

layer
0,0,0,0,0,0,0,0,0,0,0,0,0,0,0,1,1,1,1,1,1,1,1,1,1,1,1,2,2,2,2,2,2,2,2,2,2,2,2,2,2,2,2,1,1,1,1,1,0,0,0,0,0,0
0,0,0,0,0,0,0,0,0,0,0,0,0,0,0,1,1,1,1,1,1,1,1,1,1,1,1,2,2,2,2,2,2,2,2,2,2,2,2,2,2,2,2,1,1,1,1,1,0,0,0,0,0,0
0,0,0,0,0,0,0,0,0,0,0,0,0,0,0,1,1,1,1,1,1,1,1,1,1,1,1,2,2,2,2,2,2,2,2,2,2,2,2,2,2,2,2,1,1,1,1,1,0,0,0,0,0,0
0,0,0,0,0,0,0,0,0,0,0,0,0,0,0,1,1,1,1,1,1,1,1,1,1,1,1,4,4,4,4,4,4,4,4,4,4,4,4,4,4,4,4,1,1,1,1,1,0,0,0,0,0,0
0,0,0,0,0,0,0,0,0,0,0,1,1,1,1,4,4,4,4,4,4,4,4,4,4,4,4,6,6,6,6,6,0,0,0,0,0,0,0,0,0,0,0,4,1,1,1,1,0,0,0,0,0,0
0,0,0,0,0,0,0,0,0,0,0,1,1,1,1,4,4,4,4,4,0,0,0,0,0,0,6,6,0,0,0,6,0,0,0,0,0,0,0,0,0,0,0,4,1,1,1,1,0,0,0,0,0,0
0,0,0,0,0,0,0,0,0,0,0,1,1,1,1,4,4,4,4,4,0,0,0,0,0,6,6,6,0,0,0,6,0,0,0,0,0,0,0,0,0,0,0,4,1,1,1,1,0,0,0,0,0,0
0,0,0,0,0,0,0,0,0,0,0,1,1,1,1,4,4,4,4,4,0,0,0,0,0,0,6,6,0,0,0,6,0,0,0,0,0,0,0,0,0,0,0,4,1,1,1,1,0,0,0,0,0,0
0,0,0,0,0,0,0,0,0,0,0,1,1,1,1,4,4,4,4,4,0,0,0,0,0,0,0,6,6,6,6,6,0,0,0,0,0,0,0,0,0,0,0,4,1,1,1,1,0,0,0,0,0,0
0,0,0,0,0,0,0,0,0,0,0,1,1,1,1,4,0,0,0,0,0,0,0,0,0,0,8,7,7,7,7,7,0,0,0,0,0,0,0,0,0,0,0,4,1,1,1,1,0,0,0,0,0,0
0,0,0,0,0,0,0,0,0,0,0,1,1,1,1,4,0,0,0,0,0,0,0,0,0,8,7,0,0,0,0,0,0,0,0,0,0,0,0,0,0,0,0,4,1,1,1,1,0,0,0,0,0,0
0,0,0,0,0,0,0,0,0,0,0,1,1,1,1,4,0,0,0,0,0,0,0,0,0,8,7,0,0,0,0,0,0,0,0,0,0,0,0,0,0,0,0,4,1,1,1,1,0,0,0,0,0,0
0,0,0,0,0,0,0,0,0,0,0,2,2,2,2,4,0,0,0,0,0,0,0,0,0,8,7,0,0,0,0,0,0,0,0,0,0,0,0,0,0,0,0,4,1,1,1,1,0,0,0,0,0,0
0,0,0,0,0,0,0,0,0,0,0,2,2,2,2,4,0,0,0,0,0,0,0,0,0,8,7,0,0,0,0,0,0,0,0,0,0,0,0,0,0,0,0,4,1,1,1,1,0,0,0,0,0,0
0,0,0,0,0,0,0,0,0,0,0,2,2,2,2,4,0,0,0,0,0,0,0,0,0,8,7,0,0,0,0,0,0,0,0,0,0,0,0,0,0,0,0,4,1,1,1,1,0,0,0,0,0,0
0,0,0,0,0,0,0,0,0,0,0,2,2,2,2,4,0,0,0,0,0,0,0,0,0,8,7,0,0,0,0,0,0,0,0,0,0,0,0,0,0,0,0,4,1,1,1,1,0,0,0,0,0,0
0,0,0,0,0,0,0,0,0,0,0,2,2,2,2,4,0,0,0,0,0,0,0,0,0,8,7,0,0,0,0,0,0,0,0,0,0,0,0,0,0,0,0,4,1,1,1,1,0,0,0,0,0,0
0,0,0,0,0,0,0,0,0,0,0,2,2,2,2,4,0,0,0,0,0,0,0,0,0,8,7,0,0,0,0,0,0,0,0,0,0,0,0,0,0,0,0,4,1,1,1,1,0,0,0,0,0,0
0,0,0,0,0,0,0,0,0,0,0,2,2,2,2,4,0,0,0,0,0,0,0,0,0,8,7,0,0,0,0,0,0,0,0,0,0,0,0,0,0,0,0,4,1,1,1,1,0,0,0,0,0,0
0,0,0,0,0,0,0,0,0,0,0,2,2,2,2,4,0,0,0,0,0,0,0,0,0,8,7,0,0,0,0,0,0,0,0,0,0,0,0,0,0,0,0,4,1,1,1,1,0,0,0,0,0,0
0,0,0,0,0,0,0,0,0,0,0,2,2,2,2,4,0,0,0,0,0,0,0,0,0,8,7,0,0,0,0,0,0,0,0,0,0,0,0,0,0,0,0,4,1,1,1,1,0,0,0,0,0,0
0,0,0,0,0,0,0,0,0,0,0,2,2,2,2,4,0,0,0,0,0,0,0,0,0,8,7,0,0,0,0,0,0,0,0,0,0,0,0,0,0,0,0,4,1,1,1,1,0,0,0,0,0,0
0,0,0,0,0,0,0,0,0,0,0,2,2,2,2,4,0,0,0,0,0,0,0,0,0,8,7,0,0,0,0,0,0,0,0,0,0,0,0,0,0,0,0,4,1,1,1,1,0,0,0,0,0,0
0,0,0,0,0,0,0,0,0,0,0,2,2,2,2,4,0,0,0,0,0,0,0,0,0,8,7,0,0,0,0,0,0,0,0,0,0,0,0,0,0,0,0,4,1,1,1,1,0,0,0,0,0,0
0,0,0,0,0,0,0,0,0,0,0,2,2,2,2,4,0,0,0,0,0,0,0,0,0,8,7,0,0,0,0,0,0,0,0,0,0,0,0,0,0,0,0,4,1,1,1,1,0,0,0,0,0,0
0,0,0,0,0,0,0,0,0,0,0,2,2,2,2,4,0,0,0,0,0,0,0,0,0,8,7,0,0,0,0,0,0,0,0,0,0,0,0,0,0,0,0,4,1,1,1,1,0,0,0,0,0,0
0,0,0,0,0,0,0,0,0,0,0,2,2,2,2,4,0,0,0,0,0,0,0,0,0,8,7,0,0,0,0,0,0,0,0,0,0,0,0,0,0,0,0,4,1,1,1,1,0,0,0,0,0,0
0,0,0,0,0,0,0,0,0,0,0,2,2,2,2,4,0,0,0,0,0,0,0,0,0,8,7,0,0,0,0,0,0,0,0,0,0,0,0,0,0,0,0,4,1,1,1,1,0,0,0,0,0,0
0,0,0,0,0,0,0,0,0,0,0,2,2,2,2,4,0,0,0,0,0,0,0,0,0,8,7,0,0,0,0,0,0,0,0,0,0,0,0,0,0,0,0,4,1,1,1,1,0,0,0,0,0,0
0,0,0,0,0,0,0,0,0,0,0,2,2,2,2,4,0,0,0,0,0,0,0,0,0,8,7,0,0,0,0,0,0,0,0,0,0,0,0,0,0,0,0,4,1,1,1,1,0,0,0,0,0,0
0,0,0,0,0,0,0,0,0,0,0,2,2,2,2,4,0,0,0,0,0,0,0,0,0,8,7,0,0,0,0,0,0,0,0,0,0,0,0,0,0,0,0,4,1,1,1,1,0,0,0,0,0,0
0,0,0,0,0,0,0,0,0,0,0,2,2,2,2,4,0,0,0,0,0,0,0,0,0,8,7,0,0,0,0,0,0,0,0,0,0,0,0,0,0,0,0,4,1,1,1,1,0,0,0,0,0,0
0,0,0,0,0,0,0,0,0,0,0,1,1,1,1,4,0,0,0,0,0,0,0,0,0,8,7,0,0,0,0,0,0,0,0,0,0,0,0,0,0,0,0,4,1,1,1,1,0,0,0,0,0,0
0,0,0,0,0,0,0,0,0,0,0,1,1,1,1,4,0,0,0,0,0,0,0,0,0,8,7,0,0,0,0,0,0,0,0,0,0,0,0,0,0,0,0,4,1,1,1,1,0,0,0,0,0,0
0,0,0,0,0,0,0,0,0,0,0,1,1,1,1,4,0,0,0,0,0,0,0,0,0,0,8,7,7,7,7,7,0,0,0,0,0,0,0,0,0,0,0,4,1,1,1,1,0,0,0,0,0,0
0,0,0,0,0,0,0,0,0,0,0,1,1,1,1,4,4,4,4,4,0,0,0,0,0,0,0,6,6,6,6,6,0,0,0,0,0,0,0,0,0,0,0,4,1,1,1,1,0,0,0,0,0,0
0,0,0,0,0,0,0,0,0,0,0,1,1,1,1,4,4,4,4,4,0,0,0,0,0,0,6,6,0,0,0,6,0,0,0,0,0,0,0,0,0,0,0,4,1,1,1,1,0,0,0,0,0,0
0,0,0,0,0,0,0,0,0,0,0,1,1,1,1,4,4,4,4,4,0,0,0,0,0,6,6,6,0,0,0,6,0,0,0,0,0,0,0,0,0,0,0,4,1,1,1,1,0,0,0,0,0,0
0,0,0,0,0,0,0,0,0,0,0,1,1,1,1,4,4,4,4,4,0,0,0,0,0,6,6,6,0,0,0,6,0,0,0,0,0,0,0,0,0,0,0,4,1,1,1,1,0,0,0,0,0,0
0,0,0,0,0,0,0,0,0,0,0,1,1,1,1,4,4,4,4,4,4,4,4,4,4,4,4,6,6,6,6,6,0,0,0,0,0,0,0,0,0,0,0,4,1,1,1,1,0,0,0,0,0,0
0,0,0,0,0,0,0,0,0,0,0,0,0,0,0,1,1,1,1,1,1,1,1,1,1,1,1,4,4,4,4,4,4,4,4,4,4,4,4,4,4,4,4,1,1,1,1,1,0,0,0,0,0,0
0,0,0,0,0,0,0,0,0,0,0,0,0,0,0,1,1,1,1,1,1,1,1,1,1,1,1,2,2,2,2,2,2,2,2,2,2,2,2,2,2,2,2,1,1,1,1,1,0,0,0,0,0,0
0,0,0,0,0,0,0,0,0,0,0,0,0,0,0,1,1,1,1,1,1,1,1,1,1,1,1,2,2,2,2,2,2,2,2,2,2,2,2,2,2,2,2,1,1,1,1,1,0,0,0,0,0,0
0,0,0,0,0,0,0,0,0,0,0,0,0,0,0,1,1,1,1,1,1,1,1,1,1,1,1,2,2,2,2,2,2,2,2,2,2,2,2,2,2,2,2,1,1,1,1,1,0,0,0,0,0,0
endlayer

layer
0,0,0,0,0,0,0,0,0,0,0,0,0,0,0,1,1,1,1,1,1,1,1,1,1,1,1,2,2,2,2,2,2,2,2,2,2,2,2,2,2,2,2,1,1,1,1,1,0,0,0,0,0,0
0,0,0,0,0,0,0,0,0,0,0,0,0,0,0,1,1,1,1,1,1,1,1,1,1,1,1,2,2,2,2,2,2,2,2,2,2,2,2,2,2,2,2,1,1,1,1,1,0,0,0,0,0,0
0,0,0,0,0,0,0,0,0,0,0,0,0,0,0,1,1,1,1,1,1,1,1,1,1,1,1,2,2,2,2,2,2,2,2,2,2,2,2,2,2,2,2,1,1,1,1,1,0,0,0,0,0,0
0,0,0,0,0,0,0,0,0,0,0,0,0,0,0,1,1,1,1,1,1,1,1,1,1,1,1,4,4,4,4,4,4,4,4,4,4,4,4,4,4,4,4,1,1,1,1,1,0,0,0,0,0,0
0,0,0,0,0,0,0,0,0,0,0,1,1,1,1,4,4,4,4,4,4,4,4,4,4,4,4,6,6,6,6,6,0,0,0,0,0,0,0,0,0,0,0,4,1,1,1,1,0,0,0,0,0,0
0,0,0,0,0,0,0,0,0,0,0,1,1,1,1,4,0,0,0,0,0,0,0,0,0,0,6,6,0,0,0,6,0,0,0,0,0,0,0,0,0,0,0,4,1,1,1,1,0,0,0,0,0,0
0,0,0,0,0,0,0,0,0,0,0,1,1,1,1,4,0,0,0,0,0,0,0,0,0,6,6,6,0,0,0,6,0,0,0,0,0,0,0,0,0,0,0,4,1,1,1,1,0,0,0,0,0,0
0,0,0,0,0,0,0,0,0,0,0,1,1,1,1,4,0,0,0,0,0,0,0,0,0,0,6,6,0,0,0,6,0,0,0,0,0,0,0,0,0,0,0,4,1,1,1,1,0,0,0,0,0,0
0,0,0,0,0,0,0,0,0,0,0,1,1,1,1,4,0,0,0,0,0,0,0,0,0,0,0,6,6,6,6,6,0,0,0,0,0,0,0,0,0,0,0,4,1,1,1,1,0,0,0,0,0,0
0,0,0,0,0,0,0,0,0,0,0,1,1,1,1,4,0,0,0,0,0,0,0,0,0,0,8,7,7,7,7,7,0,0,0,0,0,0,0,0,0,0,0,4,1,1,1,1,0,0,0,0,0,0
0,0,0,0,0,0,0,0,0,0,0,1,1,1,1,4,0,0,0,0,0,0,0,0,0,0,8,7,7,7,7,7,0,0,0,0,0,0,0,0,0,0,0,4,1,1,1,1,0,0,0,0,0,0
0,0,0,0,0,0,0,0,0,0,0,1,1,1,1,4,0,0,0,0,0,0,0,0,0,0,8,7,7,7,7,7,0,0,0,0,0,0,0,0,0,0,0,4,1,1,1,1,0,0,0,0,0,0
0,0,0,0,0,0,0,0,0,0,0,2,2,2,2,4,0,0,0,0,0,0,0,0,0,0,8,7,7,7,7,7,0,0,0,0,0,0,0,0,0,0,0,4,1,1,1,1,0,0,0,0,0,0
0,0,0,0,0,0,0,0,0,0,0,2,2,2,2,4,0,0,0,0,0,0,0,0,0,0,8,7,7,7,7,7,0,0,0,0,0,0,0,0,0,0,0,4,1,1,1,1,0,0,0,0,0,0
0,0,0,0,0,0,0,0,0,0,0,2,2,2,2,4,0,0,0,0,0,0,0,0,0,0,8,7,7,7,7,7,0,0,0,0,0,0,0,0,0,0,0,4,1,1,1,1,0,0,0,0,0,0
0,0,0,0,0,0,0,0,0,0,0,2,2,2,2,4,0,0,0,0,0,0,0,0,0,0,8,7,7,7,7,7,0,0,0,0,0,0,0,0,0,0,0,4,1,1,1,1,0,0,0,0,0,0
0,0,0,0,0,0,0,0,0,0,0,2,2,2,2,4,0,0,0,0,0,0,0,0,0,0,8,7,7,7,7,7,0,0,0,0,0,0,0,0,0,0,0,4,1,1,1,1,0,0,0,0,0,0
0,0,0,0,0,0,0,0,0,0,0,2,2,2,2,4,0,0,0,0,0,0,0,0,0,0,8,7,7,7,7,7,0,0,0,0,0,0,0,0,0,0,0,4,1,1,1,1,0,0,0,0,0,0
0,0,0,0,0,0,0,0,0,0,0,2,2,2,2,4,0,0,0,0,0,0,0,0,0,0,8,7,7,7,7,7,0,0,0,0,0,0,0,0,0,0,0,4,1,1,1,1,0,0,0,0,0,0
0,0,0,0,0,0,0,0,0,0,0,2,2,2,2,4,0,0,0,0,0,0,0,0,0,0,8,7,7,7,7,7,0,0,0,0,0,0,0,0,0,0,0,4,1,1,1,1,0,0,0,0,0,0
0,0,0,0,0,0,0,0,0,0,0,2,2,2,2,4,0,0,0,0,0,0,0,0,0,0,8,7,7,7,7,7,0,0,0,0,0,0,0,0,0,0,0,4,1,1,1,1,0,0,0,0,0,0
0,0,0,0,0,0,0,0,0,0,0,2,2,2,2,4,0,0,0,0,0,0,0,0,0,0,8,7,7,7,7,7,0,0,0,0,0,0,0,0,0,0,0,4,1,1,1,1,0,0,0,0,0,0
0,0,0,0,0,0,0,0,0,0,0,2,2,2,2,4,0,0,0,0,0,0,0,0,0,0,8,7,7,7,7,7,0,0,0,0,0,0,0,0,0,0,0,4,1,1,1,1,0,0,0,0,0,0
0,0,0,0,0,0,0,0,0,0,0,2,2,2,2,4,0,0,0,0,0,0,0,0,0,0,8,7,7,7,7,7,0,0,0,0,0,0,0,0,0,0,0,4,1,1,1,1,0,0,0,0,0,0
0,0,0,0,0,0,0,0,0,0,0,2,2,2,2,4,0,0,0,0,0,0,0,0,0,0,8,7,7,7,7,7,0,0,0,0,0,0,0,0,0,0,0,4,1,1,1,1,0,0,0,0,0,0
0,0,0,0,0,0,0,0,0,0,0,2,2,2,2,4,0,0,0,0,0,0,0,0,0,0,8,7,7,7,7,7,0,0,0,0,0,0,0,0,0,0,0,4,1,1,1,1,0,0,0,0,0,0
0,0,0,0,0,0,0,0,0,0,0,2,2,2,2,4,0,0,0,0,0,0,0,0,0,0,8,7,7,7,7,7,0,0,0,0,0,0,0,0,0,0,0,4,1,1,1,1,0,0,0,0,0,0
0,0,0,0,0,0,0,0,0,0,0,2,2,2,2,4,0,0,0,0,0,0,0,0,0,0,8,7,7,7,7,7,0,0,0,0,0,0,0,0,0,0,0,4,1,1,1,1,0,0,0,0,0,0
0,0,0,0,0,0,0,0,0,0,0,2,2,2,2,4,0,0,0,0,0,0,0,0,0,0,8,7,7,7,7,7,0,0,0,0,0,0,0,0,0,0,0,4,1,1,1,1,0,0,0,0,0,0
0,0,0,0,0,0,0,0,0,0,0,2,2,2,2,4,0,0,0,0,0,0,0,0,0,0,8,7,7,7,7,7,0,0,0,0,0,0,0,0,0,0,0,4,1,1,1,1,0,0,0,0,0,0
0,0,0,0,0,0,0,0,0,0,0,2,2,2,2,4,0,0,0,0,0,0,0,0,0,0,8,7,7,7,7,7,0,0,0,0,0,0,0,0,0,0,0,4,1,1,1,1,0,0,0,0,0,0
0,0,0,0,0,0,0,0,0,0,0,2,2,2,2,4,0,0,0,0,0,0,0,0,0,0,8,7,7,7,7,7,0,0,0,0,0,0,0,0,0,0,0,4,1,1,1,1,0,0,0,0,0,0
0,0,0,0,0,0,0,0,0,0,0,1,1,1,1,4,0,0,0,0,0,0,0,0,0,8,7,0,0,0,0,0,0,0,0,0,0,0,0,0,0,0,0,4,1,1,1,1,0,0,0,0,0,0
0,0,0,0,0,0,0,0,0,0,0,1,1,1,1,4,0,0,0,0,0,0,0,0,0,8,7,0,0,0,0,0,0,0,0,0,0,0,0,0,0,0,0,4,1,1,1,1,0,0,0,0,0,0
0,0,0,0,0,0,0,0,0,0,0,1,1,1,1,4,0,0,0,0,0,0,0,0,0,0,8,7,7,7,7,7,0,0,0,0,0,0,0,0,0,0,0,4,1,1,1,1,0,0,0,0,0,0
0,0,0,0,0,0,0,0,0,0,0,1,1,1,1,4,0,0,0,0,0,0,0,0,0,0,0,6,6,6,6,6,0,0,0,0,0,0,0,0,0,0,0,4,1,1,1,1,0,0,0,0,0,0
0,0,0,0,0,0,0,0,0,0,0,1,1,1,1,4,0,0,0,0,0,0,0,0,0,0,6,6,0,0,0,6,0,0,0,0,0,0,0,0,0,0,0,4,1,1,1,1,0,0,0,0,0,0
0,0,0,0,0,0,0,0,0,0,0,1,1,1,1,4,0,0,0,0,0,0,0,0,0,6,6,6,0,0,0,6,0,0,0,0,0,0,0,0,0,0,0,4,1,1,1,1,0,0,0,0,0,0
0,0,0,0,0,0,0,0,0,0,0,1,1,1,1,4,0,0,0,0,0,0,0,0,0,6,6,6,0,0,0,6,0,0,0,0,0,0,0,0,0,0,0,4,1,1,1,1,0,0,0,0,0,0
0,0,0,0,0,0,0,0,0,0,0,1,1,1,1,4,4,4,4,4,4,4,4,4,4,4,4,6,6,6,6,6,0,0,0,0,0,0,0,0,0,0,0,4,1,1,1,1,0,0,0,0,0,0
0,0,0,0,0,0,0,0,0,0,0,0,0,0,0,1,1,1,1,1,1,1,1,1,1,1,1,4,4,4,4,4,4,4,4,4,4,4,4,4,4,4,4,1,1,1,1,1,0,0,0,0,0,0
0,0,0,0,0,0,0,0,0,0,0,0,0,0,0,1,1,1,1,1,1,1,1,1,1,1,1,2,2,2,2,2,2,2,2,2,2,2,2,2,2,2,2,1,1,1,1,1,0,0,0,0,0,0
0,0,0,0,0,0,0,0,0,0,0,0,0,0,0,1,1,1,1,1,1,1,1,1,1,1,1,2,2,2,2,2,2,2,2,2,2,2,2,2,2,2,2,1,1,1,1,1,0,0,0,0,0,0
0,0,0,0,0,0,0,0,0,0,0,0,0,0,0,1,1,1,1,1,1,1,1,1,1,1,1,2,2,2,2,2,2,2,2,2,2,2,2,2,2,2,2,1,1,1,1,1,0,0,0,0,0,0
endlayer

layer
0,0,0,0,0,0,0,0,0,0,0,0,0,0,0,1,1,1,1,1,1,1,1,1,1,1,1,2,2,2,2,2,2,2,2,2,2,2,2,2,2,2,2,1,1,1,1,1,0,0,0,0,0,0
0,0,0,0,0,0,0,0,0,0,0,0,0,0,0,1,1,1,1,1,1,1,1,1,1,1,1,2,2,2,2,2,2,2,2,2,2,2,2,2,2,2,2,1,1,1,1,1,0,0,0,0,0,0
0,0,0,0,0,0,0,0,0,0,0,0,0,0,0,1,1,1,1,1,1,1,1,1,1,1,1,2,2,2,2,2,2,2,2,2,2,2,2,2,2,2,2,1,1,1,1,1,0,0,0,0,0,0
0,0,0,0,0,0,0,0,0,0,0,0,0,0,0,1,1,1,1,1,1,1,1,1,1,1,1,4,4,4,4,4,4,4,4,4,4,4,4,4,4,4,4,1,1,1,1,1,0,0,0,0,0,0
0,0,0,0,0,0,0,0,0,0,0,1,1,1,1,4,4,4,4,4,4,4,4,4,4,4,4,6,6,6,6,6,0,0,0,0,0,0,0,0,0,0,0,4,1,1,1,1,0,0,0,0,0,0
0,0,0,0,0,0,0,0,0,0,0,1,1,1,1,4,0,0,0,0,0,0,0,0,0,0,6,6,0,0,0,6,0,0,0,0,0,0,0,0,0,0,0,4,1,1,1,1,0,0,0,0,0,0
0,0,0,0,0,0,0,0,0,0,0,1,1,1,1,4,0,0,0,0,0,0,0,0,0,6,6,6,0,0,0,6,0,0,0,0,0,0,0,0,0,0,0,4,1,1,1,1,0,0,0,0,0,0
0,0,0,0,0,0,0,0,0,0,0,1,1,1,1,4,0,0,0,0,0,0,0,0,0,0,6,6,0,0,0,6,0,0,0,0,0,0,0,0,0,0,0,4,1,1,1,1,0,0,0,0,0,0
0,0,0,0,0,0,0,0,0,0,0,1,1,1,1,4,0,0,0,0,0,0,0,0,0,0,0,6,6,6,6,6,0,0,0,0,0,0,0,0,0,0,0,4,1,1,1,1,0,0,0,0,0,0
0,0,0,0,0,0,0,0,0,0,0,1,1,1,1,4,0,0,0,0,0,0,0,0,0,0,8,7,7,7,7,7,0,0,0,0,0,0,0,0,0,0,0,4,1,1,1,1,0,0,0,0,0,0
0,0,0,0,0,0,0,0,0,0,0,1,1,1,1,4,0,0,0,0,0,0,0,0,0,8,7,0,0,0,0,0,0,0,0,0,0,0,0,0,0,0,0,4,1,1,1,1,0,0,0,0,0,0
0,0,0,0,0,0,0,0,0,0,0,1,1,1,1,4,0,0,0,0,0,0,0,0,0,8,7,0,0,0,0,0,0,0,0,0,0,0,0,0,0,0,0,4,1,1,1,1,0,0,0,0,0,0
0,0,0,0,0,0,0,0,0,0,0,2,2,2,2,4,0,0,0,0,0,0,0,0,0,8,7,0,0,0,0,0,0,0,0,0,0,0,0,0,0,0,0,4,1,1,1,1,0,0,0,0,0,0
0,0,0,0,0,0,0,0,0,0,0,2,2,2,2,4,0,0,0,0,0,0,0,0,0,8,7,0,0,0,0,0,0,0,0,0,0,0,0,0,0,0,0,4,1,1,1,1,0,0,0,0,0,0
0,0,0,0,0,0,0,0,0,0,0,2,2,2,2,4,0,0,0,0,0,0,0,0,0,8,7,0,0,0,0,0,0,0,0,0,0,0,0,0,0,0,0,4,1,1,1,1,0,0,0,0,0,0
0,0,0,0,0,0,0,0,0,0,0,2,2,2,2,4,0,0,0,0,0,0,0,0,0,8,7,0,0,0,0,0,0,0,0,0,0,0,0,0,0,0,0,4,1,1,1,1,0,0,0,0,0,0
0,0,0,0,0,0,0,0,0,0,0,2,2,2,2,4,0,0,0,0,0,0,0,0,0,8,7,0,0,0,0,0,0,0,0,0,0,0,0,0,0,0,0,4,1,1,1,1,0,0,0,0,0,0
0,0,0,0,0,0,0,0,0,0,0,2,2,2,2,4,0,0,0,0,0,0,0,0,0,8,7,0,0,0,0,0,0,0,0,0,0,0,0,0,0,0,0,4,1,1,1,1,0,0,0,0,0,0
0,0,0,0,0,0,0,0,0,0,0,2,2,2,2,4,0,0,0,0,0,0,0,0,0,8,7,0,0,0,0,0,0,0,0,0,0,0,0,0,0,0,0,4,1,1,1,1,0,0,0,0,0,0
0,0,0,0,0,0,0,0,0,0,0,2,2,2,2,4,0,0,0,0,0,0,0,0,0,8,7,0,0,0,0,0,0,0,0,0,0,0,0,0,0,0,0,4,1,1,1,1,0,0,0,0,0,0
0,0,0,0,0,0,0,0,0,0,0,2,2,2,2,4,0,0,0,0,0,0,0,0,0,8,7,0,0,0,0,0,0,0,0,0,0,0,0,0,0,0,0,4,1,1,1,1,0,0,0,0,0,0
0,0,0,0,0,0,0,0,0,0,0,2,2,2,2,4,0,0,0,0,0,0,0,0,0,8,7,0,0,0,0,0,0,0,0,0,0,0,0,0,0,0,0,4,1,1,1,1,0,0,0,0,0,0
0,0,0,0,0,0,0,0,0,0,0,2,2,2,2,4,0,0,0,0,0,0,0,0,0,8,7,0,0,0,0,0,0,0,0,0,0,0,0,0,0,0,0,4,1,1,1,1,0,0,0,0,0,0
0,0,0,0,0,0,0,0,0,0,0,2,2,2,2,4,0,0,0,0,0,0,0,0,0,8,7,0,0,0,0,0,0,0,0,0,0,0,0,0,0,0,0,4,1,1,1,1,0,0,0,0,0,0
0,0,0,0,0,0,0,0,0,0,0,2,2,2,2,4,0,0,0,0,0,0,0,0,0,8,7,0,0,0,0,0,0,0,0,0,0,0,0,0,0,0,0,4,1,1,1,1,0,0,0,0,0,0
0,0,0,0,0,0,0,0,0,0,0,2,2,2,2,4,0,0,0,0,0,0,0,0,0,8,7,0,0,0,0,0,0,0,0,0,0,0,0,0,0,0,0,4,1,1,1,1,0,0,0,0,0,0
0,0,0,0,0,0,0,0,0,0,0,2,2,2,2,4,0,0,0,0,0,0,0,0,0,8,7,0,0,0,0,0,0,0,0,0,0,0,0,0,0,0,0,4,1,1,1,1,0,0,0,0,0,0
0,0,0,0,0,0,0,0,0,0,0,2,2,2,2,4,0,0,0,0,0,0,0,0,0,8,7,0,0,0,0,0,0,0,0,0,0,0,0,0,0,0,0,4,1,1,1,1,0,0,0,0,0,0
0,0,0,0,0,0,0,0,0,0,0,2,2,2,2,4,0,0,0,0,0,0,0,0,0,8,7,0,0,0,0,0,0,0,0,0,0,0,0,0,0,0,0,4,1,1,1,1,0,0,0,0,0,0
0,0,0,0,0,0,0,0,0,0,0,2,2,2,2,4,0,0,0,0,0,0,0,0,0,8,7,0,0,0,0,0,0,0,0,0,0,0,0,0,0,0,0,4,1,1,1,1,0,0,0,0,0,0
0,0,0,0,0,0,0,0,0,0,0,2,2,2,2,4,0,0,0,0,0,0,0,0,0,8,7,0,0,0,0,0,0,0,0,0,0,0,0,0,0,0,0,4,1,1,1,1,0,0,0,0,0,0
0,0,0,0,0,0,0,0,0,0,0,2,2,2,2,4,0,0,0,0,0,0,0,0,0,8,7,0,0,0,0,0,0,0,0,0,0,0,0,0,0,0,0,4,1,1,1,1,0,0,0,0,0,0
0,0,0,0,0,0,0,0,0,0,0,1,1,1,1,4,0,0,0,0,0,0,0,0,0,8,7,0,0,0,0,0,0,0,0,0,0,0,0,0,0,0,0,4,1,1,1,1,0,0,0,0,0,0
0,0,0,0,0,0,0,0,0,0,0,1,1,1,1,4,0,0,0,0,0,0,0,0,0,8,7,0,0,0,0,0,0,0,0,0,0,0,0,0,0,0,0,4,1,1,1,1,0,0,0,0,0,0
0,0,0,0,0,0,0,0,0,0,0,1,1,1,1,4,0,0,0,0,0,0,0,0,0,0,8,7,7,7,7,7,0,0,0,0,0,0,0,0,0,0,0,4,1,1,1,1,0,0,0,0,0,0
0,0,0,0,0,0,0,0,0,0,0,1,1,1,1,4,0,0,0,0,0,0,0,0,0,0,0,6,6,6,6,6,0,0,0,0,0,0,0,0,0,0,0,4,1,1,1,1,0,0,0,0,0,0
0,0,0,0,0,0,0,0,0,0,0,1,1,1,1,4,0,0,0,0,0,0,0,0,0,0,6,6,0,0,0,6,0,0,0,0,0,0,0,0,0,0,0,4,1,1,1,1,0,0,0,0,0,0
0,0,0,0,0,0,0,0,0,0,0,1,1,1,1,4,0,0,0,0,0,0,0,0,0,6,6,6,0,0,0,6,0,0,0,0,0,0,0,0,0,0,0,4,1,1,1,1,0,0,0,0,0,0
0,0,0,0,0,0,0,0,0,0,0,1,1,1,1,4,0,0,0,0,0,0,0,0,0,6,6,6,0,0,0,6,0,0,0,0,0,0,0,0,0,0,0,4,1,1,1,1,0,0,0,0,0,0
0,0,0,0,0,0,0,0,0,0,0,1,1,1,1,4,4,4,4,4,4,4,4,4,4,4,4,6,6,6,6,6,0,0,0,0,0,0,0,0,0,0,0,4,1,1,1,1,0,0,0,0,0,0
0,0,0,0,0,0,0,0,0,0,0,0,0,0,0,1,1,1,1,1,1,1,1,1,1,1,1,4,4,4,4,4,4,4,4,4,4,4,4,4,4,4,4,1,1,1,1,1,0,0,0,0,0,0
0,0,0,0,0,0,0,0,0,0,0,0,0,0,0,1,1,1,1,1,1,1,1,1,1,1,1,2,2,2,2,2,2,2,2,2,2,2,2,2,2,2,2,1,1,1,1,1,0,0,0,0,0,0
0,0,0,0,0,0,0,0,0,0,0,0,0,0,0,1,1,1,1,1,1,1,1,1,1,1,1,2,2,2,2,2,2,2,2,2,2,2,2,2,2,2,2,1,1,1,1,1,0,0,0,0,0,0
0,0,0,0,0,0,0,0,0,0,0,0,0,0,0,1,1,1,1,1,1,1,1,1,1,1,1,2,2,2,2,2,2,2,2,2,2,2,2,2,2,2,2,1,1,1,1,1,0,0,0,0,0,0
endlayer

layer
0,0,0,0,0,0,0,0,0,0,0,0,0,0,0,1,1,1,1,1,1,1,1,1,1,1,1,2,2,2,2,2,2,2,2,2,2,2,2,2,2,2,2,1,1,1,1,1,0,0,0,0,0,0
0,0,0,0,0,0,0,0,0,0,0,0,0,0,0,1,1,1,1,1,1,1,1,1,1,1,1,2,2,2,2,2,2,2,2,2,2,2,2,2,2,2,2,1,1,1,1,1,0,0,0,0,0,0
0,0,0,0,0,0,0,0,0,0,0,0,0,0,0,1,1,1,1,1,1,1,1,1,1,1,1,2,2,2,2,2,2,2,2,2,2,2,2,2,2,2,2,1,1,1,1,1,0,0,0,0,0,0
0,0,0,0,0,0,0,0,0,0,0,0,0,0,0,1,1,1,1,1,1,1,1,1,1,1,1,4,4,4,4,4,4,4,4,4,4,4,4,4,4,4,4,1,1,1,1,1,0,0,0,0,0,0
0,0,0,0,0,0,0,0,0,0,0,1,1,1,1,4,4,4,4,4,4,4,4,4,4,4,4,6,6,6,6,6,0,0,0,0,0,0,0,0,0,0,0,4,1,1,1,1,0,0,0,0,0,0
0,0,0,0,0,0,0,0,0,0,0,1,1,1,1,4,0,0,0,0,0,0,0,0,0,0,6,6,0,0,0,6,0,0,0,0,0,0,0,0,0,0,0,4,1,1,1,1,0,0,0,0,0,0
0,0,0,0,0,0,0,0,0,0,0,1,1,1,1,4,0,0,0,0,0,0,0,0,0,6,6,6,0,0,0,6,0,0,0,0,0,0,0,0,0,0,0,4,1,1,1,1,0,0,0,0,0,0
0,0,0,0,0,0,0,0,0,0,0,1,1,1,1,4,0,0,0,0,0,0,0,0,0,0,6,6,0,0,0,6,0,0,0,0,0,0,0,0,0,0,0,4,1,1,1,1,0,0,0,0,0,0
0,0,0,0,0,0,0,0,0,0,0,1,1,1,1,4,0,0,0,0,0,0,0,0,0,0,0,6,6,6,6,6,0,0,0,0,0,0,0,0,0,0,0,4,1,1,1,1,0,0,0,0,0,0
0,0,0,0,0,0,0,0,0,0,0,1,1,1,1,4,0,0,0,0,0,0,0,0,0,0,8,7,7,7,7,7,0,0,0,0,0,0,0,0,0,0,0,4,1,1,1,1,0,0,0,0,0,0
0,0,0,0,0,0,0,0,0,0,0,1,1,1,1,4,0,0,0,0,0,0,0,0,0,8,7,0,0,0,0,0,0,0,0,0,0,0,0,0,0,0,0,4,1,1,1,1,0,0,0,0,0,0
0,0,0,0,0,0,0,0,0,0,0,1,1,1,1,4,0,0,0,0,0,0,0,0,0,8,7,0,0,0,0,0,0,0,0,0,0,0,0,0,0,0,0,4,1,1,1,1,0,0,0,0,0,0
0,0,0,0,0,0,0,0,0,0,0,2,2,2,2,4,0,0,0,0,0,0,0,0,0,8,7,0,0,0,0,0,0,0,0,0,0,0,0,0,0,0,0,4,1,1,1,1,0,0,0,0,0,0
0,0,0,0,0,0,0,0,0,0,0,2,2,2,2,4,0,0,0,0,0,0,0,0,0,8,7,0,0,0,0,0,0,0,0,0,0,0,0,0,0,0,0,4,1,1,1,1,0,0,0,0,0,0
0,0,0,0,0,0,0,0,0,0,0,2,2,2,2,4,0,0,0,0,0,0,0,0,0,8,7,0,0,0,0,0,0,0,0,0,0,0,0,0,0,0,0,4,1,1,1,1,0,0,0,0,0,0
0,0,0,0,0,0,0,0,0,0,0,2,2,2,2,4,0,0,0,0,0,0,0,0,0,8,7,0,0,0,0,0,0,0,0,0,0,0,0,0,0,0,0,4,1,1,1,1,0,0,0,0,0,0
0,0,0,0,0,0,0,0,0,0,0,2,2,2,2,4,0,0,0,0,0,0,0,0,0,8,7,0,0,0,0,0,0,0,0,0,0,0,0,0,0,0,0,4,1,1,1,1,0,0,0,0,0,0
0,0,0,0,0,0,0,0,0,0,0,2,2,2,2,4,0,0,0,0,0,0,0,0,0,8,7,0,0,0,0,0,0,0,0,0,0,0,0,0,0,0,0,4,1,1,1,1,0,0,0,0,0,0
0,0,0,0,0,0,0,0,0,0,0,2,2,2,2,4,0,0,0,0,0,0,0,0,0,8,7,0,0,0,0,0,0,0,0,0,0,0,0,0,0,0,0,4,1,1,1,1,0,0,0,0,0,0
0,0,0,0,0,0,0,0,0,0,0,2,2,2,2,4,0,0,0,0,0,0,0,0,0,8,7,0,0,0,0,0,0,0,0,0,0,0,0,0,0,0,0,4,1,1,1,1,0,0,0,0,0,0
0,0,0,0,0,0,0,0,0,0,0,2,2,2,2,4,0,0,0,0,0,0,0,0,0,8,7,0,0,0,0,0,0,0,0,0,0,0,0,0,0,0,0,4,1,1,1,1,0,0,0,0,0,0
0,0,0,0,0,0,0,0,0,0,0,2,2,2,2,4,0,0,0,0,0,0,0,0,0,8,7,0,0,0,0,0,0,0,0,0,0,0,0,0,0,0,0,4,1,1,1,1,0,0,0,0,0,0
0,0,0,0,0,0,0,0,0,0,0,2,2,2,2,4,0,0,0,0,0,0,0,0,0,8,7,0,0,0,0,0,0,0,0,0,0,0,0,0,0,0,0,4,1,1,1,1,0,0,0,0,0,0
0,0,0,0,0,0,0,0,0,0,0,2,2,2,2,4,0,0,0,0,0,0,0,0,0,8,7,0,0,0,0,0,0,0,0,0,0,0,0,0,0,0,0,4,1,1,1,1,0,0,0,0,0,0
0,0,0,0,0,0,0,0,0,0,0,2,2,2,2,4,0,0,0,0,0,0,0,0,0,8,7,0,0,0,0,0,0,0,0,0,0,0,0,0,0,0,0,4,1,1,1,1,0,0,0,0,0,0
0,0,0,0,0,0,0,0,0,0,0,2,2,2,2,4,0,0,0,0,0,0,0,0,0,8,7,0,0,0,0,0,0,0,0,0,0,0,0,0,0,0,0,4,1,1,1,1,0,0,0,0,0,0
0,0,0,0,0,0,0,0,0,0,0,2,2,2,2,4,0,0,0,0,0,0,0,0,0,8,7,0,0,0,0,0,0,0,0,0,0,0,0,0,0,0,0,4,1,1,1,1,0,0,0,0,0,0
0,0,0,0,0,0,0,0,0,0,0,2,2,2,2,4,0,0,0,0,0,0,0,0,0,8,7,0,0,0,0,0,0,0,0,0,0,0,0,0,0,0,0,4,1,1,1,1,0,0,0,0,0,0
0,0,0,0,0,0,0,0,0,0,0,2,2,2,2,4,0,0,0,0,0,0,0,0,0,8,7,0,0,0,0,0,0,0,0,0,0,0,0,0,0,0,0,4,1,1,1,1,0,0,0,0,0,0
0,0,0,0,0,0,0,0,0,0,0,2,2,2,2,4,0,0,0,0,0,0,0,0,0,8,7,0,0,0,0,0,0,0,0,0,0,0,0,0,0,0,0,4,1,1,1,1,0,0,0,0,0,0
0,0,0,0,0,0,0,0,0,0,0,2,2,2,2,4,0,0,0,0,0,0,0,0,0,8,7,0,0,0,0,0,0,0,0,0,0,0,0,0,0,0,0,4,1,1,1,1,0,0,0,0,0,0
0,0,0,0,0,0,0,0,0,0,0,2,2,2,2,4,0,0,0,0,0,0,0,0,0,8,7,0,0,0,0,0,0,0,0,0,0,0,0,0,0,0,0,4,1,1,1,1,0,0,0,0,0,0
0,0,0,0,0,0,0,0,0,0,0,1,1,1,1,4,0,0,0,0,0,0,0,0,0,8,7,0,0,0,0,0,0,0,0,0,0,0,0,0,0,0,0,4,1,1,1,1,0,0,0,0,0,0
0,0,0,0,0,0,0,0,0,0,0,1,1,1,1,4,0,0,0,0,0,0,0,0,0,8,7,0,0,0,0,0,0,0,0,0,0,0,0,0,0,0,0,4,1,1,1,1,0,0,0,0,0,0
0,0,0,0,0,0,0,0,0,0,0,1,1,1,1,4,0,0,0,0,0,0,0,0,0,0,8,7,7,7,7,7,0,0,0,0,0,0,0,0,0,0,0,4,1,1,1,1,0,0,0,0,0,0
0,0,0,0,0,0,0,0,0,0,0,1,1,1,1,4,0,0,0,0,0,0,0,0,0,0,0,6,6,6,6,6,0,0,0,0,0,0,0,0,0,0,0,4,1,1,1,1,0,0,0,0,0,0
0,0,0,0,0,0,0,0,0,0,0,1,1,1,1,4,0,0,0,0,0,0,0,0,0,0,6,6,0,0,0,6,0,0,0,0,0,0,0,0,0,0,0,4,1,1,1,1,0,0,0,0,0,0
0,0,0,0,0,0,0,0,0,0,0,1,1,1,1,4,0,0,0,0,0,0,0,0,0,6,6,6,0,0,0,6,0,0,0,0,0,0,0,0,0,0,0,4,1,1,1,1,0,0,0,0,0,0
0,0,0,0,0,0,0,0,0,0,0,1,1,1,1,4,0,0,0,0,0,0,0,0,0,6,6,6,0,0,0,6,0,0,0,0,0,0,0,0,0,0,0,4,1,1,1,1,0,0,0,0,0,0
0,0,0,0,0,0,0,0,0,0,0,1,1,1,1,4,4,4,4,4,4,4,4,4,4,4,4,6,6,6,6,6,0,0,0,0,0,0,0,0,0,0,0,4,1,1,1,1,0,0,0,0,0,0
0,0,0,0,0,0,0,0,0,0,0,0,0,0,0,1,1,1,1,1,1,1,1,1,1,1,1,4,4,4,4,4,4,4,4,4,4,4,4,4,4,4,4,1,1,1,1,1,0,0,0,0,0,0
0,0,0,0,0,0,0,0,0,0,0,0,0,0,0,1,1,1,1,1,1,1,1,1,1,1,1,2,2,2,2,2,2,2,2,2,2,2,2,2,2,2,2,1,1,1,1,1,0,0,0,0,0,0
0,0,0,0,0,0,0,0,0,0,0,0,0,0,0,1,1,1,1,1,1,1,1,1,1,1,1,2,2,2,2,2,2,2,2,2,2,2,2,2,2,2,2,1,1,1,1,1,0,0,0,0,0,0
0,0,0,0,0,0,0,0,0,0,0,0,0,0,0,1,1,1,1,1,1,1,1,1,1,1,1,2,2,2,2,2,2,2,2,2,2,2,2,2,2,2,2,1,1,1,1,1,0,0,0,0,0,0
endlayer

layer
0,0,0,0,0,0,0,0,0,0,0,0,0,0,0,1,1,1,1,1,1,1,1,1,1,1,1,2,2,2,2,2,2,2,2,2,2,2,2,2,2,2,2,1,1,1,1,1,0,0,0,0,0,0
0,0,0,0,0,0,0,0,0,0,0,0,0,0,0,1,1,1,1,1,1,1,1,1,1,1,1,2,2,2,2,2,2,2,2,2,2,2,2,2,2,2,2,1,1,1,1,1,0,0,0,0,0,0
0,0,0,0,0,0,0,0,0,0,0,0,0,0,0,1,1,1,1,1,1,1,1,1,1,1,1,2,2,2,2,2,2,2,2,2,2,2,2,2,2,2,2,1,1,1,1,1,0,0,0,0,0,0
0,0,0,0,0,0,0,0,0,0,0,0,0,0,0,1,1,1,1,1,1,1,1,1,1,1,1,4,4,4,4,4,4,4,4,4,4,4,4,4,4,4,4,1,1,1,1,1,0,0,0,0,0,0
0,0,0,0,0,0,0,0,0,0,0,1,1,1,1,4,4,4,4,4,4,4,4,4,4,4,4,6,6,6,6,6,0,0,0,0,0,0,0,0,0,0,0,4,1,1,1,1,0,0,0,0,0,0
0,0,0,0,0,0,0,0,0,0,0,1,1,1,1,4,0,0,0,0,0,0,0,0,0,0,6,6,0,0,0,6,0,0,0,0,0,0,0,0,0,0,0,4,1,1,1,1,0,0,0,0,0,0
0,0,0,0,0,0,0,0,0,0,0,1,1,1,1,4,0,0,0,0,0,0,0,0,0,6,6,6,0,0,0,6,0,0,0,0,0,0,0,0,0,0,0,4,1,1,1,1,0,0,0,0,0,0
