
# Created by Ruins mod version 17.1 Ingame Parser
# authoring Player: austinsupercar

weight=50
embed_into_distance=3
acceptable_target_blocks=
unacceptable_target_blocks=flowing_water,water,flowing_lava,lava
dimensions=13,16,22
allowable_overhang=0
max_leveling=2
leveling_buffer=0
preserve_water=0
preserve_lava=0
preventRotation=1

rule1=0,100,minecraft:dirt-0
rule2=0,100,minecraft:wooden_slab-4
rule3=0,100,minecraft:double_wooden_slab-4
rule4=0,100,minecraft:sand-0
rule5=0,100,minecraft:planks-4
rule6=0,100,minecraft:dirt-1
rule7=0,100,minecraft:vine-5
rule8=0,100,minecraft:jungle_stairs-1
rule9=0,100,minecraft:planks-1
rule10=0,100,minecraft:tallgrass-1
rule11=0,100,minecraft:iron_block-0
rule12=2,100,minecraft:stone_button-1
rule13=0,100,minecraft:trapdoor-1
rule14=0,100,minecraft:trapdoor-2
rule15=0,100,minecraft:bed-3
rule16=0,100,minecraft:bed-11
rule17=0,100,minecraft:wooden_slab-1
rule18=0,100,minecraft:dark_oak_stairs-0
rule19=0,100,minecraft:vine-1
rule20=0,100,minecraft:vine-8
rule21=0,100,minecraft:log-0
rule22=0,100,minecraft:vine-12
rule23=0,100,minecraft:wooden_door-6
rule24=0,100,minecraft:vine-2
rule25=0,100,minecraft:stained_glass_pane-0
rule26=0,100,minecraft:sea_lantern-0
rule27=0,100,minecraft:stained_glass_pane-15
rule28=0,100,minecraft:jungle_stairs-2
rule29=0,100,minecraft:double_wooden_slab-1
rule30=0,100,minecraft:iron_trapdoor-1
rule31=0,100,minecraft:jungle_stairs-0
rule32=0,100,minecraft:spruce_door-0
rule33=0,100,minecraft:carpet-0
rule34=0,100,minecraft:vine-4
rule35=0,100,minecraft:dark_oak_stairs-1
rule36=0,100,minecraft:wooden_door-9
rule37=0,100,minecraft:spruce_door-8
rule38=0,100,minecraft:trapdoor-4
rule39=0,100,minecraft:trapdoor-7
rule40=0,100,minecraft:trapdoor-14
rule41=0,100,minecraft:trapdoor-12
rule42=0,100,minecraft:vine-3
rule43=0,100,minecraft:web-0
rule44=0,100,minecraft:trapdoor-3
rule45=0,100,minecraft:trapdoor-0
rule46=0,100,minecraft:planks-5
rule47=0,100,minecraft:wooden_slab-9
rule48=0,100,minecraft:spruce_stairs-5
rule49=0,100,minecraft:beacon-0
rule50=0,100,minecraft:spruce_stairs-1
rule51=0,100,minecraft:spruce_stairs-0
rule52=0,100,minecraft:spruce_stairs-4
rule53=0,100,minecraft:dark_oak_stairs-3
rule54=0,100,minecraft:dark_oak_stairs-5
rule55=0,100,minecraft:dark_oak_stairs-4

layer
1,1,1,1,1,1,1,1,1,1,1,1,1,1,1,1,1,1,1,1,1,1
1,1,1,1,1,1,1,1,1,1,1,1,1,1,1,1,1,1,1,1,1,1
1,1,1,1,1,1,1,1,1,1,1,1,1,1,1,1,1,1,1,1,1,1
1,1,1,1,1,1,1,1,1,1,1,1,1,1,1,1,1,1,1,1,1,1
1,1,1,1,1,1,1,1,1,1,1,1,1,1,1,1,1,1,1,1,1,1
1,1,1,1,1,1,1,1,1,1,1,1,1,1,1,1,1,1,1,1,1,1
1,1,1,1,1,1,1,1,1,1,1,1,1,1,1,1,1,1,1,1,1,1
1,1,1,1,1,1,1,1,1,1,1,1,1,1,1,1,1,1,1,1,1,1
1,1,1,1,1,1,1,1,1,1,1,1,1,1,1,1,1,1,1,1,1,1
1,1,1,1,1,1,1,1,1,1,1,1,1,1,1,1,1,1,1,1,1,1
1,1,1,1,1,1,1,1,1,1,1,1,1,1,1,1,1,1,1,1,1,1
1,1,1,1,1,1,1,1,1,1,1,1,1,1,1,1,1,1,1,1,1,1
1,1,1,1,1,1,1,1,1,1,1,1,1,1,1,1,1,1,1,1,1,1
1,1,1,1,1,1,1,1,1,1,1,1,1,1,1,1,1,1,1,1,1,1
1,1,1,1,1,1,1,1,1,1,1,1,1,1,1,1,1,1,1,1,1,1
1,1,1,1,1,1,1,1,1,1,1,1,1,1,1,1,1,1,1,1,1,1
endlayer

layer
1,1,1,1,1,1,1,1,1,1,1,1,1,1,1,1,1,1,1,1,1,1
1,1,1,1,1,1,1,1,1,1,1,1,1,1,1,1,1,1,1,1,1,1
1,1,1,1,1,1,1,1,1,1,1,1,1,1,1,1,1,1,1,1,1,1
1,1,1,1,1,1,1,1,1,1,1,1,1,1,1,1,1,1,1,1,1,1
1,1,1,1,1,1,1,1,1,1,1,1,1,1,1,1,1,1,1,1,1,1
1,1,1,1,1,1,1,1,1,1,1,1,1,1,1,0,1,1,1,1,1,1
1,1,1,1,1,1,1,1,1,1,1,1,1,1,1,1,1,1,1,1,1,1
1,1,1,1,1,1,1,1,1,1,1,1,1,1,1,1,2,1,1,1,1,1
1,1,1,1,1,1,1,1,1,1,1,1,1,1,1,1,1,1,1,1,1,1
1,1,1,1,1,1,1,1,1,1,1,1,1,1,1,1,1,1,1,1,1,1
1,1,1,1,1,1,1,1,1,1,1,3,1,1,1,1,1,1,1,1,1,1
1,1,1,1,1,1,1,1,1,1,1,3,1,1,1,1,1,1,1,1,1,1
1,1,1,1,1,1,1,1,1,1,1,1,1,1,1,1,1,1,1,1,1,1
1,1,1,1,1,1,1,1,1,1,1,1,1,1,1,1,1,1,1,1,1,1
1,1,1,1,1,1,1,1,1,1,1,1,1,1,1,1,1,1,1,1,1,1
1,1,1,1,1,1,1,1,1,1,1,1,1,1,1,1,1,1,1,1,1,1
endlayer

layer
4,4,4,4,4,4,4,4,4,4,4,4,4,4,4,4,4,4,4,4,4,4
4,4,4,4,4,4,4,4,4,4,4,4,4,4,4,4,4,4,4,4,4,4
4,4,4,4,4,4,4,4,4,4,4,4,4,4,4,4,4,4,4,4,4,4
4,4,4,4,4,4,4,4,4,4,4,5,4,4,4,4,4,4,4,4,4,4
4,4,4,4,4,5,5,5,5,5,5,5,5,5,5,5,5,5,4,4,4,4
4,4,9,4,4,6,8,6,5,5,5,5,5,5,5,7,6,5,4,4,4,4
4,4,4,4,4,5,0,10,2,5,5,5,2,5,5,2,5,5,4,4,4,4
4,4,4,4,4,5,5,3,2,2,5,5,5,5,5,2,11,11,4,4,4,4
4,4,4,4,4,5,2,3,5,3,3,5,5,5,5,0,12,2,3,4,4,4
4,4,4,4,4,5,5,6,5,5,14,13,5,5,5,6,2,6,3,4,4,4
4,4,4,4,4,4,4,4,4,4,0,2,15,4,4,3,3,3,4,4,4,4
4,4,4,4,4,4,4,4,4,4,5,0,16,4,4,4,4,4,4,4,4,4
4,4,4,4,4,4,4,4,4,4,4,3,4,4,4,4,4,4,4,4,4,4
4,4,4,4,4,4,4,4,4,4,4,4,4,4,4,4,4,4,4,4,4,4
4,4,4,4,4,4,4,4,4,4,4,4,4,4,4,4,4,4,4,4,4,4
4,4,4,4,4,4,4,4,4,4,4,4,4,4,4,4,4,4,4,4,4,4
endlayer

layer
0,0,0,0,0,0,0,17,17,0,0,0,0,0,17,0,0,17,0,0,0,0
0,0,0,0,20,0,0,0,9,19,0,0,0,0,18,17,0,0,0,0,0,0
0,0,0,22,21,0,0,0,0,20,20,0,0,0,0,0,0,0,21,0,0,0
0,0,0,21,9,9,9,9,17,9,9,23,9,9,9,17,9,9,9,21,0,0
0,0,0,0,9,25,0,24,0,0,0,0,0,9,2,0,2,6,9,0,0,0
0,0,0,27,9,10,0,0,0,0,0,0,0,24,0,0,10,26,9,0,0,17
18,0,27,0,9,28,0,0,0,0,0,0,0,0,0,0,0,0,9,0,0,0
0,17,9,0,9,28,0,0,0,0,0,0,0,0,0,0,30,30,17,0,29,17
0,0,24,0,9,31,0,0,0,0,0,0,0,20,0,0,0,0,17,0,17,0
0,0,0,0,9,25,20,10,0,9,0,0,32,9,0,0,0,6,9,0,0,0
0,0,0,21,21,9,9,9,9,9,0,0,0,9,9,9,9,9,21,21,0,0
0,0,0,0,21,0,0,0,34,9,33,0,0,9,9,9,9,17,21,0,0,0
0,0,0,0,0,0,0,0,34,9,29,29,9,9,0,17,9,0,0,0,0,0
0,0,0,0,0,0,0,0,0,0,0,0,0,24,0,0,17,0,0,0,0,0
0,0,0,0,0,0,0,0,0,0,0,0,0,0,0,0,0,0,0,17,0,0
0,0,0,0,0,0,0,0,35,0,0,0,0,0,0,0,0,0,0,0,0,0
endlayer

layer
0,0,0,0,0,0,0,0,0,0,0,0,0,0,0,0,0,0,0,0,0,0
0,0,0,0,0,0,0,0,0,0,0,0,0,0,0,0,0,0,0,0,0,0
0,0,0,20,21,0,0,0,0,20,0,0,0,0,0,0,0,0,21,0,0,0
0,0,0,21,9,9,0,0,0,9,9,36,9,9,27,0,27,9,9,21,0,0
0,0,0,24,9,25,0,0,0,0,0,0,0,9,19,0,0,0,9,0,0,0
0,0,0,0,27,0,0,0,0,0,0,0,0,0,0,0,0,0,27,0,0,0
0,0,0,0,27,0,0,0,0,0,0,0,0,0,0,0,0,0,27,0,0,0
0,0,0,0,27,0,0,0,0,0,0,0,0,0,0,0,0,0,0,0,0,0
0,0,0,0,27,0,0,0,0,0,0,0,0,20,0,0,0,0,0,0,0,0
0,0,0,0,9,25,0,0,0,9,0,0,37,9,0,0,0,0,9,0,0,0
0,0,0,21,0,9,27,27,27,9,0,0,0,9,27,27,27,9,21,21,0,0
0,0,0,0,21,19,0,0,34,9,19,0,0,9,29,17,0,0,21,0,0,0
0,0,0,0,0,0,0,0,0,9,17,0,27,9,0,0,0,0,0,0,0,0
0,0,0,0,0,0,0,0,0,0,0,0,0,24,0,0,0,0,0,0,0,0
0,0,0,0,0,0,0,0,0,0,0,0,0,0,0,0,0,0,0,0,0,0
0,0,0,0,0,0,0,0,0,0,0,0,0,0,0,0,0,0,0,0,0,0
endlayer

layer
0,0,0,0,0,0,0,0,0,0,0,0,0,0,0,0,0,0,0,0,0,0
0,0,0,0,0,0,0,0,0,0,0,0,0,0,0,0,0,0,0,0,0,0
0,0,0,20,21,0,0,0,0,0,0,0,0,0,0,0,0,0,21,0,0,0
0,0,0,21,9,9,0,0,0,0,17,9,9,9,27,0,27,9,9,21,0,0
0,0,0,24,9,26,38,0,0,0,0,0,0,9,0,0,0,0,9,0,0,0
0,0,0,0,0,39,0,0,0,0,0,0,0,0,0,0,0,0,27,0,0,0
0,0,0,0,27,0,0,0,0,0,0,0,0,0,0,0,0,0,27,0,0,0
0,0,0,0,27,0,0,0,0,0,0,0,0,0,0,0,0,0,27,0,0,0
0,0,0,0,27,40,0,0,0,0,0,0,0,0,0,0,0,0,0,0,0,0
0,0,0,0,9,26,41,0,0,9,0,0,0,9,0,0,0,0,9,0,0,0
0,0,0,21,0,9,27,27,27,9,0,0,0,9,27,27,27,9,21,21,0,0
0,0,0,0,21,42,0,0,0,9,0,0,0,9,0,0,0,0,21,0,0,0
0,0,0,0,0,0,0,0,0,9,0,27,27,9,19,0,0,0,0,0,0,0
0,0,0,0,0,0,0,0,0,0,0,0,0,24,0,0,0,0,0,0,0,0
0,0,0,0,0,0,0,0,0,0,0,0,0,0,0,0,0,0,0,0,0,0
0,0,0,0,0,0,0,0,0,0,0,0,0,0,0,0,0,0,0,0,0,0
endlayer

layer
0,0,0,0,0,0,0,0,0,0,0,0,0,0,0,0,0,0,0,0,0,0
0,0,0,0,0,0,0,0,0,0,0,0,0,0,0,0,0,0,0,0,0,0
0,0,0,20,21,0,0,0,0,0,0,0,0,0,0,0,0,0,21,0,0,0
0,0,0,21,9,9,0,0,0,0,0,0,9,9,0,27,27,9,9,21,0,0
0,0,0,0,9,44,0,0,0,0,0,0,43,9,0,0,0,0,9,0,0,0
0,0,0,0,0,0,0,0,0,0,0,0,0,9,0,0,0,0,27,0,0,0
0,0,0,0,0,0,0,0,0,0,0,0,0,0,0,0,0,0,27,0,0,0
0,0,0,0,0,0,0,0,0,0,0,0,0,0,0,0,0,0,27,0,0,0
0,0,0,0,27,0,0,0,0,0,0,0,0,0,0,0,0,0,27,0,0,0
0,0,0,0,9,45,0,0,0,9,0,0,0,9,43,0,0,0,9,0,0,0
0,0,0,21,0,9,27,27,27,9,0,0,0,9,27,27,27,9,21,21,0,0
0,0,0,0,21,42,0,0,0,9,43,0,0,9,0,0,0,0,21,0,0,0
0,0,0,0,0,0,0,0,0,9,27,27,27,9,0,0,0,0,0,0,0,0
0,0,0,0,0,0,0,0,0,0,0,0,0,0,0,0,0,0,0,0,0,0
0,0,0,0,0,0,0,0,0,0,0,0,0,0,0,0,0,0,0,0,0,0
0,0,0,0,0,0,0,0,0,0,0,0,0,0,0,0,0,0,0,0,0,0
endlayer

layer
0,0,0,0,0,0,0,0,0,0,0,0,0,0,0,0,0,0,0,0,0,0
0,0,0,0,0,0,0,0,0,0,0,0,0,0,0,0,0,0,0,0,0,0
0,0,0,0,21,0,0,0,0,0,0,0,0,0,0,0,0,0,21,0,0,0
0,0,0,21,9,9,9,9,9,9,9,9,9,9,9,9,9,9,9,21,0,0
0,0,0,0,9,0,0,0,0,9,0,0,0,9,0,0,0,0,9,0,0,0
0,0,0,0,9,0,0,0,0,9,0,0,0,9,0,0,0,0,9,0,0,0
0,0,0,0,9,0,0,0,0,9,0,0,0,9,0,0,0,0,9,0,0,0
0,0,0,0,46,0,0,0,0,0,0,0,0,9,0,0,0,0,9,0,0,0
0,0,0,0,9,0,0,0,0,0,0,0,0,43,0,0,0,0,9,0,0,0
0,0,0,0,9,0,0,0,0,9,0,0,47,9,0,0,0,0,9,0,0,0
0,0,0,21,0,9,9,9,9,9,9,9,9,9,9,9,9,9,21,21,0,0
0,0,0,0,21,42,0,0,48,9,29,49,17,9,48,0,0,0,21,0,0,0
0,0,0,0,0,0,0,0,0,9,9,9,9,9,0,0,0,0,0,0,0,0
0,0,0,0,0,0,0,0,0,50,50,50,50,50,0,0,0,0,0,0,0,0
0,0,0,0,0,0,0,0,0,0,0,0,0,0,0,0,0,0,0,0,0,0
0,0,0,0,0,0,0,0,0,0,0,0,0,0,0,0,0,0,0,0,0,0
endlayer

layer
0,0,0,0,0,0,0,0,0,0,0,0,0,0,0,0,0,0,0,0,0,0
0,0,0,51,51,51,51,51,51,51,51,51,51,51,51,51,51,51,0,0,0,0
0,0,0,9,9,9,9,9,9,9,9,9,9,0,9,9,9,9,9,9,0,0
0,0,0,9,9,9,9,9,9,9,9,9,0,9,9,9,9,9,9,9,0,0
0,0,0,9,9,0,0,0,0,9,0,0,0,9,0,0,0,0,9,9,0,0
0,0,0,9,9,0,0,0,0,9,0,0,0,9,0,0,0,0,9,9,0,0
0,0,0,46,46,0,0,0,0,9,0,0,0,9,0,0,0,0,9,9,0,0
0,0,0,0,0,0,0,0,0,9,0,0,0,9,9,0,0,0,9,9,0,0
0,0,0,0,0,0,0,0,0,9,0,0,0,9,9,9,0,0,9,9,0,0
0,0,0,0,9,0,0,0,43,9,47,29,29,9,9,9,9,9,9,9,0,0
0,0,0,9,9,9,9,9,9,9,9,9,9,9,9,9,9,9,9,9,0,0
0,0,0,9,9,9,9,9,9,9,9,9,9,9,9,9,0,9,9,9,0,0
0,0,0,50,50,50,50,50,50,50,50,50,50,50,50,50,0,0,0,50,0,0
0,0,0,0,0,0,0,0,0,0,0,0,0,0,0,0,0,0,0,0,0,0
0,0,0,0,0,0,0,0,0,0,0,0,0,0,0,0,0,0,0,0,0,0
0,0,0,0,0,0,0,0,0,0,0,0,0,0,0,0,0,0,0,0,0,0
endlayer

layer
0,0,0,0,0,0,0,0,0,0,0,0,0,0,0,0,0,0,0,0,0,0
0,0,0,0,0,0,0,0,0,0,0,0,0,0,0,0,0,0,0,0,0,0
0,0,0,51,0,17,51,18,18,51,51,51,0,0,51,51,51,51,0,0,0,0
0,0,0,48,9,17,46,9,9,9,9,46,0,17,9,9,9,9,9,48,0,0
0,0,0,0,9,0,0,0,0,9,0,0,0,9,0,0,43,43,9,0,0,0
0,0,0,0,9,0,0,0,0,9,0,0,0,9,0,0,0,0,9,0,0,0
0,0,0,0,0,0,0,0,0,9,0,0,0,9,0,0,0,0,9,0,0,0
0,0,0,0,0,0,0,0,0,9,0,0,0,9,0,0,0,0,9,0,0,0
0,0,0,0,0,0,0,0,0,9,0,0,0,9,17,0,0,0,9,0,0,0
0,0,0,0,0,0,9,9,9,9,9,9,9,9,17,0,29,0,9,0,0,0
0,0,0,52,9,53,9,9,9,9,9,9,9,9,17,0,17,35,9,52,0,0
0,0,0,50,50,50,50,50,50,50,50,50,50,50,35,0,0,0,50,50,0,0
0,0,0,0,0,0,0,0,0,0,0,0,0,0,0,0,0,0,0,0,0,0
0,0,0,0,0,0,0,0,0,0,0,0,0,0,0,0,0,0,0,0,0,0
0,0,0,0,0,0,0,0,0,0,0,0,0,0,0,0,0,0,0,0,0,0
0,0,0,0,0,0,0,0,0,0,0,0,0,0,0,0,0,0,0,0,0,0
endlayer

layer
0,0,0,0,0,0,0,0,0,0,0,0,0,0,0,0,0,0,0,0,0,0
0,0,0,0,0,0,0,0,0,0,0,0,0,0,0,0,0,0,0,0,0,0
0,0,0,0,0,0,0,0,0,0,0,0,0,0,0,0,0,0,0,0,0,0
0,0,0,51,18,0,0,18,18,18,51,0,0,0,51,51,51,51,51,51,0,0
0,0,0,54,9,0,0,0,0,46,46,0,0,46,9,9,9,9,9,48,0,0
0,0,0,0,9,0,0,0,0,0,0,0,0,9,0,0,0,43,9,0,0,0
0,0,0,0,54,0,0,0,0,9,0,0,0,9,0,0,9,0,9,0,0,0
0,0,0,0,0,0,0,0,0,9,0,0,0,9,0,0,0,0,9,0,0,0
0,0,0,0,0,0,46,9,9,9,9,9,9,17,0,0,0,9,9,0,0,0
0,0,0,52,9,0,46,9,9,9,9,9,46,0,0,0,0,46,9,52,0,0
0,0,0,50,35,0,50,50,50,50,50,50,35,0,0,0,0,0,35,35,0,0
0,0,0,0,0,0,0,0,0,0,0,0,0,0,0,0,0,0,0,0,0,0
0,0,0,0,0,0,0,0,0,0,0,0,0,0,0,0,0,0,0,0,0,0
0,0,0,0,0,0,0,0,0,0,0,0,0,0,0,0,0,0,0,0,0,0
0,0,0,0,0,0,0,0,0,0,0,0,0,0,0,0,0,0,0,0,0,0
0,0,0,0,0,0,0,0,0,0,0,0,0,0,0,0,0,0,0,0,0,0
endlayer

layer
0,0,0,0,0,0,0,0,0,0,0,0,0,0,0,0,0,0,0,0,0,0
0,0,0,0,0,0,0,0,0,0,0,0,0,0,0,0,0,0,0,0,0,0
0,0,0,0,0,0,0,0,0,0,0,0,0,0,0,0,0,0,0,0,0,0
0,0,0,0,0,0,0,0,0,0,0,0,0,0,0,0,0,0,0,0,0,0
0,0,0,18,51,0,0,0,0,18,0,0,0,0,51,51,51,51,51,51,0,0
0,0,0,54,9,46,0,0,0,46,9,0,55,9,9,9,9,9,9,48,0,0
0,0,0,0,9,9,9,0,46,9,9,9,9,9,46,0,9,9,9,0,0,0
0,0,0,0,9,9,9,9,9,9,9,9,9,0,0,0,0,9,9,0,0,0
0,0,0,52,9,0,46,9,9,9,9,9,9,0,0,0,0,46,9,52,0,0
0,0,0,50,35,0,0,50,50,50,50,50,0,0,0,0,0,0,35,50,0,0
0,0,0,0,0,0,0,0,0,0,0,0,0,0,0,0,0,0,0,0,0,0
0,0,0,0,0,0,0,0,0,0,0,0,0,0,0,0,0,0,0,0,0,0
0,0,0,0,0,0,0,0,0,0,0,0,0,0,0,0,0,0,0,0,0,0
0,0,0,0,0,0,0,0,0,0,0,0,0,0,0,0,0,0,0,0,0,0
0,0,0,0,0,0,0,0,0,0,0,0,0,0,0,0,0,0,0,0,0,0
0,0,0,0,0,0,0,0,0,0,0,0,0,0,0,0,0,0,0,0,0,0
endlayer

layer
0,0,0,0,0,0,0,0,0,0,0,0,0,0,0,0,0,0,0,0,0,0
0,0,0,0,0,0,0,0,0,0,0,0,0,0,0,0,0,0,0,0,0,0
0,0,0,0,0,0,0,0,0,0,0,0,0,0,0,0,0,0,0,0,0,0
0,0,0,0,0,0,0,0,0,0,0,0,0,0,0,0,0,0,0,0,0,0
0,0,0,0,0,0,0,0,0,0,0,0,0,0,0,0,0,0,0,0,0,0
0,0,0,51,51,51,51,51,51,51,18,0,51,51,51,51,51,51,51,51,0,0
0,0,0,9,9,9,46,0,9,9,9,46,9,9,9,9,9,9,9,9,0,0
0,0,0,9,9,0,0,0,9,9,9,9,9,0,0,0,46,9,9,9,0,0
0,0,0,50,50,0,0,0,50,50,50,50,50,0,0,0,0,0,50,50,0,0
0,0,0,0,0,0,0,0,0,0,0,0,0,0,0,0,0,0,0,0,0,0
0,0,0,0,0,0,0,0,0,0,0,0,0,0,0,0,0,0,0,0,0,0
0,0,0,0,0,0,0,0,0,0,0,0,0,0,0,0,0,0,0,0,0,0
0,0,0,0,0,0,0,0,0,0,0,0,0,0,0,0,0,0,0,0,0,0
0,0,0,0,0,0,0,0,0,0,0,0,0,0,0,0,0,0,0,0,0,0
0,0,0,0,0,0,0,0,0,0,0,0,0,0,0,0,0,0,0,0,0,0
0,0,0,0,0,0,0,0,0,0,0,0,0,0,0,0,0,0,0,0,0,0
endlayer

