
# Created by Ruins mod version 17.1 Ingame Parser
# authoring Player: austinsupercar

weight=30
embed_into_distance=3
acceptable_target_blocks=
unacceptable_target_blocks=flowing_water,water,flowing_lava,lava
dimensions=26,11,11
allowable_overhang=0
max_leveling=2
leveling_buffer=0
preserve_water=0
preserve_lava=0
preventRotation=1

rule1=0,100,chisel:factory-0
rule2=0,100,chisel:cobblestone-1
rule3=0,100,chisel:cobblestonemossy-1

layer
1,2,3,2,2,2,2,2,2,2,1
2,2,2,3,2,3,2,2,2,3,3
2,3,2,2,2,2,2,3,3,2,2
2,2,2,2,2,2,2,2,2,2,2
2,2,2,2,2,2,2,2,3,2,2
2,3,2,2,2,2,2,3,2,2,2
3,2,2,2,3,2,2,2,2,3,2
2,2,3,2,2,2,2,2,3,3,3
3,3,2,2,3,2,2,3,2,3,2
2,2,2,2,2,2,2,2,2,2,2
1,3,2,3,2,3,3,2,2,2,1
endlayer

layer
1,2,2,2,2,2,2,3,2,3,1
2,0,0,0,0,0,0,0,0,0,2
3,0,0,0,0,0,0,0,0,0,2
2,0,2,0,0,0,0,0,0,0,3
0,0,0,0,0,0,0,3,3,0,2
2,0,0,0,0,0,0,0,2,0,2
2,0,0,0,0,0,0,0,0,0,2
2,0,2,0,0,0,0,0,0,0,2
0,0,0,0,0,0,0,0,0,0,2
2,0,0,0,0,0,0,0,0,0,3
1,2,3,2,2,2,2,3,2,2,1
endlayer

layer
1,0,2,2,2,3,2,2,2,2,1
2,0,0,0,0,0,0,0,0,0,2
2,0,0,0,0,0,0,0,0,0,0
3,0,0,0,0,0,0,0,0,0,2
2,0,0,0,0,0,0,0,2,0,2
3,0,0,0,0,0,0,0,0,0,2
0,0,0,0,0,0,0,0,0,0,2
2,0,0,0,0,0,0,0,0,0,3
2,0,0,0,0,0,0,0,0,0,2
2,0,0,0,0,0,0,0,0,0,2
1,2,2,2,2,3,2,2,2,3,1
endlayer

layer
1,0,0,2,2,2,0,2,3,0,1
2,0,0,0,0,0,0,0,0,0,0
0,0,0,0,0,0,0,0,0,0,0
2,0,0,0,0,0,0,0,0,0,2
2,0,0,0,0,0,0,0,0,0,0
2,0,0,0,0,0,0,0,0,0,0
2,0,0,0,0,0,0,0,0,0,0
2,0,0,0,0,0,0,0,0,0,2
0,0,0,0,0,0,0,0,0,0,2
2,0,0,0,0,0,0,0,0,0,0
1,0,3,0,2,2,3,0,0,2,1
endlayer

layer
1,1,1,1,1,1,1,1,1,1,1
1,0,2,3,0,0,0,2,2,3,1
1,3,2,2,3,2,0,3,2,2,1
1,2,0,2,2,3,2,2,0,0,1
1,2,2,2,3,2,0,0,0,2,1
1,2,3,0,2,2,2,0,2,3,1
1,3,2,2,0,2,3,0,0,0,1
1,2,0,0,3,3,2,2,2,3,1
1,2,2,2,2,2,0,0,3,2,1
1,2,3,2,0,2,0,2,2,3,1
1,1,1,1,1,1,1,1,1,1,1
endlayer

layer
1,0,2,3,2,2,2,2,3,2,1
2,0,0,0,0,0,0,0,0,0,2
2,0,0,0,0,0,0,0,0,0,2
2,0,0,0,0,0,0,0,0,0,2
2,0,0,0,0,0,0,0,0,0,2
3,0,0,0,0,0,0,0,0,0,2
2,0,0,0,0,0,0,0,0,0,2
2,0,0,0,0,0,0,0,0,0,2
2,0,0,0,0,0,0,0,0,0,3
3,0,0,0,0,0,0,0,0,0,2
1,2,2,2,2,3,2,2,2,3,1
endlayer

layer
1,0,0,2,2,2,2,3,2,2,1
2,0,0,0,0,0,0,0,0,0,2
3,0,0,0,0,0,0,0,0,0,3
0,0,0,0,0,0,0,0,0,0,2
2,0,0,0,0,0,0,0,0,0,0
2,0,0,0,0,0,0,0,0,0,2
2,0,0,0,0,0,0,0,0,0,3
3,0,0,0,0,0,0,0,0,0,2
3,0,0,0,0,0,0,0,0,0,2
0,0,0,0,0,0,0,0,0,0,2
1,0,2,3,2,0,0,3,2,2,1
endlayer

layer
1,0,0,0,0,2,0,2,2,0,1
3,0,0,0,0,0,0,0,0,0,2
0,0,0,0,0,0,0,0,0,0,2
0,0,0,0,0,0,0,0,0,0,0
2,0,0,0,0,0,0,0,0,0,0
0,0,0,0,0,0,0,0,0,0,2
2,0,0,0,0,0,0,0,0,0,2
0,0,0,0,0,0,0,0,0,0,0
0,0,0,0,0,0,0,0,0,0,0
0,0,0,0,0,0,0,0,0,0,2
1,0,0,2,0,0,0,0,2,2,1
endlayer

layer
1,1,1,1,1,1,1,1,1,1,1
1,2,2,0,0,0,0,2,2,3,1
1,0,2,2,2,2,2,3,2,2,1
1,0,0,3,2,2,0,0,0,2,1
1,0,2,2,0,0,0,0,2,2,1
1,2,2,0,0,0,0,2,2,3,1
1,0,2,3,0,0,0,2,3,2,1
1,0,2,2,2,0,3,2,2,2,1
1,0,2,3,2,2,2,3,0,2,1
1,2,2,2,2,0,0,2,2,2,1
1,1,1,1,1,1,1,1,1,1,1
endlayer

layer
1,2,2,3,2,2,0,0,2,3,1
2,0,0,0,0,0,0,0,0,0,2
0,0,0,0,0,0,0,0,0,0,3
2,0,0,0,0,0,0,0,0,0,2
2,0,0,0,0,0,0,0,0,0,2
2,0,0,0,0,0,0,0,0,0,3
2,0,0,0,0,0,0,0,0,0,0
3,0,0,0,0,0,0,0,0,0,2
2,0,0,0,0,0,0,0,0,0,3
2,0,0,0,0,0,0,0,0,0,2
1,3,2,2,3,0,0,0,2,3,1
endlayer

layer
1,0,3,2,3,0,0,0,0,2,1
2,0,0,0,0,0,0,0,0,0,2
0,0,0,0,0,0,0,0,0,0,2
0,0,0,0,0,0,0,0,0,0,2
3,0,0,0,0,0,0,0,0,0,0
2,0,0,0,0,0,0,0,0,0,0
0,0,0,0,0,0,0,0,0,0,0
2,0,0,0,0,0,0,0,0,0,0
0,0,0,0,0,0,0,0,0,0,2
3,0,0,0,0,0,0,0,0,0,2
1,2,3,2,0,2,3,2,3,2,1
endlayer

layer
1,0,0,2,0,0,2,3,0,0,1
0,0,0,0,0,0,0,0,0,0,3
0,0,0,0,0,0,0,0,0,0,0
0,0,0,0,0,0,0,0,0,0,0
2,0,0,0,0,0,0,0,0,0,0
0,0,0,0,0,0,0,0,0,0,2
0,0,0,0,0,0,0,0,0,0,3
0,0,0,0,0,0,0,0,0,0,0
0,0,0,0,0,0,0,0,0,0,0
3,0,0,0,0,0,0,0,0,0,3
1,3,2,0,3,0,2,0,2,2,1
endlayer

layer
1,1,1,1,1,1,1,1,1,1,1
1,3,2,2,3,0,2,3,2,0,1
1,2,0,2,2,0,0,2,0,2,1
1,3,2,0,3,0,0,2,3,2,1
1,0,0,2,0,0,0,0,0,2,1
1,0,0,0,0,0,0,0,0,0,1
1,2,0,0,0,0,0,0,0,2,1
1,2,3,0,0,0,0,0,2,3,1
1,2,0,2,3,0,0,2,3,0,1
1,3,0,2,2,3,0,2,0,2,1
1,1,1,1,1,1,1,1,1,1,1
endlayer

layer
1,2,0,0,3,0,3,2,0,2,1
3,0,0,0,0,0,0,0,0,0,2
2,0,0,0,0,0,0,0,0,0,3
0,0,0,0,0,0,0,0,0,0,2
0,0,0,0,0,0,0,0,0,0,0
2,0,0,0,0,0,0,0,0,0,0
2,0,0,0,0,0,0,0,0,0,2
2,0,0,0,0,0,0,0,0,0,2
3,0,0,0,0,0,0,0,0,0,3
0,0,0,0,0,0,0,0,0,0,2
1,3,2,2,3,0,0,3,2,2,1
endlayer

layer
1,3,2,0,0,0,0,0,0,3,1
2,0,0,0,0,0,0,0,0,0,3
3,0,0,0,0,0,0,0,0,0,2
0,0,0,0,0,0,0,0,0,0,0
0,0,0,0,0,0,0,0,0,0,0
0,0,0,0,0,0,0,0,0,0,0
3,0,0,0,0,0,0,0,0,0,0
2,0,0,0,0,0,0,0,0,0,0
0,0,0,0,0,0,0,0,0,0,2
0,0,0,0,0,0,0,0,0,0,2
1,2,3,2,0,0,0,0,2,3,1
endlayer

layer
1,2,3,0,0,2,0,3,2,2,1
2,0,0,0,0,0,0,0,0,0,2
0,0,0,0,0,0,0,0,0,0,0
0,0,0,0,0,0,0,0,0,0,0
2,0,0,0,0,0,0,0,0,0,2
0,0,0,0,0,0,0,0,0,0,3
0,0,0,0,0,0,0,0,0,0,2
0,0,0,0,0,0,0,0,0,0,0
0,0,0,0,0,0,0,0,0,0,0
2,0,0,0,0,0,0,0,0,0,0
1,0,2,2,3,0,2,0,0,2,1
endlayer

layer
1,1,1,1,1,1,1,1,1,1,1
1,0,0,2,0,0,3,2,0,0,1
1,2,0,3,0,0,2,0,0,2,1
1,0,2,0,0,2,3,2,3,2,1
1,2,0,0,0,0,0,0,0,2,1
1,0,0,0,0,0,0,0,0,0,1
1,2,0,0,0,0,0,0,0,0,1
1,2,3,0,0,0,0,0,0,3,1
1,3,0,2,0,0,0,0,2,0,1
1,0,2,3,2,0,0,2,3,2,1
1,1,1,1,1,1,1,1,1,1,1
endlayer

layer
1,3,3,2,0,2,3,2,2,0,1
3,0,0,0,0,0,0,0,0,0,3
2,0,0,0,0,0,0,0,0,0,2
3,0,0,0,0,0,0,0,0,0,2
0,0,0,0,0,0,0,0,0,0,0
2,0,0,0,0,0,0,0,0,0,0
0,0,0,0,0,0,0,0,0,0,3
2,0,0,0,0,0,0,0,0,0,0
2,0,0,0,0,0,0,0,0,0,3
3,0,0,0,0,0,0,0,0,0,2
1,3,0,2,2,3,0,0,2,2,1
endlayer

layer
1,2,2,0,0,0,0,3,0,0,1
2,0,0,0,0,0,0,0,0,0,0
0,0,0,0,0,0,0,0,0,0,2
0,0,0,0,0,0,0,0,0,0,0
0,0,0,0,0,0,0,0,0,0,0
0,0,0,0,0,0,0,0,0,0,0
0,0,0,0,0,0,0,0,0,0,0
0,0,0,0,0,0,0,0,0,0,0
2,0,0,0,0,0,0,0,0,0,0
2,0,0,0,0,0,0,0,0,0,0
1,0,0,0,0,0,0,0,0,0,1
endlayer

layer
1,0,0,0,2,0,0,0,0,3,1
0,0,0,0,0,0,0,0,0,0,0
0,0,0,0,0,0,0,0,0,0,0
0,0,0,0,0,0,0,0,0,0,0
2,0,0,0,0,0,0,0,0,0,2
0,0,0,0,0,0,0,0,0,0,2
2,0,0,0,0,0,0,0,0,0,2
0,0,0,0,0,0,0,0,0,0,0
0,0,0,0,0,0,0,0,0,0,0
0,0,0,0,0,0,0,0,0,0,2
1,2,3,0,0,0,3,0,0,3,1
endlayer

layer
1,1,1,1,1,1,1,1,1,1,1
1,0,0,0,0,0,0,0,0,0,1
1,0,0,0,0,0,0,0,0,0,1
1,0,0,0,0,0,0,0,0,0,1
1,0,0,0,0,0,0,0,0,0,1
1,0,0,0,0,0,0,0,0,2,1
1,0,0,0,0,0,0,0,0,2,1
1,0,0,0,0,0,0,0,2,0,1
1,3,2,0,0,0,0,0,3,2,1
1,0,2,3,0,0,0,2,0,2,1
1,1,1,1,1,1,1,1,1,1,1
endlayer

layer
1,0,0,0,0,0,0,0,3,3,1
0,0,0,0,0,0,0,0,0,0,0
0,0,0,0,0,0,0,0,0,0,0
0,0,0,0,0,0,0,0,0,0,0
0,0,0,0,0,0,0,0,0,0,0
0,0,0,0,0,0,0,0,0,0,2
0,0,0,0,0,0,0,0,0,0,2
0,0,0,0,0,0,0,0,0,0,3
3,0,0,0,0,0,0,0,0,0,2
2,0,0,0,0,0,0,0,0,0,3
1,2,3,2,0,0,0,2,3,2,1
endlayer

layer
0,0,0,0,0,0,0,0,0,2,1
0,0,0,0,0,0,0,0,0,0,0
0,0,0,0,0,0,0,0,0,0,0
0,0,0,0,0,0,0,0,0,0,0
0,0,0,0,0,0,0,0,0,0,0
0,0,0,0,0,0,0,0,0,0,0
0,0,0,0,0,0,0,0,0,0,0
0,0,0,0,0,0,0,0,0,0,0
0,0,0,0,0,0,0,0,0,0,2
3,0,0,0,0,0,0,0,0,0,2
1,3,0,0,0,0,0,0,2,2,1
endlayer

layer
0,0,0,0,0,0,0,0,0,0,1
0,0,0,0,0,0,0,0,0,0,0
0,0,0,0,0,0,0,0,0,0,0
0,0,0,0,0,0,0,0,0,0,0
0,0,0,0,0,0,0,0,0,0,0
0,0,0,0,0,0,0,0,0,0,0
0,0,0,0,0,0,0,0,0,0,0
0,0,0,0,0,0,0,0,0,0,0
0,0,0,0,0,0,0,0,0,0,0
0,0,0,0,0,0,0,0,0,0,0
1,0,0,0,0,0,0,0,0,0,1
endlayer

layer
0,0,0,0,0,0,0,0,0,0,1
0,0,0,0,0,0,0,0,0,0,0
0,0,0,0,0,0,0,0,0,0,0
0,0,0,0,0,0,0,0,0,0,0
0,0,0,0,0,0,0,0,0,0,0
0,0,0,0,0,0,0,0,0,0,0
0,0,0,0,0,0,0,0,0,0,0
0,0,0,0,0,0,0,0,0,0,0
0,0,0,0,0,0,0,0,0,0,0
0,0,0,0,0,0,0,0,0,0,0
0,0,0,0,0,0,0,0,0,0,1
endlayer

layer
0,0,0,0,0,0,0,0,0,0,0
0,0,0,0,0,0,0,0,0,0,0
0,0,0,0,0,0,0,0,0,0,0
0,0,0,0,0,0,0,0,0,0,0
0,0,0,0,0,0,0,0,0,0,0
0,0,0,0,0,0,0,0,0,0,0
0,0,0,0,0,0,0,0,0,0,0
0,0,0,0,0,0,0,0,0,0,0
0,0,0,0,0,0,0,0,0,0,0
0,0,0,0,0,0,0,0,0,0,0
0,0,0,0,0,0,0,0,0,0,1
endlayer

