
# Created by Ruins mod version 17.1 Ingame Parser
# authoring Player: austinsupercar

weight=20
embed_into_distance=1
acceptable_target_blocks=
unacceptable_target_blocks=flowing_water,water,flowing_lava,lava
dimensions=10,10,9
allowable_overhang=0
max_leveling=2
leveling_buffer=0
preserve_water=0
preserve_lava=0
preventRotation=1

rule1=0,100,minecraft:planks-1
rule2=0,100,minecraft:oak_stairs-2
rule3=0,100,minecraft:fence-0
rule4=0,100,minecraft:log-0
rule5=0,100,minecraft:crafting_table-0
rule6=0,100,minecraft:oak_stairs-3
rule7=0,100,minecraft:wooden_door-1
rule8=0,100,minecraft:furnace-3
rule9=0,100,ChestGenHook:chests/simple_dungeon:5-4
rule10=0,100,minecraft:glass-0
rule11=0,100,minecraft:wooden_door-9
rule12=2,100,minecraft:torch-1
rule13=0,100,minecraft:oak_stairs-1
rule14=2,100,minecraft:torch-3
rule15=2,100,minecraft:torch-4
rule16=2,100,minecraft:torch-2
rule17=0,100,minecraft:stone_stairs-2
rule18=0,100,minecraft:stone_stairs-3
rule19=0,100,ChestGenHook:chests/simple_dungeon:5-3
rule20=0,100,minecraft:bookshelf-0
rule21=0,100,minecraft:wooden_door-0
rule22=0,100,IInventory;minecraft:chest;minecraft:air#0#0#0+minecraft:air#0#0#1+minecraft:air#0#0#2+minecraft:air#0#0#3+minecraft:air#0#0#4+minecraft:air#0#0#5+minecraft:air#0#0#6+minecraft:air#0#0#7+minecraft:air#0#0#8+minecraft:air#0#0#9+minecraft:air#0#0#10+minecraft:air#0#0#11+minecraft:air#0#0#12+minecraft:air#0#0#13+minecraft:air#0#0#14+minecraft:air#0#0#15+minecraft:air#0#0#16+minecraft:air#0#0#17+minecraft:air#0#0#18+minecraft:air#0#0#19+minecraft:air#0#0#20+minecraft:air#0#0#21+minecraft:air#0#0#22+minecraft:air#0#0#23+minecraft:air#0#0#24+minecraft:air#0#0#25+minecraft:air#0#0#26-2
rule23=0,100,minecraft:bed-0
rule24=0,100,minecraft:bed-8
rule25=0,100,minecraft:wooden_door-8
rule26=0,100,minecraft:stone_stairs-0
rule27=0,100,minecraft:cobblestone-0
rule28=0,100,minecraft:stone_stairs-1
rule29=0,100,minecraft:stone_slab-3

layer
1,1,1,1,1,1,1,1,1
1,1,1,1,1,1,1,1,1
1,1,1,1,1,1,1,1,1
1,1,1,1,1,1,1,1,1
1,1,1,1,1,1,1,1,2
1,1,1,1,1,1,1,1,2
1,1,1,1,1,1,1,1,1
1,1,1,1,1,1,1,1,1
1,1,1,1,1,1,1,1,1
1,1,1,1,1,1,1,1,1
endlayer

layer
4,1,1,1,1,1,4,3,3
1,0,5,1,0,0,1,0,3
1,0,6,1,0,0,1,0,3
1,0,1,1,0,0,1,0,3
1,0,8,1,0,0,7,0,0
1,0,8,1,0,0,1,0,0
1,0,0,0,0,0,1,0,3
1,0,0,1,2,0,1,0,3
1,5,9,1,0,0,1,0,3
4,1,1,1,1,1,4,3,3
endlayer

layer
4,1,1,1,1,1,4,0,3
1,0,0,1,0,0,1,0,0
10,0,0,6,0,0,10,0,0
1,0,1,1,0,0,1,0,0
1,0,0,1,0,0,11,0,0
1,0,0,1,0,0,1,0,0
1,0,0,0,0,0,1,0,0
10,0,0,1,0,0,10,0,0
1,0,0,1,0,0,1,0,0
4,1,10,1,10,1,4,0,3
endlayer

layer
4,1,1,1,1,1,4,0,3
1,12,0,13,12,0,1,0,0
10,0,0,0,0,0,10,0,0
1,0,1,1,0,14,1,0,0
1,0,12,1,15,0,1,0,0
1,15,0,1,0,0,1,0,0
1,0,0,1,0,0,1,0,0
10,0,0,1,15,0,10,0,0
1,16,0,1,0,14,1,0,0
4,1,10,1,10,1,4,0,3
endlayer

layer
4,1,1,1,1,1,4,1,1
1,1,1,0,6,1,1,1,1
1,1,0,0,1,1,1,1,1
1,1,1,1,1,1,1,1,1
1,1,1,1,1,1,1,1,1
1,1,1,1,1,1,1,1,1
1,1,1,1,1,1,1,1,1
1,1,1,1,1,1,1,1,1
1,1,1,1,1,1,1,1,1
4,1,1,1,1,1,4,1,1
endlayer

layer
18,1,1,1,1,1,1,1,17
18,0,1,0,0,0,1,0,17
18,0,1,0,3,0,1,0,17
18,0,1,3,3,0,1,1,17
18,0,1,0,0,0,19,1,17
18,0,1,20,0,0,19,1,17
18,0,1,1,1,21,1,1,17
18,0,1,24,23,0,1,22,17
18,0,1,20,0,0,1,22,17
18,1,1,1,1,1,1,1,17
endlayer

layer
0,18,1,1,10,1,1,17,0
0,18,1,0,0,0,1,17,0
0,18,1,0,0,0,1,17,0
0,18,1,0,0,0,1,1,0
0,18,1,0,0,0,0,10,0
0,18,1,0,0,0,0,10,0
0,18,1,1,1,25,1,1,0
0,18,1,0,0,0,1,17,0
0,18,1,5,0,0,1,17,0
0,18,1,1,10,1,1,17,0
endlayer

layer
0,0,18,1,10,1,17,0,0
0,0,18,12,0,12,17,0,0
0,0,18,0,0,0,17,0,0
0,0,18,0,0,0,1,1,0
0,0,18,0,0,0,0,10,0
0,0,18,16,0,0,16,10,0
0,0,18,1,1,1,1,1,0
0,0,18,12,0,0,17,0,0
0,0,18,16,0,16,17,0,0
0,0,18,1,10,1,17,0,0
endlayer

layer
0,0,0,18,1,17,0,0,0
0,0,0,18,1,17,0,0,0
0,0,0,18,1,17,0,0,0
0,0,0,18,1,27,26,26,0
0,0,0,18,1,0,0,1,0
0,0,0,18,1,0,0,1,0
0,0,0,18,1,27,28,28,0
0,0,0,18,1,17,0,0,0
0,0,0,18,1,17,0,0,0
0,0,0,18,1,17,0,0,0
endlayer

layer
0,0,0,0,29,0,0,0,0
0,0,0,0,29,0,0,0,0
0,0,0,0,29,0,0,0,0
0,0,0,0,29,0,0,0,0
0,0,0,0,29,26,26,26,0
0,0,0,0,29,28,28,28,0
0,0,0,0,29,0,0,0,0
0,0,0,0,29,0,0,0,0
0,0,0,0,29,0,0,0,0
0,0,0,0,29,0,0,0,0
endlayer

