
# Created by Ruins mod version 17.1 Ingame Parser
# authoring Player: austinsupercar

weight=20
embed_into_distance=1
acceptable_target_blocks=sand
unacceptable_target_blocks=flowing_water,water,flowing_lava,lava
dimensions=9,23,18
allowable_overhang=0
max_leveling=2
leveling_buffer=0
preserve_water=0
preserve_lava=0
preventRotation=1

rule1=0,100,chisel:factory-0
rule2=0,100,immersiveengineering:stone_decoration-5
rule3=0,100,minecraft:iron_bars-0
rule4=0,100,minecraft:stonebrick-0
rule5=0,100,minecraft:stonebrick-1
rule6=0,100,ChestGenHook:chests/simple_dungeon:5-5
rule7=0,100,ChestGenHook:chests/simple_dungeon:5-3
rule8=0,100,minecraft:bed-0
rule9=0,100,minecraft:bed-8
rule10=0,100,minecraft:bed-10
rule11=0,100,minecraft:bed-2
rule12=0,100,ChestGenHook:chests/simple_dungeon:5-2
rule13=0,100,minecraft:iron_door-2
rule14=0,100,minecraft:iron_door-8
rule15=0,100,minecraft:web-0
rule16=0,100,immersiveengineering:metal_decoration1-0
rule17=1,100,minecraft:redstone_torch-5

layer
1,2,2,2,2,2,2,2,2,2,2,2,2,2,2,2,2,1
2,2,2,2,2,2,2,2,2,2,2,2,2,2,2,2,2,2
2,2,2,2,2,2,2,2,2,2,2,2,2,2,2,2,2,2
2,2,2,2,2,2,2,2,2,2,2,2,2,2,2,2,2,2
2,2,2,2,2,2,2,2,2,2,2,2,2,2,2,2,2,2
2,2,2,2,2,2,2,2,2,2,2,2,2,2,2,2,2,2
2,2,2,2,2,2,2,2,2,2,2,2,2,2,2,2,2,2
2,2,2,2,2,2,2,2,2,2,2,2,2,2,2,2,2,2
2,2,2,2,2,2,2,2,2,2,2,2,2,2,2,2,2,2
2,2,2,2,2,2,2,2,2,2,2,2,2,2,2,2,2,2
2,2,2,2,2,2,2,2,2,2,2,2,2,2,2,2,2,2
2,2,2,2,2,2,2,2,2,2,2,2,2,2,2,2,2,2
2,2,2,2,2,2,2,2,2,2,2,2,2,2,2,2,2,2
2,2,2,2,2,2,2,2,2,2,2,2,2,2,2,2,2,2
2,2,2,2,2,2,2,2,2,2,2,2,2,2,2,2,2,2
2,2,2,2,2,2,2,2,2,2,2,2,2,2,2,2,2,2
2,2,2,2,2,2,2,2,2,2,2,2,2,2,2,2,2,2
2,2,2,2,2,2,2,2,2,2,2,2,2,2,2,2,2,2
2,2,2,2,2,2,2,2,2,2,2,2,2,2,2,2,2,2
2,2,2,2,2,2,2,2,2,2,2,2,2,2,2,2,2,2
2,2,2,2,2,2,2,2,2,2,2,2,2,2,2,2,2,2
2,2,2,2,2,2,2,2,2,2,2,2,2,2,2,2,2,2
1,2,2,2,2,2,2,2,2,2,2,2,2,2,2,2,2,2
endlayer

layer
1,3,3,3,3,3,3,3,3,3,3,3,3,3,3,3,3,1
3,0,0,0,0,0,0,0,0,0,0,0,0,0,0,0,0,3
3,0,0,0,0,0,0,0,0,0,0,0,0,0,0,0,0,3
3,0,0,0,0,0,0,0,0,0,0,0,0,0,0,0,0,3
3,0,0,0,4,4,4,4,4,5,4,5,4,4,0,0,0,3
3,0,0,0,4,4,4,4,6,6,4,4,4,4,0,0,0,3
3,0,0,0,4,9,8,3,0,0,3,0,7,4,0,0,0,3
3,0,0,0,4,12,0,3,0,0,3,11,10,5,0,0,0,3
3,0,0,0,4,5,4,4,0,0,4,4,4,4,0,0,0,3
3,0,0,0,4,9,8,3,0,0,3,11,10,4,0,0,0,3
3,0,0,0,4,12,0,3,0,0,3,0,7,4,0,0,0,3
3,0,0,0,4,4,4,4,0,0,4,4,4,4,0,0,0,3
3,0,0,0,4,9,8,3,0,0,3,11,10,5,0,0,0,3
3,0,0,0,4,12,0,3,0,0,3,0,7,4,0,0,0,3
3,0,0,0,4,4,4,4,0,0,4,4,4,4,0,0,0,3
3,0,0,0,4,9,8,3,0,0,3,11,10,4,0,0,0,3
3,0,0,0,4,12,0,3,0,0,3,0,7,4,0,0,0,3
3,0,0,0,5,4,4,4,13,0,4,4,4,5,0,0,0,3
3,0,0,0,0,0,0,0,0,0,0,0,0,0,0,0,0,3
3,0,0,0,0,0,0,0,0,0,0,0,0,0,0,0,0,3
3,0,0,0,0,0,0,0,0,0,0,0,0,0,0,0,0,3
3,0,0,0,0,0,0,0,0,0,0,0,0,0,0,0,0,3
1,3,3,3,3,3,3,3,3,3,3,3,3,3,3,3,3,1
endlayer

layer
1,3,3,3,3,3,3,3,3,3,3,3,3,3,3,3,3,1
3,0,0,0,0,0,0,0,0,0,0,0,0,0,0,0,0,3
3,0,0,0,0,0,0,0,0,0,0,0,0,0,0,0,0,3
3,0,0,0,0,0,0,0,0,0,0,0,0,0,0,0,0,3
3,0,0,0,4,5,4,4,4,4,4,4,0,5,0,0,0,3
3,0,0,0,4,4,4,4,0,0,4,4,4,5,0,0,0,3
3,0,0,0,4,0,0,3,0,0,0,0,0,4,0,0,0,3
3,0,0,0,5,0,0,3,0,0,3,0,0,4,0,0,0,3
3,0,0,0,4,0,4,4,0,0,4,4,4,5,0,0,0,3
3,0,0,0,4,0,0,0,0,0,3,0,0,4,0,0,0,3
3,0,0,0,4,0,0,3,0,0,0,0,0,4,0,0,0,3
3,0,0,0,5,4,4,4,0,0,0,4,4,4,0,0,0,3
3,0,0,0,3,0,0,3,0,0,0,0,0,4,0,0,0,3
3,0,0,0,3,0,0,3,0,0,3,0,0,4,0,0,0,3
3,0,0,0,5,5,5,4,0,0,4,4,4,5,0,0,0,3
3,0,0,0,4,0,0,3,0,0,3,0,0,4,0,0,0,3
3,0,0,0,4,0,0,3,0,0,3,0,0,4,0,0,0,3
3,0,0,0,0,4,5,4,14,0,4,5,4,4,0,0,0,3
3,0,0,0,0,0,0,0,0,0,0,0,0,0,0,0,0,3
3,0,0,0,0,0,0,0,0,0,0,0,0,0,0,0,0,3
3,0,0,0,0,0,0,0,0,0,0,0,0,0,0,0,0,3
3,0,0,0,0,0,0,0,0,0,0,0,0,0,0,0,0,3
1,3,3,3,3,3,3,3,3,3,3,3,3,3,3,3,3,1
endlayer

layer
1,3,3,3,3,3,3,3,3,3,3,3,3,3,3,3,3,1
3,0,0,0,0,0,0,0,0,0,0,0,0,0,0,0,0,3
3,0,0,0,0,0,0,0,0,0,0,0,0,0,0,0,0,3
3,0,0,0,0,0,0,0,0,0,0,0,0,0,0,0,0,3
3,0,0,0,4,4,4,4,4,4,5,5,0,4,0,0,0,3
3,0,0,0,4,4,4,4,0,0,4,0,0,0,0,0,0,3
3,0,0,0,4,0,0,3,0,0,0,0,0,0,0,0,0,3
3,0,0,0,4,0,0,3,0,0,0,0,0,0,0,0,0,3
3,0,0,0,0,0,0,5,0,0,4,4,0,5,0,0,0,3
3,0,0,0,4,0,0,0,0,0,3,0,0,4,0,0,0,3
3,0,0,0,5,0,0,0,0,0,0,0,0,4,0,0,0,3
3,0,0,0,4,4,0,0,0,0,0,4,4,4,0,0,0,3
3,0,0,0,4,0,0,0,0,0,0,0,0,4,0,0,0,3
3,0,0,0,4,0,0,0,0,0,3,0,0,0,0,0,0,0
3,0,0,0,4,4,5,4,0,0,4,4,0,0,0,0,0,0
3,0,0,0,0,0,0,3,0,0,3,0,0,0,0,0,0,0
3,0,0,0,0,0,0,3,0,0,3,0,0,5,0,0,0,3
3,0,0,0,0,0,4,4,4,4,4,4,4,4,0,0,0,3
3,0,0,0,0,0,0,0,0,0,0,0,0,0,0,0,0,3
3,0,0,0,0,0,0,0,0,0,0,0,0,0,0,0,0,3
3,0,0,0,0,0,0,0,0,0,0,0,0,0,0,0,0,3
3,0,0,0,0,0,0,0,0,0,0,0,0,0,0,0,0,3
1,3,3,3,3,3,3,3,3,3,3,3,3,3,3,3,3,1
endlayer

layer
1,15,15,15,15,15,15,15,15,15,15,15,15,15,15,15,15,1
15,0,0,0,0,0,0,0,0,0,0,0,0,0,0,0,0,15
15,0,0,0,0,0,0,0,0,0,0,0,0,0,0,0,0,15
15,0,0,0,0,0,0,0,0,0,0,0,0,0,0,0,0,15
15,0,0,0,4,4,4,4,4,5,4,0,0,0,0,0,0,15
15,0,0,0,0,4,5,4,4,4,0,0,0,0,0,0,0,15
15,0,0,0,4,0,0,0,5,5,0,0,0,0,0,0,0,0
15,0,0,0,4,0,0,0,0,4,4,0,0,0,0,0,0,15
15,0,0,0,0,0,0,0,0,0,5,0,0,0,0,0,0,15
15,0,0,0,0,0,0,0,0,0,0,4,4,5,0,0,0,15
15,0,0,0,4,0,0,0,0,0,0,0,4,4,0,0,0,15
15,0,0,0,0,0,0,0,0,0,0,0,0,0,0,0,0,15
15,0,0,0,4,0,0,0,0,0,0,0,0,0,0,0,0,0
15,0,0,0,5,0,0,0,0,0,0,0,0,0,0,0,0,0
15,0,0,0,0,0,0,0,4,4,4,4,0,0,0,0,0,0
15,0,0,0,0,0,0,4,5,4,4,4,0,0,0,0,0,0
15,0,0,0,0,0,0,0,4,4,5,4,4,0,0,0,0,0
15,0,0,0,0,0,0,4,4,5,4,4,4,5,0,0,0,15
15,0,0,0,0,0,0,0,0,0,0,0,0,0,0,0,0,15
15,0,0,0,0,0,0,0,0,0,0,0,0,0,0,0,0,15
15,0,0,0,0,0,0,0,0,0,0,0,0,0,0,0,0,15
15,0,0,0,0,0,0,0,0,0,0,0,0,0,0,0,0,15
1,15,15,15,15,15,15,15,15,15,15,15,15,15,15,15,15,1
endlayer

layer
16,0,0,0,0,0,0,0,0,0,0,0,0,0,0,0,0,16
0,0,0,0,0,0,0,0,0,0,0,0,0,0,0,0,0,0
0,0,0,0,0,0,0,0,0,0,0,0,0,0,0,0,0,0
0,0,0,0,0,0,0,0,0,0,0,0,0,0,0,0,0,0
0,0,0,0,0,0,0,0,0,0,0,0,0,0,0,0,0,0
0,0,0,0,0,0,0,0,0,0,0,0,0,0,0,0,0,0
0,0,0,0,0,0,0,0,0,0,0,0,0,0,0,0,0,0
0,0,0,0,0,0,0,0,0,0,0,0,0,0,0,0,0,0
0,0,0,0,0,0,0,0,0,0,0,0,0,0,0,0,0,0
0,0,0,0,0,0,0,0,0,0,0,0,0,0,0,0,0,0
0,0,0,0,0,0,0,0,0,0,0,0,0,0,0,0,0,0
0,0,0,0,0,0,0,0,0,0,0,0,0,0,0,0,0,0
0,0,0,0,0,0,0,0,0,0,0,0,0,0,0,0,0,0
0,0,0,0,0,0,0,0,0,0,0,0,0,0,0,0,0,0
0,0,0,0,0,0,0,0,0,0,0,0,0,0,0,0,0,0
0,0,0,0,0,0,0,0,0,0,0,0,0,0,0,0,0,0
0,0,0,0,0,0,0,0,0,0,0,0,0,0,0,0,0,0
0,0,0,0,0,0,0,0,0,0,0,0,0,0,0,0,0,0
0,0,0,0,0,0,0,0,0,0,0,0,0,0,0,0,0,0
0,0,0,0,0,0,0,0,0,0,0,0,0,0,0,0,0,0
0,0,0,0,0,0,0,0,0,0,0,0,0,0,0,0,0,0
0,0,0,0,0,0,0,0,0,0,0,0,0,0,0,0,0,0
16,0,0,0,0,0,0,0,0,0,0,0,0,0,0,0,0,16
endlayer

layer
16,0,0,0,0,0,0,0,0,0,0,0,0,0,0,0,0,16
0,0,0,0,0,0,0,0,0,0,0,0,0,0,0,0,0,0
0,0,0,0,0,0,0,0,0,0,0,0,0,0,0,0,0,0
0,0,0,0,0,0,0,0,0,0,0,0,0,0,0,0,0,0
0,0,0,0,0,0,0,0,0,0,0,0,0,0,0,0,0,0
0,0,0,0,0,0,0,0,0,0,0,0,0,0,0,0,0,0
0,0,0,0,0,0,0,0,0,0,0,0,0,0,0,0,0,0
0,0,0,0,0,0,0,0,0,0,0,0,0,0,0,0,0,0
0,0,0,0,0,0,0,0,0,0,0,0,0,0,0,0,0,0
0,0,0,0,0,0,0,0,0,0,0,0,0,0,0,0,0,0
0,0,0,0,0,0,0,0,0,0,0,0,0,0,0,0,0,0
0,0,0,0,0,0,0,0,0,0,0,0,0,0,0,0,0,0
0,0,0,0,0,0,0,0,0,0,0,0,0,0,0,0,0,0
0,0,0,0,0,0,0,0,0,0,0,0,0,0,0,0,0,0
0,0,0,0,0,0,0,0,0,0,0,0,0,0,0,0,0,0
0,0,0,0,0,0,0,0,0,0,0,0,0,0,0,0,0,0
0,0,0,0,0,0,0,0,0,0,0,0,0,0,0,0,0,0
0,0,0,0,0,0,0,0,0,0,0,0,0,0,0,0,0,0
0,0,0,0,0,0,0,0,0,0,0,0,0,0,0,0,0,0
0,0,0,0,0,0,0,0,0,0,0,0,0,0,0,0,0,0
0,0,0,0,0,0,0,0,0,0,0,0,0,0,0,0,0,0
0,0,0,0,0,0,0,0,0,0,0,0,0,0,0,0,0,0
16,0,0,0,0,0,0,0,0,0,0,0,0,0,0,0,0,16
endlayer

layer
16,0,0,0,0,0,0,0,0,0,0,0,0,0,0,0,0,16
0,0,0,0,0,0,0,0,0,0,0,0,0,0,0,0,0,0
0,0,0,0,0,0,0,0,0,0,0,0,0,0,0,0,0,0
0,0,0,0,0,0,0,0,0,0,0,0,0,0,0,0,0,0
0,0,0,0,0,0,0,0,0,0,0,0,0,0,0,0,0,0
0,0,0,0,0,0,0,0,0,0,0,0,0,0,0,0,0,0
0,0,0,0,0,0,0,0,0,0,0,0,0,0,0,0,0,0
0,0,0,0,0,0,0,0,0,0,0,0,0,0,0,0,0,0
0,0,0,0,0,0,0,0,0,0,0,0,0,0,0,0,0,0
0,0,0,0,0,0,0,0,0,0,0,0,0,0,0,0,0,0
0,0,0,0,0,0,0,0,0,0,0,0,0,0,0,0,0,0
0,0,0,0,0,0,0,0,0,0,0,0,0,0,0,0,0,0
0,0,0,0,0,0,0,0,0,0,0,0,0,0,0,0,0,0
0,0,0,0,0,0,0,0,0,0,0,0,0,0,0,0,0,0
0,0,0,0,0,0,0,0,0,0,0,0,0,0,0,0,0,0
0,0,0,0,0,0,0,0,0,0,0,0,0,0,0,0,0,0
0,0,0,0,0,0,0,0,0,0,0,0,0,0,0,0,0,0
0,0,0,0,0,0,0,0,0,0,0,0,0,0,0,0,0,0
0,0,0,0,0,0,0,0,0,0,0,0,0,0,0,0,0,0
0,0,0,0,0,0,0,0,0,0,0,0,0,0,0,0,0,0
0,0,0,0,0,0,0,0,0,0,0,0,0,0,0,0,0,0
0,0,0,0,0,0,0,0,0,0,0,0,0,0,0,0,0,0
16,0,0,0,0,0,0,0,0,0,0,0,0,0,0,0,0,16
endlayer

layer
17,0,0,0,0,0,0,0,0,0,0,0,0,0,0,0,0,17
0,0,0,0,0,0,0,0,0,0,0,0,0,0,0,0,0,0
0,0,0,0,0,0,0,0,0,0,0,0,0,0,0,0,0,0
0,0,0,0,0,0,0,0,0,0,0,0,0,0,0,0,0,0
0,0,0,0,0,0,0,0,0,0,0,0,0,0,0,0,0,0
0,0,0,0,0,0,0,0,0,0,0,0,0,0,0,0,0,0
0,0,0,0,0,0,0,0,0,0,0,0,0,0,0,0,0,0
0,0,0,0,0,0,0,0,0,0,0,0,0,0,0,0,0,0
0,0,0,0,0,0,0,0,0,0,0,0,0,0,0,0,0,0
0,0,0,0,0,0,0,0,0,0,0,0,0,0,0,0,0,0
0,0,0,0,0,0,0,0,0,0,0,0,0,0,0,0,0,0
0,0,0,0,0,0,0,0,0,0,0,0,0,0,0,0,0,0
0,0,0,0,0,0,0,0,0,0,0,0,0,0,0,0,0,0
0,0,0,0,0,0,0,0,0,0,0,0,0,0,0,0,0,0
0,0,0,0,0,0,0,0,0,0,0,0,0,0,0,0,0,0
0,0,0,0,0,0,0,0,0,0,0,0,0,0,0,0,0,0
0,0,0,0,0,0,0,0,0,0,0,0,0,0,0,0,0,0
0,0,0,0,0,0,0,0,0,0,0,0,0,0,0,0,0,0
0,0,0,0,0,0,0,0,0,0,0,0,0,0,0,0,0,0
0,0,0,0,0,0,0,0,0,0,0,0,0,0,0,0,0,0
0,0,0,0,0,0,0,0,0,0,0,0,0,0,0,0,0,0
0,0,0,0,0,0,0,0,0,0,0,0,0,0,0,0,0,0
17,0,0,0,0,0,0,0,0,0,0,0,0,0,0,0,0,17
endlayer

