
# Created by Ruins mod version 17.2 Ingame Parser
# authoring Player: austinsupercar

# TEMPLATE PARAMETER SETTINGS:
#
# criterion expression specifying mod ids required to load template
# may include plus (AND), minus (AND NOT), comma (OR), and parentheses
# all required mods listed must be present; no prohibited mods can be
requiredMods=
#
# likelihood this template will be chosen relative to all others
# e.g., a weight=6 template is chosen 3X as often as one with weight=2
weight=5
#
# list of dimensions in which this template may spawn, even if generic
# one or more dimension names, separated by commas (blank = all)
dimensionsToSpawnIn=
#
# list of other biomes in which this template may spawn
# biome corresponding to directory is always assumed, listed or not
# generic templates should leave this list empty
biomesToSpawnIn=
#
# criterion expression specifying types of biome where template spawns
# this is in addition to those explicitly listed as biomesToSpawnIn
# generic templates should leave this list empty
biomeTypesToSpawnIn=
#
# list of biomes in which this template may not spawn
# takes precedence over biomeTypesToSpawnIn, but NOT biomesToSpawnIn
# should be empty if biomeTypesToSpawnIn is empty
biomesToNotSpawnIn=
#
# depth template is pushed down into the surface when built
# offset is min/max range of random additional bury depth
embed_into_distance=0
random_height_offset=0,0
#
# whitelist/blacklist of block types on which template may be built
# specify one, not both; leave the other empty (both empty = allow all)
acceptable_target_blocks=
unacceptable_target_blocks=
#
# size of template (#layers, #rows per layer, #blocks per row)
dimensions=9,7,20
#
# max number of missing blocks allowed in surface beneath template
allowable_overhang=0
#
# depth/height limit affected by terrain leveling
# also maximum bumpiness tolerated in surface beneath template
max_leveling=2
#
# padding applied to all sides of template horizontal footprint
# expands area affected by terrain leveling (-1 = no leveling)
leveling_buffer=0
#
# do not rotate template randomly when built (1 = no rotation)
preventRotation=1
#
# treat water/lava blocks as air and protect them from rule0 (1 = yes)
preserve_water=0
preserve_lava=0
#
# minimum distance this template must have from instances of itself
uniqueMinDistance=0
#
# min/max distances this template can be from world spawn (0 = no limit)
# only applies to overworld--i.e., dimension 0
spawnMinDistance=0
spawnMaxDistance=0
#
# other template built nearby whenever this one is
# syntax: <name>;<relativeX>;<maxYdifference>;<relativeZ>[;<chance>]
# may be used more than once to specify multiple neighbors
adjoining_template=

rule1=0,100,minecraft:quartz_block-0
rule2=0,100,minecraft:double_stone_slab-7
rule3=0,100,minecraft:quartz_stairs-0
rule4=0,100,minecraft:planks-2
rule5=0,100,minecraft:sea_lantern-0
rule6=0,100,minecraft:quartz_stairs-2
rule7=0,100,minecraft:quartz_stairs-1
rule8=0,100,minecraft:glass_pane-0
rule9=0,100,minecraft:stained_hardened_clay-3
rule10=0,100,minecraft:jungle_stairs-1
rule11=0,100,minecraft:wooden_slab-2
rule12=0,100,minecraft:jungle_stairs-3
rule13=0,100,minecraft:jungle_stairs-0
rule14=0,100,minecraft:stone_slab-15
rule15=0,100,minecraft:cauldron-0
rule16=0,100,minecraft:cauldron-1
rule17=0,100,minecraft:stone_slab-7
rule18=0,100,minecraft:double_stone_slab-0

layer
0,0,0,0,0,0,0,0,0,0,1,1,1,1,1,1,1,1,1,0
0,0,0,0,0,0,0,0,1,1,1,1,1,1,1,1,1,1,1,1
0,0,0,0,0,0,0,1,1,1,1,1,1,1,1,1,1,1,1,1
0,0,0,0,0,0,1,1,1,1,1,1,1,1,1,1,1,1,1,1
0,0,0,0,0,0,0,1,1,1,1,1,1,1,1,1,1,1,1,1
0,0,0,0,0,0,0,0,1,1,1,1,1,1,1,1,1,1,1,1
0,0,0,0,0,0,0,0,0,0,1,1,1,1,1,1,1,1,1,0
endlayer

layer
0,0,0,0,0,0,0,0,1,1,1,1,1,1,1,1,1,1,2,0
0,0,0,0,0,0,5,1,0,4,4,4,4,4,4,4,4,4,1,3
0,0,0,0,0,1,1,0,0,4,4,4,4,4,4,4,4,4,1,6
0,0,0,0,1,1,0,0,0,4,4,4,4,4,4,4,4,4,1,6
0,0,0,0,0,1,1,0,0,4,4,4,4,4,4,4,4,4,1,6
0,0,0,0,0,0,5,1,0,4,4,4,4,4,4,4,4,4,1,7
0,0,0,0,0,0,0,0,1,1,1,1,1,1,1,1,1,1,1,0
endlayer

layer
0,0,0,0,0,0,0,9,9,9,9,9,9,9,9,9,9,8,8,0
0,0,0,0,0,9,9,4,11,0,0,0,0,0,10,10,10,0,0,0
0,0,0,9,9,1,4,4,11,0,0,0,0,0,0,0,12,0,0,0
0,0,9,9,1,4,4,4,11,0,0,0,0,0,0,0,0,0,0,0
0,0,0,9,9,1,4,4,11,0,0,0,0,0,0,0,12,0,0,0
0,0,0,0,0,9,9,4,11,0,0,0,0,0,13,13,12,0,0,0
0,0,0,0,0,0,0,9,9,9,9,9,9,9,9,9,9,8,8,0
endlayer

layer
0,0,0,0,0,1,1,1,1,1,1,1,1,1,14,8,8,0,0,0
0,0,0,1,1,15,0,0,0,0,0,0,0,0,0,0,0,0,0,0
0,0,1,0,0,0,0,0,0,0,0,0,0,0,0,0,0,0,0,0
0,1,0,0,0,0,0,0,0,0,0,0,0,0,0,0,0,0,0,0
0,0,1,0,0,0,0,0,0,0,0,0,0,0,0,0,0,0,0,0
0,0,0,1,1,16,0,0,0,0,0,0,0,0,0,0,0,0,0,0
0,0,0,0,0,1,1,1,1,1,1,1,1,1,14,8,8,0,0,0
endlayer

layer
0,0,0,0,0,0,0,0,0,17,17,17,17,17,2,14,0,0,0,0
0,0,0,0,0,0,0,0,0,0,0,0,0,0,0,0,0,0,0,0
0,0,0,0,0,0,0,0,0,0,0,0,0,0,0,0,0,0,0,0
0,0,0,0,0,0,0,0,0,0,0,0,0,0,0,0,0,0,0,0
0,0,0,0,0,0,0,0,0,0,0,0,0,0,0,0,0,0,0,0
0,0,0,0,0,0,0,0,0,0,0,0,0,0,0,0,0,0,0,0
0,0,0,0,0,0,0,0,0,0,17,17,17,17,2,14,0,0,0,0
endlayer

layer
0,0,0,0,0,0,0,0,0,0,17,2,2,2,2,2,2,14,0,0
0,0,0,0,0,0,0,0,0,17,2,2,2,14,14,14,2,2,14,0
0,0,0,0,0,0,0,0,17,2,2,14,14,14,14,14,14,2,2,14
0,0,0,0,0,0,0,17,2,14,14,5,14,14,14,14,5,2,2,14
0,0,0,0,0,0,0,0,17,2,2,14,14,14,14,14,14,2,2,14
0,0,0,0,0,0,0,0,0,17,2,2,2,14,14,14,2,2,14,0
0,0,0,0,0,0,0,0,0,0,17,17,2,2,2,2,2,14,0,0
endlayer

layer
0,0,0,0,0,0,0,0,0,0,0,0,17,2,2,2,2,2,2,17
0,0,0,0,0,0,0,0,0,0,0,17,2,11,11,18,11,2,17,17
0,0,0,0,0,0,0,0,0,0,17,2,11,11,11,18,17,17,17,17
0,0,0,0,0,0,0,0,0,17,2,11,18,11,11,11,17,17,17,17
0,0,0,0,0,0,0,0,0,0,17,2,11,11,11,18,17,17,17,17
0,0,0,0,0,0,0,0,0,0,0,17,2,11,11,18,11,2,17,17
0,0,0,0,0,0,0,0,0,0,0,0,0,2,2,2,2,2,2,17
endlayer

layer
0,0,0,0,0,0,0,0,0,0,0,0,0,0,0,0,17,17,2,14
0,0,0,0,0,0,0,0,0,0,0,0,0,0,0,0,0,17,0,0
0,0,0,0,0,0,0,0,0,0,0,0,0,0,0,0,0,0,0,0
0,0,0,0,0,0,0,0,0,0,0,0,8,0,0,0,0,0,0,0
0,0,0,0,0,0,0,0,0,0,0,0,0,0,0,0,0,0,0,0
0,0,0,0,0,0,0,0,0,0,0,0,0,0,0,0,0,17,0,0
0,0,0,0,0,0,0,0,0,0,0,0,0,0,0,0,17,17,2,14
endlayer

layer
0,0,0,0,0,0,0,0,0,0,0,0,0,0,0,0,0,0,0,0
0,0,0,0,0,0,0,0,0,0,0,0,0,0,0,0,0,0,0,17
0,0,0,0,0,0,0,0,0,0,0,0,0,0,0,0,0,0,0,17
0,0,0,0,0,0,0,0,0,0,0,0,0,0,0,0,0,0,0,17
0,0,0,0,0,0,0,0,0,0,0,0,0,0,0,0,0,0,0,17
0,0,0,0,0,0,0,0,0,0,0,0,0,0,0,0,0,0,0,17
0,0,0,0,0,0,0,0,0,0,0,0,0,0,0,0,0,0,0,0
endlayer

